Workbook

Sheet Resumen
A1: Resumen — Fondos de Inversión Atlántida
A2: Atlántida Capital | Fuente: atlantidacapital.com.sv | datos al 2026-07-14 (actualización 2026-10-14)
A3: Fondo | B3: Tipo | C3: Inicio | D3: VC inicial (base) | E3: VC actual | F3: Fecha dato | G3: Patrimonio actual (US$) | H3: Meses | I3: Rend. acum. desde inicio | J3: Rend. anualizado (CAGR)
A4: Fondo Abierto de Liquidez | B4: Abierto | C4: 43132 | D4: 1 | E4: ='Valor cuota (fin de mes)'!CY4 | F4: 46217 | G4: ='Patrimonio (fin de mes)'!CY4 | H4: 102 | I4: =E4/D4-1 | J4: =IFERROR((E4/D4)^(365/(F4-C4))-1,"")
A5: Fondo de Inversion Abierto Atlantida de Renta Mixta | B5: Abierto | C5: 45957 | D5: 1 | E5: ='Valor cuota (fin de mes)'!CY5 | F5: 46217 | G5: ='Patrimonio (fin de mes)'!CY5 | H5: 10 | I5: =E5/D5-1 | J5: =IFERROR((E5/D5)^(365/(F5-C5))-1,"")
A6: Fondo de Inversión Abierto de Crecimiento | B6: Abierto | C6: 43216 | D6: 1 | E6: ='Valor cuota (fin de mes)'!CY6 | F6: 46217 | G6: ='Patrimonio (fin de mes)'!CY6 | H6: 100 | I6: =E6/D6-1 | J6: =IFERROR((E6/D6)^(365/(F6-C6))-1,"")
A7: Fondo de Inversión Cerrado Inmobiliario Atlántida Progresa + | B7: Abierto | C7: 43718 | D7: 5000 | E7: ='Valor cuota (fin de mes)'!CY7 | F7: 46217 | G7: ='Patrimonio (fin de mes)'!CY7 | H7: 83 | I7: =E7/D7-1 | J7: =IFERROR((E7/D7)^(365/(F7-C7))-1,"")

Sheet Gráficas
A1: Gráficas por fondo — patrimonio y rendimiento
A2: Atlántida Capital | Fuente: atlantidacapital.com.sv | datos al 2026-07-14 (actualización 2026-10-14) | una gráfica por fondo · cada una con su propio eje · se actualizan solas al crecer meses/días
A3: Fondo Abierto de Liquidez
A20: Fondo de Inversion Abierto Atlantida de Renta Mixta
A37: Fondo de Inversión Abierto de Crecimiento
A54: Fondo de Inversión Cerrado Inmobiliario Atlántida Progresa +

Sheet Rendimiento mensual
A1: Rendimiento mensual
A2: Atlántida Capital | Fuente: atlantidacapital.com.sv | datos al 2026-07-14 (actualización 2026-10-14)
A3: Fondo | B3: feb-2018 | C3: mar-2018 | D3: abr-2018 | E3: may-2018 | F3: jun-2018 | G3: jul-2018 | H3: ago-2018 | I3: sep-2018 | J3: oct-2018 | K3: nov-2018 | L3: dic-2018 | M3: ene-2019 | N3: feb-2019 | O3: mar-2019 | P3: abr-2019 | Q3: may-2019 | R3: jun-2019 | S3: jul-2019 | T3: ago-2019 | U3: sep-2019 | V3: oct-2019 | W3: nov-2019 | X3: dic-2019 | Y3: ene-2020 | Z3: feb-2020 | AA3: mar-2020 | AB3: abr-2020 | AC3: may-2020 | AD3: jun-2020 | AE3: jul-2020 | AF3: ago-2020 | AG3: sep-2020 | AH3: oct-2020 | AI3: nov-2020 | AJ3: dic-2020 | AK3: ene-2021 | AL3: feb-2021 | AM3: mar-2021 | AN3: abr-2021 | AO3: may-2021 | AP3: jun-2021 | AQ3: jul-2021 | AR3: ago-2021 | AS3: sep-2021 | AT3: oct-2021 | AU3: nov-2021 | AV3: dic-2021 | AW3: ene-2022 | AX3: feb-2022 | AY3: mar-2022 | AZ3: abr-2022 | BA3: may-2022 | BB3: jun-2022 | BC3: jul-2022 | BD3: ago-2022 | BE3: sep-2022 | BF3: oct-2022 | BG3: nov-2022 | BH3: dic-2022 | BI3: ene-2023 | BJ3: feb-2023 | BK3: mar-2023 | BL3: abr-2023 | BM3: may-2023 | BN3: jun-2023 | BO3: jul-2023 | BP3: ago-2023 | BQ3: sep-2023 | BR3: oct-2023 | BS3: nov-2023 | BT3: dic-2023 | BU3: ene-2024 | BV3: feb-2024 | BW3: mar-2024 | BX3: abr-2024 | BY3: may-2024 | BZ3: jun-2024 | CA3: jul-2024 | CB3: ago-2024 | CC3: sep-2024 | CD3: oct-2024 | CE3: nov-2024 | CF3: dic-2024 | CG3: ene-2025 | CH3: feb-2025 | CI3: mar-2025 | CJ3: abr-2025 | CK3: may-2025 | CL3: jun-2025 | CM3: jul-2025 | CN3: ago-2025 | CO3: sep-2025 | CP3: oct-2025 | CQ3: nov-2025 | CR3: dic-2025 | CS3: ene-2026 | CT3: feb-2026 | CU3: mar-2026 | CV3: abr-2026 | CW3: may-2026 | CX3: jun-2026 | CY3: jul-2026*
A4: Fondo Abierto de Liquidez | B4: =IF('Valor cuota (fin de mes)'!B4="","",'Valor cuota (fin de mes)'!B4/'Resumen'!$D$4-1) | C4: =IFERROR(IF(OR('Valor cuota (fin de mes)'!C4="",'Valor cuota (fin de mes)'!B4=""),"",'Valor cuota (fin de mes)'!C4/'Valor cuota (fin de mes)'!B4-1),"") | D4: =IFERROR(IF(OR('Valor cuota (fin de mes)'!D4="",'Valor cuota (fin de mes)'!C4=""),"",'Valor cuota (fin de mes)'!D4/'Valor cuota (fin de mes)'!C4-1),"") | E4: =IFERROR(IF(OR('Valor cuota (fin de mes)'!E4="",'Valor cuota (fin de mes)'!D4=""),"",'Valor cuota (fin de mes)'!E4/'Valor cuota (fin de mes)'!D4-1),"") | F4: =IFERROR(IF(OR('Valor cuota (fin de mes)'!F4="",'Valor cuota (fin de mes)'!E4=""),"",'Valor cuota (fin de mes)'!F4/'Valor cuota (fin de mes)'!E4-1),"") | G4: =IFERROR(IF(OR('Valor cuota (fin de mes)'!G4="",'Valor cuota (fin de mes)'!F4=""),"",'Valor cuota (fin de mes)'!G4/'Valor cuota (fin de mes)'!F4-1),"") | H4: =IFERROR(IF(OR('Valor cuota (fin de mes)'!H4="",'Valor cuota (fin de mes)'!G4=""),"",'Valor cuota (fin de mes)'!H4/'Valor cuota (fin de mes)'!G4-1),"") | I4: =IFERROR(IF(OR('Valor cuota (fin de mes)'!I4="",'Valor cuota (fin de mes)'!H4=""),"",'Valor cuota (fin de mes)'!I4/'Valor cuota (fin de mes)'!H4-1),"") | J4: =IFERROR(IF(OR('Valor cuota (fin de mes)'!J4="",'Valor cuota (fin de mes)'!I4=""),"",'Valor cuota (fin de mes)'!J4/'Valor cuota (fin de mes)'!I4-1),"") | ... CY4: =IFERROR(IF(OR('Valor cuota (fin de mes)'!CY4="",'Valor cuota (fin de mes)'!CX4=""),"",'Valor cuota (fin de mes)'!CY4/'Valor cuota (fin de mes)'!CX4-1),"")
A5: Fondo de Inversion Abierto Atlantida de Renta Mixta | CP5: =IF('Valor cuota (fin de mes)'!CP5="","",'Valor cuota (fin de mes)'!CP5/'Resumen'!$D$5-1) | CQ5: =IFERROR(IF(OR('Valor cuota (fin de mes)'!CQ5="",'Valor cuota (fin de mes)'!CP5=""),"",'Valor cuota (fin de mes)'!CQ5/'Valor cuota (fin de mes)'!CP5-1),"") | CR5: =IFERROR(IF(OR('Valor cuota (fin de mes)'!CR5="",'Valor cuota (fin de mes)'!CQ5=""),"",'Valor cuota (fin de mes)'!CR5/'Valor cuota (fin de mes)'!CQ5-1),"") | CS5: =IFERROR(IF(OR('Valor cuota (fin de mes)'!CS5="",'Valor cuota (fin de mes)'!CR5=""),"",'Valor cuota (fin de mes)'!CS5/'Valor cuota (fin de mes)'!CR5-1),"") | CT5: =IFERROR(IF(OR('Valor cuota (fin de mes)'!CT5="",'Valor cuota (fin de mes)'!CS5=""),"",'Valor cuota (fin de mes)'!CT5/'Valor cuota (fin de mes)'!CS5-1),"") | CU5: =IFERROR(IF(OR('Valor cuota (fin de mes)'!CU5="",'Valor cuota (fin de mes)'!CT5=""),"",'Valor cuota (fin de mes)'!CU5/'Valor cuota (fin de mes)'!CT5-1),"") | CV5: =IFERROR(IF(OR('Valor cuota (fin de mes)'!CV5="",'Valor cuota (fin de mes)'!CU5=""),"",'Valor cuota (fin de mes)'!CV5/'Valor cuota (fin de mes)'!CU5-1),"") | CW5: =IFERROR(IF(OR('Valor cuota (fin de mes)'!CW5="",'Valor cuota (fin de mes)'!CV5=""),"",'Valor cuota (fin de mes)'!CW5/'Valor cuota (fin de mes)'!CV5-1),"") | CX5: =IFERROR(IF(OR('Valor cuota (fin de mes)'!CX5="",'Valor cuota (fin de mes)'!CW5=""),"",'Valor cuota (fin de mes)'!CX5/'Valor cuota (fin de mes)'!CW5-1),"") | CY5: =IFERROR(IF(OR('Valor cuota (fin de mes)'!CY5="",'Valor cuota (fin de mes)'!CX5=""),"",'Valor cuota (fin de mes)'!CY5/'Valor cuota (fin de mes)'!CX5-1),"")
A6: Fondo de Inversión Abierto de Crecimiento | D6: =IF('Valor cuota (fin de mes)'!D6="","",'Valor cuota (fin de mes)'!D6/'Resumen'!$D$6-1) | E6: =IFERROR(IF(OR('Valor cuota (fin de mes)'!E6="",'Valor cuota (fin de mes)'!D6=""),"",'Valor cuota (fin de mes)'!E6/'Valor cuota (fin de mes)'!D6-1),"") | F6: =IFERROR(IF(OR('Valor cuota (fin de mes)'!F6="",'Valor cuota (fin de mes)'!E6=""),"",'Valor cuota (fin de mes)'!F6/'Valor cuota (fin de mes)'!E6-1),"") | G6: =IFERROR(IF(OR('Valor cuota (fin de mes)'!G6="",'Valor cuota (fin de mes)'!F6=""),"",'Valor cuota (fin de mes)'!G6/'Valor cuota (fin de mes)'!F6-1),"") | H6: =IFERROR(IF(OR('Valor cuota (fin de mes)'!H6="",'Valor cuota (fin de mes)'!G6=""),"",'Valor cuota (fin de mes)'!H6/'Valor cuota (fin de mes)'!G6-1),"") | I6: =IFERROR(IF(OR('Valor cuota (fin de mes)'!I6="",'Valor cuota (fin de mes)'!H6=""),"",'Valor cuota (fin de mes)'!I6/'Valor cuota (fin de mes)'!H6-1),"") | J6: =IFERROR(IF(OR('Valor cuota (fin de mes)'!J6="",'Valor cuota (fin de mes)'!I6=""),"",'Valor cuota (fin de mes)'!J6/'Valor cuota (fin de mes)'!I6-1),"") | K6: =IFERROR(IF(OR('Valor cuota (fin de mes)'!K6="",'Valor cuota (fin de mes)'!J6=""),"",'Valor cuota (fin de mes)'!K6/'Valor cuota (fin de mes)'!J6-1),"") | L6: =IFERROR(IF(OR('Valor cuota (fin de mes)'!L6="",'Valor cuota (fin de mes)'!K6=""),"",'Valor cuota (fin de mes)'!L6/'Valor cuota (fin de mes)'!K6-1),"") | ... CY6: =IFERROR(IF(OR('Valor cuota (fin de mes)'!CY6="",'Valor cuota (fin de mes)'!CX6=""),"",'Valor cuota (fin de mes)'!CY6/'Valor cuota (fin de mes)'!CX6-1),"")
A7: Fondo de Inversión Cerrado Inmobiliario Atlántida Progresa + | U7: =IF('Valor cuota (fin de mes)'!U7="","",'Valor cuota (fin de mes)'!U7/'Resumen'!$D$7-1) | V7: =IFERROR(IF(OR('Valor cuota (fin de mes)'!V7="",'Valor cuota (fin de mes)'!U7=""),"",'Valor cuota (fin de mes)'!V7/'Valor cuota (fin de mes)'!U7-1),"") | W7: =IFERROR(IF(OR('Valor cuota (fin de mes)'!W7="",'Valor cuota (fin de mes)'!V7=""),"",'Valor cuota (fin de mes)'!W7/'Valor cuota (fin de mes)'!V7-1),"") | X7: =IFERROR(IF(OR('Valor cuota (fin de mes)'!X7="",'Valor cuota (fin de mes)'!W7=""),"",'Valor cuota (fin de mes)'!X7/'Valor cuota (fin de mes)'!W7-1),"") | Y7: =IFERROR(IF(OR('Valor cuota (fin de mes)'!Y7="",'Valor cuota (fin de mes)'!X7=""),"",'Valor cuota (fin de mes)'!Y7/'Valor cuota (fin de mes)'!X7-1),"") | Z7: =IFERROR(IF(OR('Valor cuota (fin de mes)'!Z7="",'Valor cuota (fin de mes)'!Y7=""),"",'Valor cuota (fin de mes)'!Z7/'Valor cuota (fin de mes)'!Y7-1),"") | AA7: =IFERROR(IF(OR('Valor cuota (fin de mes)'!AA7="",'Valor cuota (fin de mes)'!Z7=""),"",'Valor cuota (fin de mes)'!AA7/'Valor cuota (fin de mes)'!Z7-1),"") | AB7: =IFERROR(IF(OR('Valor cuota (fin de mes)'!AB7="",'Valor cuota (fin de mes)'!AA7=""),"",'Valor cuota (fin de mes)'!AB7/'Valor cuota (fin de mes)'!AA7-1),"") | AC7: =IFERROR(IF(OR('Valor cuota (fin de mes)'!AC7="",'Valor cuota (fin de mes)'!AB7=""),"",'Valor cuota (fin de mes)'!AC7/'Valor cuota (fin de mes)'!AB7-1),"") | ... CY7: =IFERROR(IF(OR('Valor cuota (fin de mes)'!CY7="",'Valor cuota (fin de mes)'!CX7=""),"",'Valor cuota (fin de mes)'!CY7/'Valor cuota (fin de mes)'!CX7-1),"")

Sheet Cierre 31-dic (mensual)
A1: Cierre 31-dic (mensual)
A2: Rendimiento del mes de diciembre de cada año (mismo indicador que la hoja mensual). El año en curso = ultimo mes disponible (parcial)
A3: Fondo | B3: 2018 | C3: 2019 | D3: 2020 | E3: 2021 | F3: 2022 | G3: 2023 | H3: 2024 | I3: 2025 | J3: 2026 (YTD)
A4: Fondo Abierto de Liquidez | B4: ='Rendimiento mensual'!L4 | C4: ='Rendimiento mensual'!X4 | D4: ='Rendimiento mensual'!AJ4 | E4: ='Rendimiento mensual'!AV4 | F4: ='Rendimiento mensual'!BH4 | G4: ='Rendimiento mensual'!BT4 | H4: ='Rendimiento mensual'!CF4 | I4: ='Rendimiento mensual'!CR4 | J4: ='Rendimiento mensual'!CY4
A5: Fondo de Inversion Abierto Atlantida de Renta Mixta | I5: ='Rendimiento mensual'!CR5 | J5: ='Rendimiento mensual'!CY5
A6: Fondo de Inversión Abierto de Crecimiento | B6: ='Rendimiento mensual'!L6 | C6: ='Rendimiento mensual'!X6 | D6: ='Rendimiento mensual'!AJ6 | E6: ='Rendimiento mensual'!AV6 | F6: ='Rendimiento mensual'!BH6 | G6: ='Rendimiento mensual'!BT6 | H6: ='Rendimiento mensual'!CF6 | I6: ='Rendimiento mensual'!CR6 | J6: ='Rendimiento mensual'!CY6
A7: Fondo de Inversión Cerrado Inmobiliario Atlántida Progresa + | C7: ='Rendimiento mensual'!X7 | D7: ='Rendimiento mensual'!AJ7 | E7: ='Rendimiento mensual'!AV7 | F7: ='Rendimiento mensual'!BH7 | G7: ='Rendimiento mensual'!BT7 | H7: ='Rendimiento mensual'!CF7 | I7: ='Rendimiento mensual'!CR7 | J7: ='Rendimiento mensual'!CY7

Sheet Rendimiento anual
A1: Rendimiento anual
A2: Rendimiento ANUAL (ene–dic) desde la cuota. Año de lanzamiento = desde la base; el año en curso = YTD (parcial)
A3: Fondo | B3: 2018 | C3: 2019 | D3: 2020 | E3: 2021 | F3: 2022 | G3: 2023 | H3: 2024 | I3: 2025 | J3: 2026 (YTD)
A4: Fondo Abierto de Liquidez | B4: =IFERROR('Valor cuota (fin de mes)'!L4/'Resumen'!$D$4-1,"") | C4: =IFERROR('Valor cuota (fin de mes)'!X4/'Valor cuota (fin de mes)'!L4-1,"") | D4: =IFERROR('Valor cuota (fin de mes)'!AJ4/'Valor cuota (fin de mes)'!X4-1,"") | E4: =IFERROR('Valor cuota (fin de mes)'!AV4/'Valor cuota (fin de mes)'!AJ4-1,"") | F4: =IFERROR('Valor cuota (fin de mes)'!BH4/'Valor cuota (fin de mes)'!AV4-1,"") | G4: =IFERROR('Valor cuota (fin de mes)'!BT4/'Valor cuota (fin de mes)'!BH4-1,"") | H4: =IFERROR('Valor cuota (fin de mes)'!CF4/'Valor cuota (fin de mes)'!BT4-1,"") | I4: =IFERROR('Valor cuota (fin de mes)'!CR4/'Valor cuota (fin de mes)'!CF4-1,"") | J4: =IFERROR('Valor cuota (fin de mes)'!CY4/'Valor cuota (fin de mes)'!CR4-1,"")
A5: Fondo de Inversion Abierto Atlantida de Renta Mixta | I5: =IFERROR('Valor cuota (fin de mes)'!CR5/'Resumen'!$D$5-1,"") | J5: =IFERROR('Valor cuota (fin de mes)'!CY5/'Valor cuota (fin de mes)'!CR5-1,"")
A6: Fondo de Inversión Abierto de Crecimiento | B6: =IFERROR('Valor cuota (fin de mes)'!L6/'Resumen'!$D$6-1,"") | C6: =IFERROR('Valor cuota (fin de mes)'!X6/'Valor cuota (fin de mes)'!L6-1,"") | D6: =IFERROR('Valor cuota (fin de mes)'!AJ6/'Valor cuota (fin de mes)'!X6-1,"") | E6: =IFERROR('Valor cuota (fin de mes)'!AV6/'Valor cuota (fin de mes)'!AJ6-1,"") | F6: =IFERROR('Valor cuota (fin de mes)'!BH6/'Valor cuota (fin de mes)'!AV6-1,"") | G6: =IFERROR('Valor cuota (fin de mes)'!BT6/'Valor cuota (fin de mes)'!BH6-1,"") | H6: =IFERROR('Valor cuota (fin de mes)'!CF6/'Valor cuota (fin de mes)'!BT6-1,"") | I6: =IFERROR('Valor cuota (fin de mes)'!CR6/'Valor cuota (fin de mes)'!CF6-1,"") | J6: =IFERROR('Valor cuota (fin de mes)'!CY6/'Valor cuota (fin de mes)'!CR6-1,"")
A7: Fondo de Inversión Cerrado Inmobiliario Atlántida Progresa + | C7: =IFERROR('Valor cuota (fin de mes)'!X7/'Resumen'!$D$7-1,"") | D7: =IFERROR('Valor cuota (fin de mes)'!AJ7/'Valor cuota (fin de mes)'!X7-1,"") | E7: =IFERROR('Valor cuota (fin de mes)'!AV7/'Valor cuota (fin de mes)'!AJ7-1,"") | F7: =IFERROR('Valor cuota (fin de mes)'!BH7/'Valor cuota (fin de mes)'!AV7-1,"") | G7: =IFERROR('Valor cuota (fin de mes)'!BT7/'Valor cuota (fin de mes)'!BH7-1,"") | H7: =IFERROR('Valor cuota (fin de mes)'!CF7/'Valor cuota (fin de mes)'!BT7-1,"") | I7: =IFERROR('Valor cuota (fin de mes)'!CR7/'Valor cuota (fin de mes)'!CF7-1,"") | J7: =IFERROR('Valor cuota (fin de mes)'!CY7/'Valor cuota (fin de mes)'!CR7-1,"")

Sheet Diario
A1: Detalle diario — 4 fondos de inversión
A2: Atlántida Capital | Fuente: atlantidacapital.com.sv | datos al 2026-07-14 (actualización 2026-10-14) | una fila por día · lo más reciente arriba · se actualiza a diario
A3: Fecha | B3: Fondo Abierto de Liquidez | E3: Fondo de Inversion Abierto Atlantida de Renta Mixta | H3: Fondo de Inversión Abierto de Crecimiento | K3: Fondo de Inversión Cerrado Inmobiliario Atlántida Progresa +
B4: Valor cuota | C4: Rend. diario | D4: Patrimonio | E4: Valor cuota | F4: Rend. diario | G4: Patrimonio | H4: Valor cuota | I4: Rend. diario | J4: Patrimonio | K4: Valor cuota | L4: Rend. diario | M4: Patrimonio
A5: 46217 | B5: 1.3490205 | C5: 0.000106 | D5: 32192093 | E5: 1.0542528 | F5: 0.000717 | G5: 13305390 | H5: 1.5269554 | I5: 0.000228 | J5: 26949440 | K5: 5965.8165 | L5: 0.00013 | M5: 71876157
A6: 46216 | B6: 1.3488782 | C6: 0.000106 | D6: 32210245 | E6: 1.0534972 | F6: -0.000582 | G6: 13251236 | H6: 1.5266078 | I6: 0.000157 | J6: 26899436 | K6: 5965.0419 | L6: 0.000211 | M6: 71866825
A7: 46215 | B7: 1.3487359 | C7: 0.000106 | D7: 32210146 | E7: 1.0541104 | F7: 0.00012 | G7: 13255646 | H7: 1.5263683 | I7: 0.000157 | J7: 26895816 | K7: 5963.7857 | L7: 0.00013 | M7: 71851690
A8: 46214 | B8: 1.3485936 | C8: 0.000106 | D8: 32206748 | E8: 1.053984 | F8: 0.00012 | G8: 13254057 | H8: 1.5261289 | I8: 0.000157 | J8: 26891596 | K8: 5963.0092 | L8: 0.00013 | M8: 71842335
A9: 46213 | B9: 1.3484513 | C9: 0.000107 | D9: 32203350 | E9: 1.0538576 | F9: 0.00018 | G9: 13252468 | H9: 1.5258894 | I9: 0.000157 | J9: 26887377 | K9: 5962.2325 | L9: 9.7e-05 | M9: 71832977
A10: 46212 | B10: 1.3483077 | C10: 0.000106 | D10: 30108943 | E10: 1.0536681 | F10: 0.000578 | G10: 13206443 | H10: 1.5256498 | I10: 0.000157 | J10: 26877879 | K10: 5961.6519 | L10: 0.000122 | M10: 71825982
A11: 46211 | B11: 1.348165 | C11: 0.000106 | D11: 29755814 | E11: 1.0530596 | F11: -0.001544 | G11: 13140409 | H11: 1.5254102 | I11: 0.000134 | J11: 26871658 | K11: 5960.9262 | L11: 0.000291 | M11: 71817238
A12: 46210 | B12: 1.3480224 | C12: 0.000106 | D12: 29752416 | E12: 1.0546883 | F12: -0.000579 | G12: 5673620.6 | H12: 1.5252053 | I12: -0.001413 | J12: 26667576 | K12: 5959.1925 | L12: 0.000116 | M12: 71796352
A13: 46209 | B13: 1.3478795 | C13: 0.000106 | D13: 29735340 | E13: 1.0552995 | F13: 0.001071 | G13: 7754711.9 | H13: 1.5273629 | I13: 0.000159 | J13: 26700550 | K13: 5958.5023 | L13: 6.5e-05 | M13: 71788036
A14: 46208 | B14: 1.3477367 | C14: 0.000106 | D14: 29688768 | E14: 1.0541708 | F14: 0.000157 | G14: 7727566.6 | H14: 1.5271207 | I14: 0.000159 | J14: 26695317 | K14: 5958.1169 | L14: 0.000128 | M14: 71783393
A15: 46207 | B15: 1.3475938 | C15: 0.000106 | D15: 29689421 | E15: 1.0540055 | F15: 0.000156 | G15: 7726705.1 | H15: 1.5268786 | I15: 0.000159 | J15: 26691085 | K15: 5957.3531 | L15: 9.5e-05 | M15: 71774190
A16: 46206 | B16: 1.3474509 | C16: 0.000107 | D16: 29686273 | E16: 1.0538407 | F16: 0.000158 | G16: 7725497 | H16: 1.5266365 | I16: 0.000159 | J16: 26686852 | K16: 5956.7895 | L16: 1.5e-05 | M16: 71767400
... A265: 45957 | B265: 1.3122574 | C265: 0.000123 | D265: 22652850 | E265: 1 | F265: 0 | G265: 528300 | H265: 1.469852 | I265: 0.000125 | J265: 15175897 | K265: 5939.1816 | L265: 0.000158 | M265: 71555260
A266: 45956 | B266: 1.3120964 | C266: 0.000119 | D266: 21662501 | H266: 1.4696684 | I266: 0.000125 | J266: 15172741 | K266: 5938.2406 | L266: 0.000158 | M266: 71543923
A267: 45955 | B267: 1.3119403 | C267: 0.000119 | D267: 22271051 | H267: 1.4694841 | I267: 0.000125 | J267: 15172838 | K267: 5937.2997 | L267: 0.000152 | M267: 71532586
A268: 45954 | B268: 1.3117842 | C268: 0.000119 | D268: 22268401 | H268: 1.4692999 | I268: 0.000125 | J268: 15170936 | K268: 5936.3967 | L268: 0.000159 | M268: 71521707
A269: 45953 | B269: 1.3116279 | C269: 0.000119 | D269: 22264107 | H269: 1.4691156 | I269: 0.000116 | J269: 15167344 | K269: 5935.4557 | L269: 0.000149 | M269: 71510371
A270: 45952 | B270: 1.3114716 | C270: 0.00012 | D270: 22211742 | H270: 1.4689452 | I270: 0.000116 | J270: 15165384 | K270: 5934.5701 | L270: 0.001279 | M270: 71499700
A271: 45951 | B271: 1.3113148 | C271: 0.000119 | D271: 22202137 | H271: 1.4687745 | I271: 0.000116 | J271: 15163622 | K271: 5926.9899 | L271: 0.000159 | M271: 71408374
A272: 45950 | B272: 1.3111584 | C272: 0.000118 | D272: 22204637 | H272: 1.4686039 | I272: 0.000116 | J272: 15158761 | K272: 5926.0453 | L272: 0.00012 | M272: 71396993
A273: 45949 | B273: 1.3110034 | C273: 0.000118 | D273: 22127221 | H273: 1.4684332 | I273: 0.000121 | J273: 15135602 | K273: 5925.3366 | L273: 0.000164 | M273: 71388455
A274: 45948 | B274: 1.3108484 | C274: 0.000118 | D274: 22124756 | H274: 1.4682556 | I274: 0.000121 | J274: 15133771 | K274: 5924.3663 | L274: 0.000156 | M274: 71376765
A275: 45947 | B275: 1.3106935 | C275: 0.000119 | D275: 22122141 | H275: 1.468078 | I275: 0.000143 | J275: 15131941 | K275: 5923.4402 | L275: 0.000157 | M275: 71365608
A276: 45946 | B276: 1.3105382 | C276: 0.000118 | D276: 22114316 | H276: 1.4678674 | I276: 0.000158 | J276: 15129620 | K276: 5922.5132 | L276: 0.000157 | M276: 71354439
A277: 45945 | B277: 1.310383 | C277: 0.000118 | D277: 22091900 | H277: 1.4676353 | I277: 0.000135 | J277: 15121029 | K277: 5921.5864 | L277: 0.000114 | M277: 71343273
... A2504: 43718 | B2504: 1.0570277 | C2504: 9.8e-05 | D2504: 2563320.2 | H2504: 1.0748823 | I2504: 0.000145 | J2504: 3997884 | K2504: 5000 | L2504: 0 | M2504: 4035000
A2505: 43717 | B2505: 1.056924 | C2505: 8.3e-05 | D2505: 2552480 | H2505: 1.0747264 | I2505: 0.000146 | J2505: 3996304.3
A2506: 43716 | B2506: 1.0568362 | C2506: 8.4e-05 | D2506: 2645587.2 | H2506: 1.0745695 | I2506: 0.000145 | J2506: 3989321.5
A2507: 43715 | B2507: 1.0567473 | C2507: 8.4e-05 | D2507: 2645364.9 | H2507: 1.0744133 | I2507: 0.000146 | J2507: 3988741.7
A2508: 43714 | B2508: 1.0566584 | C2508: 8.4e-05 | D2508: 2645142.4 | H2508: 1.0742563 | I2508: 0.000146 | J2508: 3988159
A2509: 43713 | B2509: 1.0565694 | C2509: 8.8e-05 | D2509: 2642819.7 | H2509: 1.0741 | I2509: 0.000146 | J2509: 3984579
A2510: 43712 | B2510: 1.0564763 | C2510: 8.7e-05 | D2510: 2595074.5 | H2510: 1.0739436 | I2510: 0.000155 | J2510: 3983998.9
A2511: 43711 | B2511: 1.056384 | C2511: 8.7e-05 | D2511: 2587148.3 | H2511: 1.073777 | I2511: 0.000144 | J2511: 3982281
A2512: 43710 | B2512: 1.0562919 | C2512: 8.7e-05 | D2512: 2545926.3 | H2512: 1.0736224 | I2512: 0.000144 | J2512: 4104693.6
A2513: 43709 | B2513: 1.0562003 | C2513: 8.5e-05 | D2513: 2543206 | H2513: 1.0734676 | I2513: 0.000144 | J2513: 4102102.1
A2514: 43708 | B2514: 1.0561102 | C2514: 8.5e-05 | D2514: 2542988.8 | H2514: 1.0733133 | I2514: 0.000144 | J2514: 4107037.8
...

Sheet Valor cuota (fin de mes)
A1: Valor cuota (fin de mes)
A2: Atlántida Capital | Fuente: atlantidacapital.com.sv | datos al 2026-07-14 (actualización 2026-10-14)
A3: Fondo | B3: feb-2018 | C3: mar-2018 | D3: abr-2018 | E3: may-2018 | F3: jun-2018 | G3: jul-2018 | H3: ago-2018 | I3: sep-2018 | J3: oct-2018 | K3: nov-2018 | L3: dic-2018 | M3: ene-2019 | N3: feb-2019 | O3: mar-2019 | P3: abr-2019 | Q3: may-2019 | R3: jun-2019 | S3: jul-2019 | T3: ago-2019 | U3: sep-2019 | V3: oct-2019 | W3: nov-2019 | X3: dic-2019 | Y3: ene-2020 | Z3: feb-2020 | AA3: mar-2020 | AB3: abr-2020 | AC3: may-2020 | AD3: jun-2020 | AE3: jul-2020 | AF3: ago-2020 | AG3: sep-2020 | AH3: oct-2020 | AI3: nov-2020 | AJ3: dic-2020 | AK3: ene-2021 | AL3: feb-2021 | AM3: mar-2021 | AN3: abr-2021 | AO3: may-2021 | AP3: jun-2021 | AQ3: jul-2021 | AR3: ago-2021 | AS3: sep-2021 | AT3: oct-2021 | AU3: nov-2021 | AV3: dic-2021 | AW3: ene-2022 | AX3: feb-2022 | AY3: mar-2022 | AZ3: abr-2022 | BA3: may-2022 | BB3: jun-2022 | BC3: jul-2022 | BD3: ago-2022 | BE3: sep-2022 | BF3: oct-2022 | BG3: nov-2022 | BH3: dic-2022 | BI3: ene-2023 | BJ3: feb-2023 | BK3: mar-2023 | BL3: abr-2023 | BM3: may-2023 | BN3: jun-2023 | BO3: jul-2023 | BP3: ago-2023 | BQ3: sep-2023 | BR3: oct-2023 | BS3: nov-2023 | BT3: dic-2023 | BU3: ene-2024 | BV3: feb-2024 | BW3: mar-2024 | BX3: abr-2024 | BY3: may-2024 | BZ3: jun-2024 | CA3: jul-2024 | CB3: ago-2024 | CC3: sep-2024 | CD3: oct-2024 | CE3: nov-2024 | CF3: dic-2024 | CG3: ene-2025 | CH3: feb-2025 | CI3: mar-2025 | CJ3: abr-2025 | CK3: may-2025 | CL3: jun-2025 | CM3: jul-2025 | CN3: ago-2025 | CO3: sep-2025 | CP3: oct-2025 | CQ3: nov-2025 | CR3: dic-2025 | CS3: ene-2026 | CT3: feb-2026 | CU3: mar-2026 | CV3: abr-2026 | CW3: may-2026 | CX3: jun-2026 | CY3: jul-2026*
A4: Fondo Abierto de Liquidez | B4: 1.0027058 | C4: 1.0060035 | D4: 1.0089739 | E4: 1.0120513 | F4: 1.0150456 | G4: 1.018131 | H4: 1.0211955 | I4: 1.0241762 | J4: 1.0271888 | K4: 1.0300738 | L4: 1.0329693 | M4: 1.0358618 | N4: 1.0385451 | O4: 1.0415208 | P4: 1.0443289 | Q4: 1.0472398 | R4: 1.0501074 | S4: 1.0530889 | T4: 1.0561102 | U4: 1.0588914 | V4: 1.0617624 | W4: 1.0645862 | X4: 1.0676041 | Y4: 1.0705389 | Z4: 1.0733619 | AA4: 1.0763313 | AB4: 1.0791992 | AC4: 1.0822356 | AD4: 1.0853317 | AE4: 1.088352 | AF4: 1.0913323 | AG4: 1.0941561 | AH4: 1.0972527 | AI4: 1.1002635 | AJ4: 1.1032671 | AK4: 1.1062105 | AL4: 1.1088147 | AM4: 1.1115742 | AN4: 1.1143289 | AO4: 1.1169457 | AP4: 1.1197384 | AQ4: 1.1226012 | AR4: 1.1255376 | AS4: 1.1282885 | AT4: 1.1310509 | AU4: 1.1337271 | AV4: 1.1366731 | AW4: 1.1388505 | AX4: 1.1413848 | AY4: 1.1443516 | AZ4: 1.1469871 | BA4: 1.1496682 | BB4: 1.1524777 | BC4: 1.1550335 | BD4: 1.157957 | BE4: 1.1612738 | BF4: 1.1642901 | BG4: 1.1680113 | BH4: 1.1708085 | BI4: 1.1747638 | BJ4: 1.1781172 | BK4: 1.1816528 | BL4: 1.1850695 | BM4: 1.1884418 | BN4: 1.1917521 | BO4: 1.195588 | BP4: 1.1993087 | BQ4: 1.2025416 | BR4: 1.2059146 | BS4: 1.2087833 | BT4: 1.2138162 | BU4: 1.2192079 | BV4: 1.2233845 | BW4: 1.2281258 | BX4: 1.2325768 | BY4: 1.2371273 | BZ4: 1.2412925 | CA4: 1.2460513 | CB4: 1.2507656 | CC4: 1.2548881 | CD4: 1.2589586 | CE4: 1.2628868 | CF4: 1.2676557 | CG4: 1.2720692 | CH4: 1.2760523 | CI4: 1.2804738 | CJ4: 1.2841969 | CK4: 1.2890292 | CL4: 1.2935792 | CM4: 1.298468 | CN4: 1.3033272 | CO4: 1.3080593 | CP4: 1.312503 | CQ4: 1.316648 | CR4: 1.3206519 | CS4: 1.3250574 | CT4: 1.3290959 | CU4: 1.3337137 | CV4: 1.3383399 | CW4: 1.3427579 | CX4: 1.3471091 | CY4: 1.3490205
A5: Fondo de Inversion Abierto Atlantida de Renta Mixta | CP5: 1.0007898 | CQ5: 1.0076388 | CR5: 1.0139732 | CS5: 1.0203351 | CT5: 1.0262287 | CU5: 1.0297756 | CV5: 1.0385197 | CW5: 1.0485612 | CX5: 1.0541943 | CY5: 1.0542528
A6: Fondo de Inversión Abierto de Crecimiento | D6: 1.0004502 | E6: 1.0050538 | F6: 1.0094767 | G6: 1.0141434 | H6: 1.018796 | I6: 1.0233196 | J6: 1.027979 | K6: 1.0324594 | L6: 1.0370866 | M6: 1.0416967 | N6: 1.0458578 | O6: 1.0504487 | P6: 1.0549345 | Q6: 1.0596591 | R6: 1.0640745 | S6: 1.0686665 | T6: 1.0733133 | U6: 1.0779594 | V6: 1.0826388 | W6: 1.0872109 | X6: 1.0919592 | Y6: 1.0967226 | Z6: 1.1012523 | AA6: 1.1061215 | AB6: 1.1108414 | AC6: 1.1157829 | AD6: 1.1205408 | AE6: 1.1255021 | AF6: 1.130427 | AG6: 1.1351851 | AH6: 1.1402842 | AI6: 1.1452568 | AJ6: 1.1562125 | AK6: 1.1611759 | AL6: 1.1656765 | AM6: 1.1705827 | AN6: 1.1754465 | AO6: 1.1802386 | AP6: 1.1850501 | AQ6: 1.1900313 | AR6: 1.1949902 | AS6: 1.1998609 | AT6: 1.2052499 | AU6: 1.2102286 | AV6: 1.2148163 | AW6: 1.2191638 | AX6: 1.2233733 | AY6: 1.2281899 | AZ6: 1.2328749 | BA6: 1.2376007 | BB6: 1.2423464 | BC6: 1.2473836 | BD6: 1.2521358 | BE6: 1.2572666 | BF6: 1.2628267 | BG6: 1.2683383 | BH6: 1.2739653 | BI6: 1.2796698 | BJ6: 1.2847713 | BK6: 1.2903572 | BL6: 1.2956995 | BM6: 1.3011878 | BN6: 1.3067145 | BO6: 1.3129125 | BP6: 1.3191354 | BQ6: 1.3248367 | BR6: 1.3308609 | BS6: 1.337148 | BT6: 1.3435521 | BU6: 1.350554 | BV6: 1.3566091 | BW6: 1.3631562 | BX6: 1.3694203 | BY6: 1.3757719 | BZ6: 1.3806911 | CA6: 1.3865852 | CB6: 1.3923046 | CC6: 1.3971127 | CD6: 1.4018921 | CE6: 1.4069177 | CF6: 1.4122025 | CG6: 1.417611 | CH6: 1.4220132 | CI6: 1.4270252 | CJ6: 1.4321025 | CK6: 1.4375772 | CL6: 1.4450577 | CM6: 1.4517226 | CN6: 1.4576427 | CO6: 1.4643267 | CP6: 1.4705744 | CQ6: 1.476293 | CR6: 1.4824698 | CS6: 1.4893681 | CT6: 1.4956207 | CU6: 1.503442 | CV6: 1.5110095 | CW6: 1.5186288 | CX6: 1.5259072 | CY6: 1.5269554
A7: Fondo de Inversión Cerrado Inmobiliario Atlántida Progresa + | U7: 5000 | V7: 5033.791 | W7: 5067.3958 | X7: 5000 | Y7: 5033.2638 | Z7: 5066.1127 | AA7: 5000 | AB7: 5033.5215 | AC7: 5066.4679 | AD7: 5000 | AE7: 5032.3283 | AF7: 5063.8017 | AG7: 5279.7473 | AH7: 5311.513 | AI7: 5342.4736 | AJ7: 5279.7483 | AK7: 5309.9537 | AL7: 5338.1056 | AM7: 5279.7483 | AN7: 5302.6356 | AO7: 5323.5951 | AP7: 5279.7493 | AQ7: 5302.8388 | AR7: 5324.361 | AS7: 5293.0373 | AT7: 5317.2391 | AU7: 5344.5553 | AV7: 5317.567 | AW7: 5345.0755 | AX7: 5373.024 | AY7: 5317.567 | AZ7: 5344.4075 | BA7: 5370.0909 | BB7: 5348.516 | BC7: 5372.5332 | BD7: 5399.6067 | BE7: 5359.5945 | BF7: 5474.1749 | BG7: 5502.1036 | BH7: 5536.3117 | BI7: 5564.8017 | BJ7: 5591.2479 | BK7: 5536.3117 | BL7: 5560.9399 | BM7: 5584.4645 | BN7: 5546.7318 | BO7: 5652.2458 | BP7: 5674.9498 | BQ7: 5659.033 | BR7: 5707.7475 | BS7: 5733.2865 | BT7: 5734.7677 | BU7: 5760.456 | BV7: 5789.3343 | BW7: 5746.7915 | BX7: 5775.9814 | BY7: 5803.6536 | BZ7: 5787.1409 | CA7: 5824.7817 | CB7: 5846.4912 | CC7: 5812.1311 | CD7: 5859.9584 | CE7: 5879.4349 | CF7: 5892.9095 | CG7: 5918.9008 | CH7: 5945.682 | CI7: 5913.4832 | CJ7: 5938.2914 | CK7: 5961.2666 | CL7: 5945.1145 | CM7: 5988.8779 | CN7: 6012.8897 | CO7: 5904.174 | CP7: 5942.325 | CQ7: 5968.8657 | CR7: 5975.6664 | CS7: 5998.6493 | CT7: 6023.8833 | CU7: 5936.3718 | CV7: 5961.4818 | CW7: 5987.8529 | CX7: 5956.2561 | CY7: 5965.8165

Sheet Patrimonio (fin de mes)
A1: Patrimonio (fin de mes)
A2: Atlántida Capital | Fuente: atlantidacapital.com.sv | datos al 2026-07-14 (actualización 2026-10-14)
A3: Fondo | B3: feb-2018 | C3: mar-2018 | D3: abr-2018 | E3: may-2018 | F3: jun-2018 | G3: jul-2018 | H3: ago-2018 | I3: sep-2018 | J3: oct-2018 | K3: nov-2018 | L3: dic-2018 | M3: ene-2019 | N3: feb-2019 | O3: mar-2019 | P3: abr-2019 | Q3: may-2019 | R3: jun-2019 | S3: jul-2019 | T3: ago-2019 | U3: sep-2019 | V3: oct-2019 | W3: nov-2019 | X3: dic-2019 | Y3: ene-2020 | Z3: feb-2020 | AA3: mar-2020 | AB3: abr-2020 | AC3: may-2020 | AD3: jun-2020 | AE3: jul-2020 | AF3: ago-2020 | AG3: sep-2020 | AH3: oct-2020 | AI3: nov-2020 | AJ3: dic-2020 | AK3: ene-2021 | AL3: feb-2021 | AM3: mar-2021 | AN3: abr-2021 | AO3: may-2021 | AP3: jun-2021 | AQ3: jul-2021 | AR3: ago-2021 | AS3: sep-2021 | AT3: oct-2021 | AU3: nov-2021 | AV3: dic-2021 | AW3: ene-2022 | AX3: feb-2022 | AY3: mar-2022 | AZ3: abr-2022 | BA3: may-2022 | BB3: jun-2022 | BC3: jul-2022 | BD3: ago-2022 | BE3: sep-2022 | BF3: oct-2022 | BG3: nov-2022 | BH3: dic-2022 | BI3: ene-2023 | BJ3: feb-2023 | BK3: mar-2023 | BL3: abr-2023 | BM3: may-2023 | BN3: jun-2023 | BO3: jul-2023 | BP3: ago-2023 | BQ3: sep-2023 | BR3: oct-2023 | BS3: nov-2023 | BT3: dic-2023 | BU3: ene-2024 | BV3: feb-2024 | BW3: mar-2024 | BX3: abr-2024 | BY3: may-2024 | BZ3: jun-2024 | CA3: jul-2024 | CB3: ago-2024 | CC3: sep-2024 | CD3: oct-2024 | CE3: nov-2024 | CF3: dic-2024 | CG3: ene-2025 | CH3: feb-2025 | CI3: mar-2025 | CJ3: abr-2025 | CK3: may-2025 | CL3: jun-2025 | CM3: jul-2025 | CN3: ago-2025 | CO3: sep-2025 | CP3: oct-2025 | CQ3: nov-2025 | CR3: dic-2025 | CS3: ene-2026 | CT3: feb-2026 | CU3: mar-2026 | CV3: abr-2026 | CW3: may-2026 | CX3: jun-2026 | CY3: jul-2026*
A4: Fondo Abierto de Liquidez | B4: 352631.46 | C4: 1034111.3 | D4: 1430912.3 | E4: 1686478.9 | F4: 1687546.3 | G4: 1734421.2 | H4: 1756533.9 | I4: 2158261.9 | J4: 2745121.8 | K4: 2489518.5 | L4: 2431951.1 | M4: 2569537.2 | N4: 2604744 | O4: 2469186.2 | P4: 2391227.2 | Q4: 2089483.9 | R4: 2354920.5 | S4: 2507118.9 | T4: 2542988.8 | U4: 2790701.8 | V4: 3271874 | W4: 3130270.6 | X4: 3559674.1 | Y4: 4107060.6 | Z4: 3574290.3 | AA4: 3795774 | AB4: 4123165.2 | AC4: 7322501.4 | AD4: 7525075.9 | AE4: 8751916.5 | AF4: 8353345.2 | AG4: 9783262.2 | AH4: 10644760 | AI4: 12634749 | AJ4: 17400564 | AK4: 19005033 | AL4: 18938505 | AM4: 21713619 | AN4: 26840650 | AO4: 25749405 | AP4: 27743168 | AQ4: 30177956 | AR4: 27730473 | AS4: 24703922 | AT4: 32392711 | AU4: 27357143 | AV4: 22141017 | AW4: 26989960 | AX4: 23146590 | AY4: 22090142 | AZ4: 22418696 | BA4: 21724792 | BB4: 17078960 | BC4: 13553434 | BD4: 12561619 | BE4: 15046119 | BF4: 15704970 | BG4: 14296652 | BH4: 13467889 | BI4: 12886164 | BJ4: 11765344 | BK4: 13647045 | BL4: 13180452 | BM4: 14463667 | BN4: 12573901 | BO4: 12919506 | BP4: 12353044 | BQ4: 12098256 | BR4: 12260089 | BS4: 11847223 | BT4: 21500981 | BU4: 21402781 | BV4: 24043213 | BW4: 26595462 | BX4: 29037308 | BY4: 30675365 | BZ4: 31972026 | CA4: 31104211 | CB4: 27920249 | CC4: 21117680 | CD4: 16826887 | CE4: 14897120 | CF4: 15218613 | CG4: 14879680 | CH4: 11488946 | CI4: 14174685 | CJ4: 15973514 | CK4: 16711132 | CL4: 19778984 | CM4: 17552609 | CN4: 19699416 | CO4: 19227451 | CP4: 27782823 | CQ4: 28533550 | CR4: 44744469 | CS4: 42994995 | CT4: 38407342 | CU4: 39239517 | CV4: 26933827 | CW4: 32180582 | CX4: 29671764 | CY4: 32192093
A5: Fondo de Inversion Abierto Atlantida de Renta Mixta | CP5: 640450.25 | CQ5: 885955.92 | CR5: 2242306 | CS5: 2657145.4 | CT5: 4121488.1 | CU5: 5549436.5 | CV5: 6064387 | CW5: 6661230.5 | CX5: 7615253 | CY5: 13305390
A6: Fondo de Inversión Abierto de Crecimiento | D6: 1166525 | E6: 1385531.2 | F6: 2190376.5 | G6: 2383826.6 | H6: 2424824.4 | I6: 2445610.9 | J6: 2768781.6 | K6: 2782856.1 | L6: 2894774.1 | M6: 2927669.3 | N6: 3095972.2 | O6: 3134543.6 | P6: 3187860 | Q6: 2929441.2 | R6: 3142921.8 | S6: 3552863.7 | T6: 4107037.8 | U6: 4062210 | V6: 4734711.1 | W6: 4458322.8 | X6: 4881713 | Y6: 5593691.9 | Z6: 6243959 | AA6: 6683366 | AB6: 6755879.8 | AC6: 7022303.8 | AD6: 8554540 | AE6: 9166556.7 | AF6: 9251938.5 | AG6: 9623389.9 | AH6: 9778226.4 | AI6: 9954957.1 | AJ6: 11699592 | AK6: 12325700 | AL6: 17225543 | AM6: 20401272 | AN6: 20549507 | AO6: 20537763 | AP6: 19313949 | AQ6: 19922077 | AR6: 16273155 | AS6: 17519297 | AT6: 17670093 | AU6: 17433453 | AV6: 17828442 | AW6: 15429254 | AX6: 16053581 | AY6: 16148080 | AZ6: 16477371 | BA6: 16162773 | BB6: 16085697 | BC6: 16194659 | BD6: 16257344 | BE6: 16435425 | BF6: 16387051 | BG6: 16760294 | BH6: 17155046 | BI6: 16924254 | BJ6: 17557340 | BK6: 18540372 | BL6: 18872692 | BM6: 18946579 | BN6: 19367269 | BO6: 18935312 | BP6: 19264248 | BQ6: 19609478 | BR6: 44204661 | BS6: 44555962 | BT6: 59954788 | BU6: 57900206 | BV6: 58195718 | BW6: 55778643 | BX6: 61175328 | BY6: 61521107 | BZ6: 61413756 | CA6: 61276821 | CB6: 61563363 | CC6: 53656004 | CD6: 49780024 | CE6: 46425578 | CF6: 45974908 | CG6: 45632614 | CH6: 45786500 | CI6: 45426867 | CJ6: 41999510 | CK6: 38137845 | CL6: 33509857 | CM6: 29678083 | CN6: 21536957 | CO6: 21562580 | CP6: 20205838 | CQ6: 20151080 | CR6: 25266105 | CS6: 25336374 | CT6: 25267742 | CU6: 25623164 | CV6: 25755238 | CW6: 25860689 | CX6: 26580995 | CY6: 26949440
A7: Fondo de Inversión Cerrado Inmobiliario Atlántida Progresa + | U7: 4035000 | V7: 4062269.4 | W7: 4089388.4 | X7: 4035000 | Y7: 4061843.9 | Z7: 4088352.9 | AA7: 4035000 | AB7: 4062051.8 | AC7: 4088639.6 | AD7: 4035000 | AE7: 4061089 | AF7: 4086488 | AG7: 4260756 | AH7: 4286391 | AI7: 4311376.2 | AJ7: 6900631 | AK7: 6940109.4 | AL7: 6976904 | AM7: 6900631 | AN7: 6930544.7 | AO7: 6957938.9 | AP7: 17935309 | AQ7: 18013743 | AR7: 18086854 | AS7: 17980448 | AT7: 33993109 | AU7: 34167742 | AV7: 38834192 | AW7: 39035086 | AX7: 39239194 | AY7: 38834192 | AZ7: 39030208 | BA7: 39722562 | BB7: 39562973 | BC7: 44876770 | BD7: 45102914 | BE7: 44768693 | BF7: 45725783 | BG7: 45959072 | BH7: 48558990 | BI7: 48808876 | BJ7: 49040836 | BK7: 48558990 | BL7: 48775004 | BM7: 56068024 | BN7: 55689187 | BO7: 56748548 | BP7: 56976496 | BQ7: 56816691 | BR7: 57305785 | BS7: 57562196 | BT7: 65055205 | BU7: 65346613 | BV7: 65674209 | BW7: 68812082 | BX7: 69161601 | BY7: 69492948 | BZ7: 69295225 | CA7: 69745936 | CB7: 70280670 | CC7: 69867628 | CD7: 70600779 | CE7: 70835432 | CF7: 70997773 | CG7: 71310917 | CH7: 71633577 | CI7: 71245645 | CJ7: 71544535 | CK7: 71821340 | CL7: 71626740 | CM7: 72154000 | CN7: 72443295 | CO7: 71133489 | CP7: 71593132 | CQ7: 71912894 | CR7: 71994829 | CS7: 72271727 | CT7: 72575746 | CU7: 71521408 | CV7: 71823933 | CW7: 72141651 | CX7: 71760974 | CY7: 71876157

Sheet Notas y metodologia
A1: Notas y metodología
A3: Fuente: Atlántida Capital, S.A. — atlantidacapital.com.sv.
A4: datos al 2026-07-14 (actualización 2026-10-14).
A6: DEFINICIÓN DE 'RENDIMIENTO MENSUAL':
A7: Rendimiento del mes = (Valor cuota al cierre del mes ÷ Valor cuota al cierre del mes anterior) − 1. Es el rendimiento real de la cuota en el mes.
A8: El primer mes de cada fondo se mide desde el valor cuota inicial (base) hasta el cierre de ese mes (puede ser parcial). El año en curso es PARCIAL.
A10: ADVERTENCIA (fondos cerrados):
A11: • Renta Fija I DISTRIBUYE en mayo y noviembre: la cuota baja esos meses, por lo que su rendimiento medido SOLO desde la cuota SUBESTIMA el total del partícipe (lo distribuido se paga en efectivo).
A12: • Growth y Vivienda 01 registran REVALUACIONES inmobiliarias (saltos grandes) y bajas por distribución/markdown. Commercial Properties tiene historia mínima (inició may-2026).
A14: Códigos de color: azul = dato de origen extraído; verde = enlace a otra hoja; negro = fórmula.

Sheet Datos_graficas
A1: Fondo | B1: feb-2018 | C1: mar-2018 | D1: abr-2018 | E1: may-2018 | F1: jun-2018 | G1: jul-2018 | H1: ago-2018 | I1: sep-2018 | J1: oct-2018 | K1: nov-2018 | L1: dic-2018 | M1: ene-2019 | N1: feb-2019 | O1: mar-2019 | P1: abr-2019 | Q1: may-2019 | R1: jun-2019 | S1: jul-2019 | T1: ago-2019 | U1: sep-2019 | V1: oct-2019 | W1: nov-2019 | X1: dic-2019 | Y1: ene-2020 | Z1: feb-2020 | AA1: mar-2020 | AB1: abr-2020 | AC1: may-2020 | AD1: jun-2020 | AE1: jul-2020 | AF1: ago-2020 | AG1: sep-2020 | AH1: oct-2020 | AI1: nov-2020 | AJ1: dic-2020 | AK1: ene-2021 | AL1: feb-2021 | AM1: mar-2021 | AN1: abr-2021 | AO1: may-2021 | AP1: jun-2021 | AQ1: jul-2021 | AR1: ago-2021 | AS1: sep-2021 | AT1: oct-2021 | AU1: nov-2021 | AV1: dic-2021 | AW1: ene-2022 | AX1: feb-2022 | AY1: mar-2022 | AZ1: abr-2022 | BA1: may-2022 | BB1: jun-2022 | BC1: jul-2022 | BD1: ago-2022 | BE1: sep-2022 | BF1: oct-2022 | BG1: nov-2022 | BH1: dic-2022 | BI1: ene-2023 | BJ1: feb-2023 | BK1: mar-2023 | BL1: abr-2023 | BM1: may-2023 | BN1: jun-2023 | BO1: jul-2023 | BP1: ago-2023 | BQ1: sep-2023 | BR1: oct-2023 | BS1: nov-2023 | BT1: dic-2023 | BU1: ene-2024 | BV1: feb-2024 | BW1: mar-2024 | BX1: abr-2024 | BY1: may-2024 | BZ1: jun-2024 | CA1: jul-2024 | CB1: ago-2024 | CC1: sep-2024 | CD1: oct-2024 | CE1: nov-2024 | CF1: dic-2024 | CG1: ene-2025 | CH1: feb-2025 | CI1: mar-2025 | CJ1: abr-2025 | CK1: may-2025 | CL1: jun-2025 | CM1: jul-2025 | CN1: ago-2025 | CO1: sep-2025 | CP1: oct-2025 | CQ1: nov-2025 | CR1: dic-2025 | CS1: ene-2026 | CT1: feb-2026 | CU1: mar-2026 | CV1: abr-2026 | CW1: may-2026 | CX1: jun-2026 | CY1: jul-2026*
A2: Fondo Abierto de Liquidez | B2: 352631.46 | C2: 1034111.3 | D2: 1430912.3 | E2: 1686478.9 | F2: 1687546.3 | G2: 1734421.2 | H2: 1756533.9 | I2: 2158261.9 | J2: 2745121.8 | K2: 2489518.5 | L2: 2431951.1 | M2: 2569537.2 | N2: 2604744 | O2: 2469186.2 | P2: 2391227.2 | Q2: 2089483.9 | R2: 2354920.5 | S2: 2507118.9 | T2: 2542988.8 | U2: 2790701.8 | V2: 3271874 | W2: 3130270.6 | X2: 3559674.1 | Y2: 4107060.6 | Z2: 3574290.3 | AA2: 3795774 | AB2: 4123165.2 | AC2: 7322501.4 | AD2: 7525075.9 | AE2: 8751916.5 | AF2: 8353345.2 | AG2: 9783262.2 | AH2: 10644760 | AI2: 12634749 | AJ2: 17400564 | AK2: 19005033 | AL2: 18938505 | AM2: 21713619 | AN2: 26840650 | AO2: 25749405 | AP2: 27743168 | AQ2: 30177956 | AR2: 27730473 | AS2: 24703922 | AT2: 32392711 | AU2: 27357143 | AV2: 22141017 | AW2: 26989960 | AX2: 23146590 | AY2: 22090142 | AZ2: 22418696 | BA2: 21724792 | BB2: 17078960 | BC2: 13553434 | BD2: 12561619 | BE2: 15046119 | BF2: 15704970 | BG2: 14296652 | BH2: 13467889 | BI2: 12886164 | BJ2: 11765344 | BK2: 13647045 | BL2: 13180452 | BM2: 14463667 | BN2: 12573901 | BO2: 12919506 | BP2: 12353044 | BQ2: 12098256 | BR2: 12260089 | BS2: 11847223 | BT2: 21500981 | BU2: 21402781 | BV2: 24043213 | BW2: 26595462 | BX2: 29037308 | BY2: 30675365 | BZ2: 31972026 | CA2: 31104211 | CB2: 27920249 | CC2: 21117680 | CD2: 16826887 | CE2: 14897120 | CF2: 15218613 | CG2: 14879680 | CH2: 11488946 | CI2: 14174685 | CJ2: 15973514 | CK2: 16711132 | CL2: 19778984 | CM2: 17552609 | CN2: 19699416 | CO2: 19227451 | CP2: 27782823 | CQ2: 28533550 | CR2: 44744469 | CS2: 42994995 | CT2: 38407342 | CU2: 39239517 | CV2: 26933827 | CW2: 32180582 | CX2: 29671764 | CY2: 32192093
A3: Fondo de Inversion Abierto Atlantida de Renta Mixta | CP3: 640450.25 | CQ3: 885955.92 | CR3: 2242306 | CS3: 2657145.4 | CT3: 4121488.1 | CU3: 5549436.5 | CV3: 6064387 | CW3: 6661230.5 | CX3: 7615253 | CY3: 13305390
A4: Fondo de Inversión Abierto de Crecimiento | D4: 1166525 | E4: 1385531.2 | F4: 2190376.5 | G4: 2383826.6 | H4: 2424824.4 | I4: 2445610.9 | J4: 2768781.6 | K4: 2782856.1 | L4: 2894774.1 | M4: 2927669.3 | N4: 3095972.2 | O4: 3134543.6 | P4: 3187860 | Q4: 2929441.2 | R4: 3142921.8 | S4: 3552863.7 | T4: 4107037.8 | U4: 4062210 | V4: 4734711.1 | W4: 4458322.8 | X4: 4881713 | Y4: 5593691.9 | Z4: 6243959 | AA4: 6683366 | AB4: 6755879.8 | AC4: 7022303.8 | AD4: 8554540 | AE4: 9166556.7 | AF4: 9251938.5 | AG4: 9623389.9 | AH4: 9778226.4 | AI4: 9954957.1 | AJ4: 11699592 | AK4: 12325700 | AL4: 17225543 | AM4: 20401272 | AN4: 20549507 | AO4: 20537763 | AP4: 19313949 | AQ4: 19922077 | AR4: 16273155 | AS4: 17519297 | AT4: 17670093 | AU4: 17433453 | AV4: 17828442 | AW4: 15429254 | AX4: 16053581 | AY4: 16148080 | AZ4: 16477371 | BA4: 16162773 | BB4: 16085697 | BC4: 16194659 | BD4: 16257344 | BE4: 16435425 | BF4: 16387051 | BG4: 16760294 | BH4: 17155046 | BI4: 16924254 | BJ4: 17557340 | BK4: 18540372 | BL4: 18872692 | BM4: 18946579 | BN4: 19367269 | BO4: 18935312 | BP4: 19264248 | BQ4: 19609478 | BR4: 44204661 | BS4: 44555962 | BT4: 59954788 | BU4: 57900206 | BV4: 58195718 | BW4: 55778643 | BX4: 61175328 | BY4: 61521107 | BZ4: 61413756 | CA4: 61276821 | CB4: 61563363 | CC4: 53656004 | CD4: 49780024 | CE4: 46425578 | CF4: 45974908 | CG4: 45632614 | CH4: 45786500 | CI4: 45426867 | CJ4: 41999510 | CK4: 38137845 | CL4: 33509857 | CM4: 29678083 | CN4: 21536957 | CO4: 21562580 | CP4: 20205838 | CQ4: 20151080 | CR4: 25266105 | CS4: 25336374 | CT4: 25267742 | CU4: 25623164 | CV4: 25755238 | CW4: 25860689 | CX4: 26580995 | CY4: 26949440
A5: Fondo de Inversión Cerrado Inmobiliario Atlántida Progresa + | U5: 4035000 | V5: 4062269.4 | W5: 4089388.4 | X5: 4035000 | Y5: 4061843.9 | Z5: 4088352.9 | AA5: 4035000 | AB5: 4062051.8 | AC5: 4088639.6 | AD5: 4035000 | AE5: 4061089 | AF5: 4086488 | AG5: 4260756 | AH5: 4286391 | AI5: 4311376.2 | AJ5: 6900631 | AK5: 6940109.4 | AL5: 6976904 | AM5: 6900631 | AN5: 6930544.7 | AO5: 6957938.9 | AP5: 17935309 | AQ5: 18013743 | AR5: 18086854 | AS5: 17980448 | AT5: 33993109 | AU5: 34167742 | AV5: 38834192 | AW5: 39035086 | AX5: 39239194 | AY5: 38834192 | AZ5: 39030208 | BA5: 39722562 | BB5: 39562973 | BC5: 44876770 | BD5: 45102914 | BE5: 44768693 | BF5: 45725783 | BG5: 45959072 | BH5: 48558990 | BI5: 48808876 | BJ5: 49040836 | BK5: 48558990 | BL5: 48775004 | BM5: 56068024 | BN5: 55689187 | BO5: 56748548 | BP5: 56976496 | BQ5: 56816691 | BR5: 57305785 | BS5: 57562196 | BT5: 65055205 | BU5: 65346613 | BV5: 65674209 | BW5: 68812082 | BX5: 69161601 | BY5: 69492948 | BZ5: 69295225 | CA5: 69745936 | CB5: 70280670 | CC5: 69867628 | CD5: 70600779 | CE5: 70835432 | CF5: 70997773 | CG5: 71310917 | CH5: 71633577 | CI5: 71245645 | CJ5: 71544535 | CK5: 71821340 | CL5: 71626740 | CM5: 72154000 | CN5: 72443295 | CO5: 71133489 | CP5: 71593132 | CQ5: 71912894 | CR5: 71994829 | CS5: 72271727 | CT5: 72575746 | CU5: 71521408 | CV5: 71823933 | CW5: 72141651 | CX5: 71760974 | CY5: 71876157
A10: Fondo | B10: 2018 | C10: 2019 | D10: 2020 | E10: 2021 | F10: 2022 | G10: 2023 | H10: 2024 | I10: 2025 | J10: 2026
A11: Fondo Abierto de Liquidez | B11: 2431951.1 | C11: 3559674.1 | D11: 17400564 | E11: 22141017 | F11: 13467889 | G11: 21500981 | H11: 15218613 | I11: 44744469 | J11: 32192093
A12: Fondo de Inversion Abierto Atlantida de Renta Mixta | I12: 2242306 | J12: 13305390
A13: Fondo de Inversión Abierto de Crecimiento | B13: 2894774.1 | C13: 4881713 | D13: 11699592 | E13: 17828442 | F13: 17155046 | G13: 59954788 | H13: 45974908 | I13: 25266105 | J13: 26949440
A14: Fondo de Inversión Cerrado Inmobiliario Atlántida Progresa + | C14: 4035000 | D14: 6900631 | E14: 38834192 | F14: 48558990 | G14: 65055205 | H14: 70997773 | I14: 71994829 | J14: 71876157
A19: Fondo | B19: feb-2018 | C19: mar-2018 | D19: abr-2018 | E19: may-2018 | F19: jun-2018 | G19: jul-2018 | H19: ago-2018 | I19: sep-2018 | J19: oct-2018 | K19: nov-2018 | L19: dic-2018 | M19: ene-2019 | N19: feb-2019 | O19: mar-2019 | P19: abr-2019 | Q19: may-2019 | R19: jun-2019 | S19: jul-2019 | T19: ago-2019 | U19: sep-2019 | V19: oct-2019 | W19: nov-2019 | X19: dic-2019 | Y19: ene-2020 | Z19: feb-2020 | AA19: mar-2020 | AB19: abr-2020 | AC19: may-2020 | AD19: jun-2020 | AE19: jul-2020 | AF19: ago-2020 | AG19: sep-2020 | AH19: oct-2020 | AI19: nov-2020 | AJ19: dic-2020 | AK19: ene-2021 | AL19: feb-2021 | AM19: mar-2021 | AN19: abr-2021 | AO19: may-2021 | AP19: jun-2021 | AQ19: jul-2021 | AR19: ago-2021 | AS19: sep-2021 | AT19: oct-2021 | AU19: nov-2021 | AV19: dic-2021 | AW19: ene-2022 | AX19: feb-2022 | AY19: mar-2022 | AZ19: abr-2022 | BA19: may-2022 | BB19: jun-2022 | BC19: jul-2022 | BD19: ago-2022 | BE19: sep-2022 | BF19: oct-2022 | BG19: nov-2022 | BH19: dic-2022 | BI19: ene-2023 | BJ19: feb-2023 | BK19: mar-2023 | BL19: abr-2023 | BM19: may-2023 | BN19: jun-2023 | BO19: jul-2023 | BP19: ago-2023 | BQ19: sep-2023 | BR19: oct-2023 | BS19: nov-2023 | BT19: dic-2023 | BU19: ene-2024 | BV19: feb-2024 | BW19: mar-2024 | BX19: abr-2024 | BY19: may-2024 | BZ19: jun-2024 | CA19: jul-2024 | CB19: ago-2024 | CC19: sep-2024 | CD19: oct-2024 | CE19: nov-2024 | CF19: dic-2024 | CG19: ene-2025 | CH19: feb-2025 | CI19: mar-2025 | CJ19: abr-2025 | CK19: may-2025 | CL19: jun-2025 | CM19: jul-2025 | CN19: ago-2025 | CO19: sep-2025 | CP19: oct-2025 | CQ19: nov-2025 | CR19: dic-2025 | CS19: ene-2026 | CT19: feb-2026 | CU19: mar-2026 | CV19: abr-2026 | CW19: may-2026 | CX19: jun-2026 | CY19: jul-2026*
A20: Fondo Abierto de Liquidez | B20: 0.002706 | C20: 0.003289 | D20: 0.002953 | E20: 0.00305 | F20: 0.002959 | G20: 0.00304 | H20: 0.00301 | I20: 0.002919 | J20: 0.002941 | K20: 0.002809 | L20: 0.002811 | M20: 0.0028 | N20: 0.00259 | O20: 0.002865 | P20: 0.002696 | Q20: 0.002787 | R20: 0.002738 | S20: 0.002839 | T20: 0.002869 | U20: 0.002633 | V20: 0.002711 | W20: 0.002659 | X20: 0.002835 | Y20: 0.002749 | Z20: 0.002637 | AA20: 0.002766 | AB20: 0.002664 | AC20: 0.002814 | AD20: 0.002861 | AE20: 0.002783 | AF20: 0.002738 | AG20: 0.002587 | AH20: 0.00283 | AI20: 0.002744 | AJ20: 0.00273 | AK20: 0.002668 | AL20: 0.002354 | AM20: 0.002489 | AN20: 0.002478 | AO20: 0.002348 | AP20: 0.0025 | AQ20: 0.002557 | AR20: 0.002616 | AS20: 0.002444 | AT20: 0.002448 | AU20: 0.002366 | AV20: 0.002599 | AW20: 0.001916 | AX20: 0.002225 | AY20: 0.002599 | AZ20: 0.002303 | BA20: 0.002338 | BB20: 0.002444 | BC20: 0.002218 | BD20: 0.002531 | BE20: 0.002864 | BF20: 0.002597 | BG20: 0.003196 | BH20: 0.002395 | BI20: 0.003378 | BJ20: 0.002855 | BK20: 0.003001 | BL20: 0.002892 | BM20: 0.002846 | BN20: 0.002785 | BO20: 0.003219 | BP20: 0.003112 | BQ20: 0.002696 | BR20: 0.002805 | BS20: 0.002379 | BT20: 0.004164 | BU20: 0.004442 | BV20: 0.003426 | BW20: 0.003876 | BX20: 0.003624 | BY20: 0.003692 | BZ20: 0.003367 | CA20: 0.003834 | CB20: 0.003783 | CC20: 0.003296 | CD20: 0.003244 | CE20: 0.00312 | CF20: 0.003776 | CG20: 0.003482 | CH20: 0.003131 | CI20: 0.003465 | CJ20: 0.002908 | CK20: 0.003763 | CL20: 0.00353 | CM20: 0.003779 | CN20: 0.003742 | CO20: 0.003631 | CP20: 0.003397 | CQ20: 0.003158 | CR20: 0.003041 | CS20: 0.003336 | CT20: 0.003048 | CU20: 0.003474 | CV20: 0.003469 | CW20: 0.003301 | CX20: 0.003241 | CY20: 0.001419
A21: Fondo de Inversion Abierto Atlantida de Renta Mixta | CP21: 0.00079 | CQ21: 0.006844 | CR21: 0.006286 | CS21: 0.006274 | CT21: 0.005776 | CU21: 0.003456 | CV21: 0.008491 | CW21: 0.009669 | CX21: 0.005372 | CY21: 5.6e-05
A22: Fondo de Inversión Abierto de Crecimiento | D22: 0.00045 | E22: 0.004602 | F22: 0.004401 | G22: 0.004623 | H22: 0.004588 | I22: 0.00444 | J22: 0.004553 | K22: 0.004358 | L22: 0.004482 | M22: 0.004445 | N22: 0.003995 | O22: 0.00439 | P22: 0.00427 | Q22: 0.004479 | R22: 0.004167 | S22: 0.004316 | T22: 0.004348 | U22: 0.004329 | V22: 0.004341 | W22: 0.004223 | X22: 0.004367 | Y22: 0.004362 | Z22: 0.00413 | AA22: 0.004422 | AB22: 0.004267 | AC22: 0.004448 | AD22: 0.004264 | AE22: 0.004428 | AF22: 0.004376 | AG22: 0.004209 | AH22: 0.004492 | AI22: 0.004361 | AJ22: 0.009566 | AK22: 0.004293 | AL22: 0.003876 | AM22: 0.004209 | AN22: 0.004155 | AO22: 0.004077 | AP22: 0.004077 | AQ22: 0.004203 | AR22: 0.004167 | AS22: 0.004076 | AT22: 0.004491 | AU22: 0.004131 | AV22: 0.003791 | AW22: 0.003579 | AX22: 0.003453 | AY22: 0.003937 | AZ22: 0.003815 | BA22: 0.003833 | BB22: 0.003835 | BC22: 0.004055 | BD22: 0.00381 | BE22: 0.004098 | BF22: 0.004422 | BG22: 0.004365 | BH22: 0.004436 | BI22: 0.004478 | BJ22: 0.003987 | BK22: 0.004348 | BL22: 0.00414 | BM22: 0.004236 | BN22: 0.004247 | BO22: 0.004743 | BP22: 0.00474 | BQ22: 0.004322 | BR22: 0.004547 | BS22: 0.004724 | BT22: 0.004789 | BU22: 0.005211 | BV22: 0.004483 | BW22: 0.004826 | BX22: 0.004595 | BY22: 0.004638 | BZ22: 0.003576 | CA22: 0.004269 | CB22: 0.004125 | CC22: 0.003453 | CD22: 0.003421 | CE22: 0.003585 | CF22: 0.003756 | CG22: 0.00383 | CH22: 0.003105 | CI22: 0.003525 | CJ22: 0.003558 | CK22: 0.003823 | CL22: 0.005204 | CM22: 0.004612 | CN22: 0.004078 | CO22: 0.004585 | CP22: 0.004267 | CQ22: 0.003889 | CR22: 0.004184 | CS22: 0.004653 | CT22: 0.004198 | CU22: 0.005229 | CV22: 0.005033 | CW22: 0.005043 | CX22: 0.004793 | CY22: 0.000687
A23: Fondo de Inversión Cerrado Inmobiliario Atlántida Progresa + | U23: 0 | V23: 0.006758 | W23: 0.006676 | X23: -0.0133 | Y23: 0.006653 | Z23: 0.006526 | AA23: -0.01305 | AB23: 0.006704 | AC23: 0.006545 | AD23: -0.013119 | AE23: 0.006466 | AF23: 0.006254 | AG23: 0.042645 | AH23: 0.006017 | AI23: 0.005829 | AJ23: -0.011741 | AK23: 0.005721 | AL23: 0.005302 | AM23: -0.010932 | AN23: 0.004335 | AO23: 0.003953 | AP23: -0.008236 | AQ23: 0.004373 | AR23: 0.004059 | AS23: -0.005883 | AT23: 0.004572 | AU23: 0.005137 | AV23: -0.00505 | AW23: 0.005173 | AX23: 0.005229 | AY23: -0.010321 | AZ23: 0.005048 | BA23: 0.004806 | BB23: -0.004018 | BC23: 0.00449 | BD23: 0.005039 | BE23: -0.00741 | BF23: 0.021379 | BG23: 0.005102 | BH23: 0.006217 | BI23: 0.005146 | BJ23: 0.004752 | BK23: -0.009825 | BL23: 0.004448 | BM23: 0.00423 | BN23: -0.006757 | BO23: 0.019023 | BP23: 0.004017 | BQ23: -0.002805 | BR23: 0.008608 | BS23: 0.004474 | BT23: 0.000258 | BU23: 0.004479 | BV23: 0.005013 | BW23: -0.007348 | BX23: 0.005079 | BY23: 0.004791 | BZ23: -0.002845 | CA23: 0.006504 | CB23: 0.003727 | CC23: -0.005877 | CD23: 0.008229 | CE23: 0.003324 | CF23: 0.002292 | CG23: 0.004411 | CH23: 0.004525 | CI23: -0.005416 | CJ23: 0.004195 | CK23: 0.003869 | CL23: -0.00271 | CM23: 0.007361 | CN23: 0.004009 | CO23: -0.01808 | CP23: 0.006462 | CQ23: 0.004466 | CR23: 0.001139 | CS23: 0.003846 | CT23: 0.004207 | CU23: -0.014527 | CV23: 0.00423 | CW23: 0.004424 | CX23: -0.005277 | CY23: 0.001605
