Workbook

Sheet Resumen
A1: Resumen — Todas las gestoras
A2: Fondos de Inversión El Salvador — Todas las gestoras | Fuente: sitios oficiales de cada gestora | datos al 2026-10-11 (actualización 2026-10-11)
A3: Fondo | B3: Tipo | C3: Inicio | D3: VC inicial (base) | E3: VC actual | F3: Fecha dato | G3: Patrimonio actual (US$) | H3: Meses | I3: Rend. acum. desde inicio | J3: Rend. anualizado (CAGR)
A4: Hencorp · FI Abierto Hencorp Opportunity | B4: Abierto | C4: 45048 | D4: 1 | E4: ='Valor cuota (fin de mes)'!DR4 | F4: 46305 | G4: ='Patrimonio (fin de mes)'!DR4 | H4: 42 | I4: =E4/D4-1 | J4: =IFERROR((E4/D4)^(365/(F4-C4))-1,"")
A5: Hencorp · FIC Renta Fija I | B5: Cerrado | C5: 45212 | D5: 1000 | E5: ='Valor cuota (fin de mes)'!DR5 | F5: 46305 | G5: ='Patrimonio (fin de mes)'!DR5 | H5: 37 | I5: =E5/D5-1 | J5: =IFERROR((E5/D5)^(365/(F5-C5))-1,"")
A6: Hencorp · FIC Inmobiliario Hencorp Growth | B6: Cerrado | C6: 45372 | D6: 1000 | E6: ='Valor cuota (fin de mes)'!DR6 | F6: 46306 | G6: ='Patrimonio (fin de mes)'!DR6 | H6: 32 | I6: =E6/D6-1 | J6: =IFERROR((E6/D6)^(365/(F6-C6))-1,"")
A7: Hencorp · FIC Desarrollo Inmob. Hencorp Vivienda 01 | B7: Cerrado | C7: 45819 | D7: 1000 | E7: ='Valor cuota (fin de mes)'!DR7 | F7: 46306 | G7: ='Patrimonio (fin de mes)'!DR7 | H7: 17 | I7: =E7/D7-1 | J7: =IFERROR((E7/D7)^(365/(F7-C7))-1,"")
A8: Hencorp · FIC Inmobiliario Hencorp Blue Whale | B8: Cerrado | C8: 45919 | D8: 1000 | E8: ='Valor cuota (fin de mes)'!DR8 | F8: 46306 | G8: ='Patrimonio (fin de mes)'!DR8 | H8: 14 | I8: =E8/D8-1 | J8: =IFERROR((E8/D8)^(365/(F8-C8))-1,"")
A9: Hencorp · FIC Inmobiliario Hencorp Commercial Properties | B9: Cerrado | C9: 46157 | D9: 1000 | E9: ='Valor cuota (fin de mes)'!DR9 | F9: 46306 | G9: ='Patrimonio (fin de mes)'!DR9 | H9: 6 | I9: =E9/D9-1 | J9: =IFERROR((E9/D9)^(365/(F9-C9))-1,"")
A10: SGB · FI Abierto Rentable Corto Plazo | B10: Abierto | C10: 42655 | D10: 1 | E10: ='Valor cuota (fin de mes)'!DR10 | F10: 46306 | G10: ='Patrimonio (fin de mes)'!DR10 | H10: 121 | I10: =E10/D10-1 | J10: =IFERROR((E10/D10)^(365/(F10-C10))-1,"")
A11: SGB · FI Abierto Plazo 180 | B11: Abierto | C11: 43201 | D11: 1 | E11: ='Valor cuota (fin de mes)'!DR11 | F11: 46306 | G11: ='Patrimonio (fin de mes)'!DR11 | H11: 103 | I11: =E11/D11-1 | J11: =IFERROR((E11/D11)^(365/(F11-C11))-1,"")
A12: Atlántida · Fondo Abierto de Liquidez | B12: Abierto | C12: 43132 | D12: 1 | E12: ='Valor cuota (fin de mes)'!DR12 | F12: 46217 | G12: ='Patrimonio (fin de mes)'!DR12 | H12: 102 | I12: =E12/D12-1 | J12: =IFERROR((E12/D12)^(365/(F12-C12))-1,"")
A13: Atlántida · Fondo de Inversion Abierto Atlantida de Renta Mixta | B13: Abierto | C13: 45957 | D13: 1 | E13: ='Valor cuota (fin de mes)'!DR13 | F13: 46217 | G13: ='Patrimonio (fin de mes)'!DR13 | H13: 10 | I13: =E13/D13-1 | J13: =IFERROR((E13/D13)^(365/(F13-C13))-1,"")
A14: Atlántida · Fondo de Inversión Abierto de Crecimiento | B14: Abierto | C14: 43216 | D14: 1 | E14: ='Valor cuota (fin de mes)'!DR14 | F14: 46217 | G14: ='Patrimonio (fin de mes)'!DR14 | H14: 100 | I14: =E14/D14-1 | J14: =IFERROR((E14/D14)^(365/(F14-C14))-1,"")
A15: Atlántida · Fondo de Inversión Cerrado Inmobiliario Atlántida Progresa + | B15: Abierto | C15: 43718 | D15: 5000 | E15: ='Valor cuota (fin de mes)'!DR15 | F15: 46217 | G15: ='Patrimonio (fin de mes)'!DR15 | H15: 83 | I15: =E15/D15-1 | J15: =IFERROR((E15/D15)^(365/(F15-C15))-1,"")

Sheet Gráficas
A1: Gráficas por fondo — patrimonio y rendimiento
A2: Fondos de Inversión El Salvador — Todas las gestoras | Fuente: sitios oficiales de cada gestora | datos al 2026-10-11 (actualización 2026-10-11) | una gráfica por fondo · cada una con su propio eje · se actualizan solas al crecer meses/días
A3: Hencorp · FI Abierto Hencorp Opportunity
A20: Hencorp · FIC Renta Fija I
A37: Hencorp · FIC Inmobiliario Hencorp Growth
A54: Hencorp · FIC Desarrollo Inmob. Hencorp Vivienda 01
A71: Hencorp · FIC Inmobiliario Hencorp Blue Whale
A88: Hencorp · FIC Inmobiliario Hencorp Commercial Properties
A105: SGB · FI Abierto Rentable Corto Plazo
A122: SGB · FI Abierto Plazo 180
A139: Atlántida · Fondo Abierto de Liquidez
A156: Atlántida · Fondo de Inversion Abierto Atlantida de Renta Mixta
... A190: Atlántida · Fondo de Inversión Cerrado Inmobiliario Atlántida Progresa +

Sheet Rendimiento mensual
A1: Rendimiento mensual
A2: Fondos de Inversión El Salvador — Todas las gestoras | Fuente: sitios oficiales de cada gestora | datos al 2026-10-11 (actualización 2026-10-11)
A3: Fondo | B3: oct-2016 | C3: nov-2016 | D3: dic-2016 | E3: ene-2017 | F3: feb-2017 | G3: mar-2017 | H3: abr-2017 | I3: may-2017 | J3: jun-2017 | K3: jul-2017 | L3: ago-2017 | M3: sep-2017 | N3: oct-2017 | O3: nov-2017 | P3: dic-2017 | Q3: ene-2018 | R3: feb-2018 | S3: mar-2018 | T3: abr-2018 | U3: may-2018 | V3: jun-2018 | W3: jul-2018 | X3: ago-2018 | Y3: sep-2018 | Z3: oct-2018 | AA3: nov-2018 | AB3: dic-2018 | AC3: ene-2019 | AD3: feb-2019 | AE3: mar-2019 | AF3: abr-2019 | AG3: may-2019 | AH3: jun-2019 | AI3: jul-2019 | AJ3: ago-2019 | AK3: sep-2019 | AL3: oct-2019 | AM3: nov-2019 | AN3: dic-2019 | AO3: ene-2020 | AP3: feb-2020 | AQ3: mar-2020 | AR3: abr-2020 | AS3: may-2020 | AT3: jun-2020 | AU3: jul-2020 | AV3: ago-2020 | AW3: sep-2020 | AX3: oct-2020 | AY3: nov-2020 | AZ3: dic-2020 | BA3: ene-2021 | BB3: feb-2021 | BC3: mar-2021 | BD3: abr-2021 | BE3: may-2021 | BF3: jun-2021 | BG3: jul-2021 | BH3: ago-2021 | BI3: sep-2021 | BJ3: oct-2021 | BK3: nov-2021 | BL3: dic-2021 | BM3: ene-2022 | BN3: feb-2022 | BO3: mar-2022 | BP3: abr-2022 | BQ3: may-2022 | BR3: jun-2022 | BS3: jul-2022 | BT3: ago-2022 | BU3: sep-2022 | BV3: oct-2022 | BW3: nov-2022 | BX3: dic-2022 | BY3: ene-2023 | BZ3: feb-2023 | CA3: mar-2023 | CB3: abr-2023 | CC3: may-2023 | CD3: jun-2023 | CE3: jul-2023 | CF3: ago-2023 | CG3: sep-2023 | CH3: oct-2023 | CI3: nov-2023 | CJ3: dic-2023 | CK3: ene-2024 | CL3: feb-2024 | CM3: mar-2024 | CN3: abr-2024 | CO3: may-2024 | CP3: jun-2024 | CQ3: jul-2024 | CR3: ago-2024 | CS3: sep-2024 | CT3: oct-2024 | CU3: nov-2024 | CV3: dic-2024 | CW3: ene-2025 | CX3: feb-2025 | CY3: mar-2025 | CZ3: abr-2025 | DA3: may-2025 | DB3: jun-2025 | DC3: jul-2025 | DD3: ago-2025 | DE3: sep-2025 | DF3: oct-2025 | DG3: nov-2025 | DH3: dic-2025 | DI3: ene-2026 | DJ3: feb-2026 | DK3: mar-2026 | DL3: abr-2026 | DM3: may-2026 | DN3: jun-2026 | DO3: jul-2026 | DP3: ago-2026 | DQ3: sep-2026 | DR3: oct-2026*
A4: Hencorp · FI Abierto Hencorp Opportunity | CC4: =IF('Valor cuota (fin de mes)'!CC4="","",'Valor cuota (fin de mes)'!CC4/'Resumen'!$D$4-1) | CD4: =IFERROR(IF(OR('Valor cuota (fin de mes)'!CD4="",'Valor cuota (fin de mes)'!CC4=""),"",'Valor cuota (fin de mes)'!CD4/'Valor cuota (fin de mes)'!CC4-1),"") | CE4: =IFERROR(IF(OR('Valor cuota (fin de mes)'!CE4="",'Valor cuota (fin de mes)'!CD4=""),"",'Valor cuota (fin de mes)'!CE4/'Valor cuota (fin de mes)'!CD4-1),"") | CF4: =IFERROR(IF(OR('Valor cuota (fin de mes)'!CF4="",'Valor cuota (fin de mes)'!CE4=""),"",'Valor cuota (fin de mes)'!CF4/'Valor cuota (fin de mes)'!CE4-1),"") | CG4: =IFERROR(IF(OR('Valor cuota (fin de mes)'!CG4="",'Valor cuota (fin de mes)'!CF4=""),"",'Valor cuota (fin de mes)'!CG4/'Valor cuota (fin de mes)'!CF4-1),"") | CH4: =IFERROR(IF(OR('Valor cuota (fin de mes)'!CH4="",'Valor cuota (fin de mes)'!CG4=""),"",'Valor cuota (fin de mes)'!CH4/'Valor cuota (fin de mes)'!CG4-1),"") | CI4: =IFERROR(IF(OR('Valor cuota (fin de mes)'!CI4="",'Valor cuota (fin de mes)'!CH4=""),"",'Valor cuota (fin de mes)'!CI4/'Valor cuota (fin de mes)'!CH4-1),"") | CJ4: =IFERROR(IF(OR('Valor cuota (fin de mes)'!CJ4="",'Valor cuota (fin de mes)'!CI4=""),"",'Valor cuota (fin de mes)'!CJ4/'Valor cuota (fin de mes)'!CI4-1),"") | CK4: =IFERROR(IF(OR('Valor cuota (fin de mes)'!CK4="",'Valor cuota (fin de mes)'!CJ4=""),"",'Valor cuota (fin de mes)'!CK4/'Valor cuota (fin de mes)'!CJ4-1),"") | ... DR4: =IFERROR(IF(OR('Valor cuota (fin de mes)'!DR4="",'Valor cuota (fin de mes)'!DQ4=""),"",'Valor cuota (fin de mes)'!DR4/'Valor cuota (fin de mes)'!DQ4-1),"")
A5: Hencorp · FIC Renta Fija I | CH5: =IF('Valor cuota (fin de mes)'!CH5="","",'Valor cuota (fin de mes)'!CH5/'Resumen'!$D$5-1) | CI5: =IFERROR(IF(OR('Valor cuota (fin de mes)'!CI5="",'Valor cuota (fin de mes)'!CH5=""),"",'Valor cuota (fin de mes)'!CI5/'Valor cuota (fin de mes)'!CH5-1),"") | CJ5: =IFERROR(IF(OR('Valor cuota (fin de mes)'!CJ5="",'Valor cuota (fin de mes)'!CI5=""),"",'Valor cuota (fin de mes)'!CJ5/'Valor cuota (fin de mes)'!CI5-1),"") | CK5: =IFERROR(IF(OR('Valor cuota (fin de mes)'!CK5="",'Valor cuota (fin de mes)'!CJ5=""),"",'Valor cuota (fin de mes)'!CK5/'Valor cuota (fin de mes)'!CJ5-1),"") | CL5: =IFERROR(IF(OR('Valor cuota (fin de mes)'!CL5="",'Valor cuota (fin de mes)'!CK5=""),"",'Valor cuota (fin de mes)'!CL5/'Valor cuota (fin de mes)'!CK5-1),"") | CM5: =IFERROR(IF(OR('Valor cuota (fin de mes)'!CM5="",'Valor cuota (fin de mes)'!CL5=""),"",'Valor cuota (fin de mes)'!CM5/'Valor cuota (fin de mes)'!CL5-1),"") | CN5: =IFERROR(IF(OR('Valor cuota (fin de mes)'!CN5="",'Valor cuota (fin de mes)'!CM5=""),"",'Valor cuota (fin de mes)'!CN5/'Valor cuota (fin de mes)'!CM5-1),"") | CO5: =IFERROR(IF(OR('Valor cuota (fin de mes)'!CO5="",'Valor cuota (fin de mes)'!CN5=""),"",'Valor cuota (fin de mes)'!CO5/'Valor cuota (fin de mes)'!CN5-1),"") | CP5: =IFERROR(IF(OR('Valor cuota (fin de mes)'!CP5="",'Valor cuota (fin de mes)'!CO5=""),"",'Valor cuota (fin de mes)'!CP5/'Valor cuota (fin de mes)'!CO5-1),"") | ... DR5: =IFERROR(IF(OR('Valor cuota (fin de mes)'!DR5="",'Valor cuota (fin de mes)'!DQ5=""),"",'Valor cuota (fin de mes)'!DR5/'Valor cuota (fin de mes)'!DQ5-1),"")
A6: Hencorp · FIC Inmobiliario Hencorp Growth | CM6: =IF('Valor cuota (fin de mes)'!CM6="","",'Valor cuota (fin de mes)'!CM6/'Resumen'!$D$6-1) | CN6: =IFERROR(IF(OR('Valor cuota (fin de mes)'!CN6="",'Valor cuota (fin de mes)'!CM6=""),"",'Valor cuota (fin de mes)'!CN6/'Valor cuota (fin de mes)'!CM6-1),"") | CO6: =IFERROR(IF(OR('Valor cuota (fin de mes)'!CO6="",'Valor cuota (fin de mes)'!CN6=""),"",'Valor cuota (fin de mes)'!CO6/'Valor cuota (fin de mes)'!CN6-1),"") | CP6: =IFERROR(IF(OR('Valor cuota (fin de mes)'!CP6="",'Valor cuota (fin de mes)'!CO6=""),"",'Valor cuota (fin de mes)'!CP6/'Valor cuota (fin de mes)'!CO6-1),"") | CQ6: =IFERROR(IF(OR('Valor cuota (fin de mes)'!CQ6="",'Valor cuota (fin de mes)'!CP6=""),"",'Valor cuota (fin de mes)'!CQ6/'Valor cuota (fin de mes)'!CP6-1),"") | CR6: =IFERROR(IF(OR('Valor cuota (fin de mes)'!CR6="",'Valor cuota (fin de mes)'!CQ6=""),"",'Valor cuota (fin de mes)'!CR6/'Valor cuota (fin de mes)'!CQ6-1),"") | CS6: =IFERROR(IF(OR('Valor cuota (fin de mes)'!CS6="",'Valor cuota (fin de mes)'!CR6=""),"",'Valor cuota (fin de mes)'!CS6/'Valor cuota (fin de mes)'!CR6-1),"") | CT6: =IFERROR(IF(OR('Valor cuota (fin de mes)'!CT6="",'Valor cuota (fin de mes)'!CS6=""),"",'Valor cuota (fin de mes)'!CT6/'Valor cuota (fin de mes)'!CS6-1),"") | CU6: =IFERROR(IF(OR('Valor cuota (fin de mes)'!CU6="",'Valor cuota (fin de mes)'!CT6=""),"",'Valor cuota (fin de mes)'!CU6/'Valor cuota (fin de mes)'!CT6-1),"") | ... DR6: =IFERROR(IF(OR('Valor cuota (fin de mes)'!DR6="",'Valor cuota (fin de mes)'!DQ6=""),"",'Valor cuota (fin de mes)'!DR6/'Valor cuota (fin de mes)'!DQ6-1),"")
A7: Hencorp · FIC Desarrollo Inmob. Hencorp Vivienda 01 | DB7: =IF('Valor cuota (fin de mes)'!DB7="","",'Valor cuota (fin de mes)'!DB7/'Resumen'!$D$7-1) | DC7: =IFERROR(IF(OR('Valor cuota (fin de mes)'!DC7="",'Valor cuota (fin de mes)'!DB7=""),"",'Valor cuota (fin de mes)'!DC7/'Valor cuota (fin de mes)'!DB7-1),"") | DD7: =IFERROR(IF(OR('Valor cuota (fin de mes)'!DD7="",'Valor cuota (fin de mes)'!DC7=""),"",'Valor cuota (fin de mes)'!DD7/'Valor cuota (fin de mes)'!DC7-1),"") | DE7: =IFERROR(IF(OR('Valor cuota (fin de mes)'!DE7="",'Valor cuota (fin de mes)'!DD7=""),"",'Valor cuota (fin de mes)'!DE7/'Valor cuota (fin de mes)'!DD7-1),"") | DF7: =IFERROR(IF(OR('Valor cuota (fin de mes)'!DF7="",'Valor cuota (fin de mes)'!DE7=""),"",'Valor cuota (fin de mes)'!DF7/'Valor cuota (fin de mes)'!DE7-1),"") | DG7: =IFERROR(IF(OR('Valor cuota (fin de mes)'!DG7="",'Valor cuota (fin de mes)'!DF7=""),"",'Valor cuota (fin de mes)'!DG7/'Valor cuota (fin de mes)'!DF7-1),"") | DH7: =IFERROR(IF(OR('Valor cuota (fin de mes)'!DH7="",'Valor cuota (fin de mes)'!DG7=""),"",'Valor cuota (fin de mes)'!DH7/'Valor cuota (fin de mes)'!DG7-1),"") | DI7: =IFERROR(IF(OR('Valor cuota (fin de mes)'!DI7="",'Valor cuota (fin de mes)'!DH7=""),"",'Valor cuota (fin de mes)'!DI7/'Valor cuota (fin de mes)'!DH7-1),"") | DJ7: =IFERROR(IF(OR('Valor cuota (fin de mes)'!DJ7="",'Valor cuota (fin de mes)'!DI7=""),"",'Valor cuota (fin de mes)'!DJ7/'Valor cuota (fin de mes)'!DI7-1),"") | ... DR7: =IFERROR(IF(OR('Valor cuota (fin de mes)'!DR7="",'Valor cuota (fin de mes)'!DQ7=""),"",'Valor cuota (fin de mes)'!DR7/'Valor cuota (fin de mes)'!DQ7-1),"")
A8: Hencorp · FIC Inmobiliario Hencorp Blue Whale | DE8: =IF('Valor cuota (fin de mes)'!DE8="","",'Valor cuota (fin de mes)'!DE8/'Resumen'!$D$8-1) | DF8: =IFERROR(IF(OR('Valor cuota (fin de mes)'!DF8="",'Valor cuota (fin de mes)'!DE8=""),"",'Valor cuota (fin de mes)'!DF8/'Valor cuota (fin de mes)'!DE8-1),"") | DG8: =IFERROR(IF(OR('Valor cuota (fin de mes)'!DG8="",'Valor cuota (fin de mes)'!DF8=""),"",'Valor cuota (fin de mes)'!DG8/'Valor cuota (fin de mes)'!DF8-1),"") | DH8: =IFERROR(IF(OR('Valor cuota (fin de mes)'!DH8="",'Valor cuota (fin de mes)'!DG8=""),"",'Valor cuota (fin de mes)'!DH8/'Valor cuota (fin de mes)'!DG8-1),"") | DI8: =IFERROR(IF(OR('Valor cuota (fin de mes)'!DI8="",'Valor cuota (fin de mes)'!DH8=""),"",'Valor cuota (fin de mes)'!DI8/'Valor cuota (fin de mes)'!DH8-1),"") | DJ8: =IFERROR(IF(OR('Valor cuota (fin de mes)'!DJ8="",'Valor cuota (fin de mes)'!DI8=""),"",'Valor cuota (fin de mes)'!DJ8/'Valor cuota (fin de mes)'!DI8-1),"") | DK8: =IFERROR(IF(OR('Valor cuota (fin de mes)'!DK8="",'Valor cuota (fin de mes)'!DJ8=""),"",'Valor cuota (fin de mes)'!DK8/'Valor cuota (fin de mes)'!DJ8-1),"") | DL8: =IFERROR(IF(OR('Valor cuota (fin de mes)'!DL8="",'Valor cuota (fin de mes)'!DK8=""),"",'Valor cuota (fin de mes)'!DL8/'Valor cuota (fin de mes)'!DK8-1),"") | DM8: =IFERROR(IF(OR('Valor cuota (fin de mes)'!DM8="",'Valor cuota (fin de mes)'!DL8=""),"",'Valor cuota (fin de mes)'!DM8/'Valor cuota (fin de mes)'!DL8-1),"") | ... DR8: =IFERROR(IF(OR('Valor cuota (fin de mes)'!DR8="",'Valor cuota (fin de mes)'!DQ8=""),"",'Valor cuota (fin de mes)'!DR8/'Valor cuota (fin de mes)'!DQ8-1),"")
A9: Hencorp · FIC Inmobiliario Hencorp Commercial Properties | DM9: =IF('Valor cuota (fin de mes)'!DM9="","",'Valor cuota (fin de mes)'!DM9/'Resumen'!$D$9-1) | DN9: =IFERROR(IF(OR('Valor cuota (fin de mes)'!DN9="",'Valor cuota (fin de mes)'!DM9=""),"",'Valor cuota (fin de mes)'!DN9/'Valor cuota (fin de mes)'!DM9-1),"") | DO9: =IFERROR(IF(OR('Valor cuota (fin de mes)'!DO9="",'Valor cuota (fin de mes)'!DN9=""),"",'Valor cuota (fin de mes)'!DO9/'Valor cuota (fin de mes)'!DN9-1),"") | DP9: =IFERROR(IF(OR('Valor cuota (fin de mes)'!DP9="",'Valor cuota (fin de mes)'!DO9=""),"",'Valor cuota (fin de mes)'!DP9/'Valor cuota (fin de mes)'!DO9-1),"") | DQ9: =IFERROR(IF(OR('Valor cuota (fin de mes)'!DQ9="",'Valor cuota (fin de mes)'!DP9=""),"",'Valor cuota (fin de mes)'!DQ9/'Valor cuota (fin de mes)'!DP9-1),"") | DR9: =IFERROR(IF(OR('Valor cuota (fin de mes)'!DR9="",'Valor cuota (fin de mes)'!DQ9=""),"",'Valor cuota (fin de mes)'!DR9/'Valor cuota (fin de mes)'!DQ9-1),"")
A10: SGB · FI Abierto Rentable Corto Plazo | B10: =IF('Valor cuota (fin de mes)'!B10="","",'Valor cuota (fin de mes)'!B10/'Resumen'!$D$10-1) | C10: =IFERROR(IF(OR('Valor cuota (fin de mes)'!C10="",'Valor cuota (fin de mes)'!B10=""),"",'Valor cuota (fin de mes)'!C10/'Valor cuota (fin de mes)'!B10-1),"") | D10: =IFERROR(IF(OR('Valor cuota (fin de mes)'!D10="",'Valor cuota (fin de mes)'!C10=""),"",'Valor cuota (fin de mes)'!D10/'Valor cuota (fin de mes)'!C10-1),"") | E10: =IFERROR(IF(OR('Valor cuota (fin de mes)'!E10="",'Valor cuota (fin de mes)'!D10=""),"",'Valor cuota (fin de mes)'!E10/'Valor cuota (fin de mes)'!D10-1),"") | F10: =IFERROR(IF(OR('Valor cuota (fin de mes)'!F10="",'Valor cuota (fin de mes)'!E10=""),"",'Valor cuota (fin de mes)'!F10/'Valor cuota (fin de mes)'!E10-1),"") | G10: =IFERROR(IF(OR('Valor cuota (fin de mes)'!G10="",'Valor cuota (fin de mes)'!F10=""),"",'Valor cuota (fin de mes)'!G10/'Valor cuota (fin de mes)'!F10-1),"") | H10: =IFERROR(IF(OR('Valor cuota (fin de mes)'!H10="",'Valor cuota (fin de mes)'!G10=""),"",'Valor cuota (fin de mes)'!H10/'Valor cuota (fin de mes)'!G10-1),"") | I10: =IFERROR(IF(OR('Valor cuota (fin de mes)'!I10="",'Valor cuota (fin de mes)'!H10=""),"",'Valor cuota (fin de mes)'!I10/'Valor cuota (fin de mes)'!H10-1),"") | J10: =IFERROR(IF(OR('Valor cuota (fin de mes)'!J10="",'Valor cuota (fin de mes)'!I10=""),"",'Valor cuota (fin de mes)'!J10/'Valor cuota (fin de mes)'!I10-1),"") | ... DR10: =IFERROR(IF(OR('Valor cuota (fin de mes)'!DR10="",'Valor cuota (fin de mes)'!DQ10=""),"",'Valor cuota (fin de mes)'!DR10/'Valor cuota (fin de mes)'!DQ10-1),"")
A11: SGB · FI Abierto Plazo 180 | T11: =IF('Valor cuota (fin de mes)'!T11="","",'Valor cuota (fin de mes)'!T11/'Resumen'!$D$11-1) | U11: =IFERROR(IF(OR('Valor cuota (fin de mes)'!U11="",'Valor cuota (fin de mes)'!T11=""),"",'Valor cuota (fin de mes)'!U11/'Valor cuota (fin de mes)'!T11-1),"") | V11: =IFERROR(IF(OR('Valor cuota (fin de mes)'!V11="",'Valor cuota (fin de mes)'!U11=""),"",'Valor cuota (fin de mes)'!V11/'Valor cuota (fin de mes)'!U11-1),"") | W11: =IFERROR(IF(OR('Valor cuota (fin de mes)'!W11="",'Valor cuota (fin de mes)'!V11=""),"",'Valor cuota (fin de mes)'!W11/'Valor cuota (fin de mes)'!V11-1),"") | X11: =IFERROR(IF(OR('Valor cuota (fin de mes)'!X11="",'Valor cuota (fin de mes)'!W11=""),"",'Valor cuota (fin de mes)'!X11/'Valor cuota (fin de mes)'!W11-1),"") | Y11: =IFERROR(IF(OR('Valor cuota (fin de mes)'!Y11="",'Valor cuota (fin de mes)'!X11=""),"",'Valor cuota (fin de mes)'!Y11/'Valor cuota (fin de mes)'!X11-1),"") | Z11: =IFERROR(IF(OR('Valor cuota (fin de mes)'!Z11="",'Valor cuota (fin de mes)'!Y11=""),"",'Valor cuota (fin de mes)'!Z11/'Valor cuota (fin de mes)'!Y11-1),"") | AA11: =IFERROR(IF(OR('Valor cuota (fin de mes)'!AA11="",'Valor cuota (fin de mes)'!Z11=""),"",'Valor cuota (fin de mes)'!AA11/'Valor cuota (fin de mes)'!Z11-1),"") | AB11: =IFERROR(IF(OR('Valor cuota (fin de mes)'!AB11="",'Valor cuota (fin de mes)'!AA11=""),"",'Valor cuota (fin de mes)'!AB11/'Valor cuota (fin de mes)'!AA11-1),"") | ... DR11: =IFERROR(IF(OR('Valor cuota (fin de mes)'!DR11="",'Valor cuota (fin de mes)'!DQ11=""),"",'Valor cuota (fin de mes)'!DR11/'Valor cuota (fin de mes)'!DQ11-1),"")
A12: Atlántida · Fondo Abierto de Liquidez | R12: =IF('Valor cuota (fin de mes)'!R12="","",'Valor cuota (fin de mes)'!R12/'Resumen'!$D$12-1) | S12: =IFERROR(IF(OR('Valor cuota (fin de mes)'!S12="",'Valor cuota (fin de mes)'!R12=""),"",'Valor cuota (fin de mes)'!S12/'Valor cuota (fin de mes)'!R12-1),"") | T12: =IFERROR(IF(OR('Valor cuota (fin de mes)'!T12="",'Valor cuota (fin de mes)'!S12=""),"",'Valor cuota (fin de mes)'!T12/'Valor cuota (fin de mes)'!S12-1),"") | U12: =IFERROR(IF(OR('Valor cuota (fin de mes)'!U12="",'Valor cuota (fin de mes)'!T12=""),"",'Valor cuota (fin de mes)'!U12/'Valor cuota (fin de mes)'!T12-1),"") | V12: =IFERROR(IF(OR('Valor cuota (fin de mes)'!V12="",'Valor cuota (fin de mes)'!U12=""),"",'Valor cuota (fin de mes)'!V12/'Valor cuota (fin de mes)'!U12-1),"") | W12: =IFERROR(IF(OR('Valor cuota (fin de mes)'!W12="",'Valor cuota (fin de mes)'!V12=""),"",'Valor cuota (fin de mes)'!W12/'Valor cuota (fin de mes)'!V12-1),"") | X12: =IFERROR(IF(OR('Valor cuota (fin de mes)'!X12="",'Valor cuota (fin de mes)'!W12=""),"",'Valor cuota (fin de mes)'!X12/'Valor cuota (fin de mes)'!W12-1),"") | Y12: =IFERROR(IF(OR('Valor cuota (fin de mes)'!Y12="",'Valor cuota (fin de mes)'!X12=""),"",'Valor cuota (fin de mes)'!Y12/'Valor cuota (fin de mes)'!X12-1),"") | Z12: =IFERROR(IF(OR('Valor cuota (fin de mes)'!Z12="",'Valor cuota (fin de mes)'!Y12=""),"",'Valor cuota (fin de mes)'!Z12/'Valor cuota (fin de mes)'!Y12-1),"") | ... DO12: =IFERROR(IF(OR('Valor cuota (fin de mes)'!DO12="",'Valor cuota (fin de mes)'!DN12=""),"",'Valor cuota (fin de mes)'!DO12/'Valor cuota (fin de mes)'!DN12-1),"")
A13: Atlántida · Fondo de Inversion Abierto Atlantida de Renta Mixta | DF13: =IF('Valor cuota (fin de mes)'!DF13="","",'Valor cuota (fin de mes)'!DF13/'Resumen'!$D$13-1) | DG13: =IFERROR(IF(OR('Valor cuota (fin de mes)'!DG13="",'Valor cuota (fin de mes)'!DF13=""),"",'Valor cuota (fin de mes)'!DG13/'Valor cuota (fin de mes)'!DF13-1),"") | DH13: =IFERROR(IF(OR('Valor cuota (fin de mes)'!DH13="",'Valor cuota (fin de mes)'!DG13=""),"",'Valor cuota (fin de mes)'!DH13/'Valor cuota (fin de mes)'!DG13-1),"") | DI13: =IFERROR(IF(OR('Valor cuota (fin de mes)'!DI13="",'Valor cuota (fin de mes)'!DH13=""),"",'Valor cuota (fin de mes)'!DI13/'Valor cuota (fin de mes)'!DH13-1),"") | DJ13: =IFERROR(IF(OR('Valor cuota (fin de mes)'!DJ13="",'Valor cuota (fin de mes)'!DI13=""),"",'Valor cuota (fin de mes)'!DJ13/'Valor cuota (fin de mes)'!DI13-1),"") | DK13: =IFERROR(IF(OR('Valor cuota (fin de mes)'!DK13="",'Valor cuota (fin de mes)'!DJ13=""),"",'Valor cuota (fin de mes)'!DK13/'Valor cuota (fin de mes)'!DJ13-1),"") | DL13: =IFERROR(IF(OR('Valor cuota (fin de mes)'!DL13="",'Valor cuota (fin de mes)'!DK13=""),"",'Valor cuota (fin de mes)'!DL13/'Valor cuota (fin de mes)'!DK13-1),"") | DM13: =IFERROR(IF(OR('Valor cuota (fin de mes)'!DM13="",'Valor cuota (fin de mes)'!DL13=""),"",'Valor cuota (fin de mes)'!DM13/'Valor cuota (fin de mes)'!DL13-1),"") | DN13: =IFERROR(IF(OR('Valor cuota (fin de mes)'!DN13="",'Valor cuota (fin de mes)'!DM13=""),"",'Valor cuota (fin de mes)'!DN13/'Valor cuota (fin de mes)'!DM13-1),"") | DO13: =IFERROR(IF(OR('Valor cuota (fin de mes)'!DO13="",'Valor cuota (fin de mes)'!DN13=""),"",'Valor cuota (fin de mes)'!DO13/'Valor cuota (fin de mes)'!DN13-1),"")
A14: Atlántida · Fondo de Inversión Abierto de Crecimiento | T14: =IF('Valor cuota (fin de mes)'!T14="","",'Valor cuota (fin de mes)'!T14/'Resumen'!$D$14-1) | U14: =IFERROR(IF(OR('Valor cuota (fin de mes)'!U14="",'Valor cuota (fin de mes)'!T14=""),"",'Valor cuota (fin de mes)'!U14/'Valor cuota (fin de mes)'!T14-1),"") | V14: =IFERROR(IF(OR('Valor cuota (fin de mes)'!V14="",'Valor cuota (fin de mes)'!U14=""),"",'Valor cuota (fin de mes)'!V14/'Valor cuota (fin de mes)'!U14-1),"") | W14: =IFERROR(IF(OR('Valor cuota (fin de mes)'!W14="",'Valor cuota (fin de mes)'!V14=""),"",'Valor cuota (fin de mes)'!W14/'Valor cuota (fin de mes)'!V14-1),"") | X14: =IFERROR(IF(OR('Valor cuota (fin de mes)'!X14="",'Valor cuota (fin de mes)'!W14=""),"",'Valor cuota (fin de mes)'!X14/'Valor cuota (fin de mes)'!W14-1),"") | Y14: =IFERROR(IF(OR('Valor cuota (fin de mes)'!Y14="",'Valor cuota (fin de mes)'!X14=""),"",'Valor cuota (fin de mes)'!Y14/'Valor cuota (fin de mes)'!X14-1),"") | Z14: =IFERROR(IF(OR('Valor cuota (fin de mes)'!Z14="",'Valor cuota (fin de mes)'!Y14=""),"",'Valor cuota (fin de mes)'!Z14/'Valor cuota (fin de mes)'!Y14-1),"") | AA14: =IFERROR(IF(OR('Valor cuota (fin de mes)'!AA14="",'Valor cuota (fin de mes)'!Z14=""),"",'Valor cuota (fin de mes)'!AA14/'Valor cuota (fin de mes)'!Z14-1),"") | AB14: =IFERROR(IF(OR('Valor cuota (fin de mes)'!AB14="",'Valor cuota (fin de mes)'!AA14=""),"",'Valor cuota (fin de mes)'!AB14/'Valor cuota (fin de mes)'!AA14-1),"") | ... DO14: =IFERROR(IF(OR('Valor cuota (fin de mes)'!DO14="",'Valor cuota (fin de mes)'!DN14=""),"",'Valor cuota (fin de mes)'!DO14/'Valor cuota (fin de mes)'!DN14-1),"")
A15: Atlántida · Fondo de Inversión Cerrado Inmobiliario Atlántida Progresa + | AK15: =IF('Valor cuota (fin de mes)'!AK15="","",'Valor cuota (fin de mes)'!AK15/'Resumen'!$D$15-1) | AL15: =IFERROR(IF(OR('Valor cuota (fin de mes)'!AL15="",'Valor cuota (fin de mes)'!AK15=""),"",'Valor cuota (fin de mes)'!AL15/'Valor cuota (fin de mes)'!AK15-1),"") | AM15: =IFERROR(IF(OR('Valor cuota (fin de mes)'!AM15="",'Valor cuota (fin de mes)'!AL15=""),"",'Valor cuota (fin de mes)'!AM15/'Valor cuota (fin de mes)'!AL15-1),"") | AN15: =IFERROR(IF(OR('Valor cuota (fin de mes)'!AN15="",'Valor cuota (fin de mes)'!AM15=""),"",'Valor cuota (fin de mes)'!AN15/'Valor cuota (fin de mes)'!AM15-1),"") | AO15: =IFERROR(IF(OR('Valor cuota (fin de mes)'!AO15="",'Valor cuota (fin de mes)'!AN15=""),"",'Valor cuota (fin de mes)'!AO15/'Valor cuota (fin de mes)'!AN15-1),"") | AP15: =IFERROR(IF(OR('Valor cuota (fin de mes)'!AP15="",'Valor cuota (fin de mes)'!AO15=""),"",'Valor cuota (fin de mes)'!AP15/'Valor cuota (fin de mes)'!AO15-1),"") | AQ15: =IFERROR(IF(OR('Valor cuota (fin de mes)'!AQ15="",'Valor cuota (fin de mes)'!AP15=""),"",'Valor cuota (fin de mes)'!AQ15/'Valor cuota (fin de mes)'!AP15-1),"") | AR15: =IFERROR(IF(OR('Valor cuota (fin de mes)'!AR15="",'Valor cuota (fin de mes)'!AQ15=""),"",'Valor cuota (fin de mes)'!AR15/'Valor cuota (fin de mes)'!AQ15-1),"") | AS15: =IFERROR(IF(OR('Valor cuota (fin de mes)'!AS15="",'Valor cuota (fin de mes)'!AR15=""),"",'Valor cuota (fin de mes)'!AS15/'Valor cuota (fin de mes)'!AR15-1),"") | ... DO15: =IFERROR(IF(OR('Valor cuota (fin de mes)'!DO15="",'Valor cuota (fin de mes)'!DN15=""),"",'Valor cuota (fin de mes)'!DO15/'Valor cuota (fin de mes)'!DN15-1),"")

Sheet Cierre 31-dic (mensual)
A1: Cierre 31-dic (mensual)
A2: Rendimiento del mes de diciembre de cada año (mismo indicador que la hoja mensual). El año en curso = ultimo mes disponible (parcial)
A3: Fondo | B3: 2016 | C3: 2017 | D3: 2018 | E3: 2019 | F3: 2020 | G3: 2021 | H3: 2022 | I3: 2023 | J3: 2024 | K3: 2025 | L3: 2026 (YTD)
A4: Hencorp · FI Abierto Hencorp Opportunity | I4: ='Rendimiento mensual'!CJ4 | J4: ='Rendimiento mensual'!CV4 | K4: ='Rendimiento mensual'!DH4 | L4: ='Rendimiento mensual'!DR4
A5: Hencorp · FIC Renta Fija I | I5: ='Rendimiento mensual'!CJ5 | J5: ='Rendimiento mensual'!CV5 | K5: ='Rendimiento mensual'!DH5 | L5: ='Rendimiento mensual'!DR5
A6: Hencorp · FIC Inmobiliario Hencorp Growth | J6: ='Rendimiento mensual'!CV6 | K6: ='Rendimiento mensual'!DH6 | L6: ='Rendimiento mensual'!DR6
A7: Hencorp · FIC Desarrollo Inmob. Hencorp Vivienda 01 | K7: ='Rendimiento mensual'!DH7 | L7: ='Rendimiento mensual'!DR7
A8: Hencorp · FIC Inmobiliario Hencorp Blue Whale | K8: ='Rendimiento mensual'!DH8 | L8: ='Rendimiento mensual'!DR8
A9: Hencorp · FIC Inmobiliario Hencorp Commercial Properties | L9: ='Rendimiento mensual'!DR9
A10: SGB · FI Abierto Rentable Corto Plazo | B10: ='Rendimiento mensual'!D10 | C10: ='Rendimiento mensual'!P10 | D10: ='Rendimiento mensual'!AB10 | E10: ='Rendimiento mensual'!AN10 | F10: ='Rendimiento mensual'!AZ10 | G10: ='Rendimiento mensual'!BL10 | H10: ='Rendimiento mensual'!BX10 | I10: ='Rendimiento mensual'!CJ10 | J10: ='Rendimiento mensual'!CV10 | K10: ='Rendimiento mensual'!DH10 | L10: ='Rendimiento mensual'!DR10
A11: SGB · FI Abierto Plazo 180 | D11: ='Rendimiento mensual'!AB11 | E11: ='Rendimiento mensual'!AN11 | F11: ='Rendimiento mensual'!AZ11 | G11: ='Rendimiento mensual'!BL11 | H11: ='Rendimiento mensual'!BX11 | I11: ='Rendimiento mensual'!CJ11 | J11: ='Rendimiento mensual'!CV11 | K11: ='Rendimiento mensual'!DH11 | L11: ='Rendimiento mensual'!DR11
A12: Atlántida · Fondo Abierto de Liquidez | D12: ='Rendimiento mensual'!AB12 | E12: ='Rendimiento mensual'!AN12 | F12: ='Rendimiento mensual'!AZ12 | G12: ='Rendimiento mensual'!BL12 | H12: ='Rendimiento mensual'!BX12 | I12: ='Rendimiento mensual'!CJ12 | J12: ='Rendimiento mensual'!CV12 | K12: ='Rendimiento mensual'!DH12
A13: Atlántida · Fondo de Inversion Abierto Atlantida de Renta Mixta | K13: ='Rendimiento mensual'!DH13
A14: Atlántida · Fondo de Inversión Abierto de Crecimiento | D14: ='Rendimiento mensual'!AB14 | E14: ='Rendimiento mensual'!AN14 | F14: ='Rendimiento mensual'!AZ14 | G14: ='Rendimiento mensual'!BL14 | H14: ='Rendimiento mensual'!BX14 | I14: ='Rendimiento mensual'!CJ14 | J14: ='Rendimiento mensual'!CV14 | K14: ='Rendimiento mensual'!DH14
A15: Atlántida · Fondo de Inversión Cerrado Inmobiliario Atlántida Progresa + | E15: ='Rendimiento mensual'!AN15 | F15: ='Rendimiento mensual'!AZ15 | G15: ='Rendimiento mensual'!BL15 | H15: ='Rendimiento mensual'!BX15 | I15: ='Rendimiento mensual'!CJ15 | J15: ='Rendimiento mensual'!CV15 | K15: ='Rendimiento mensual'!DH15

Sheet Rendimiento anual
A1: Rendimiento anual
A2: Rendimiento ANUAL (ene–dic) desde la cuota. Año de lanzamiento = desde la base; el año en curso = YTD (parcial)
A3: Fondo | B3: 2016 | C3: 2017 | D3: 2018 | E3: 2019 | F3: 2020 | G3: 2021 | H3: 2022 | I3: 2023 | J3: 2024 | K3: 2025 | L3: 2026 (YTD)
A4: Hencorp · FI Abierto Hencorp Opportunity | I4: =IFERROR('Valor cuota (fin de mes)'!CJ4/'Resumen'!$D$4-1,"") | J4: =IFERROR('Valor cuota (fin de mes)'!CV4/'Valor cuota (fin de mes)'!CJ4-1,"") | K4: =IFERROR('Valor cuota (fin de mes)'!DH4/'Valor cuota (fin de mes)'!CV4-1,"") | L4: =IFERROR('Valor cuota (fin de mes)'!DR4/'Valor cuota (fin de mes)'!DH4-1,"")
A5: Hencorp · FIC Renta Fija I | I5: =IFERROR('Valor cuota (fin de mes)'!CJ5/'Resumen'!$D$5-1,"") | J5: =IFERROR('Valor cuota (fin de mes)'!CV5/'Valor cuota (fin de mes)'!CJ5-1,"") | K5: =IFERROR('Valor cuota (fin de mes)'!DH5/'Valor cuota (fin de mes)'!CV5-1,"") | L5: =IFERROR('Valor cuota (fin de mes)'!DR5/'Valor cuota (fin de mes)'!DH5-1,"")
A6: Hencorp · FIC Inmobiliario Hencorp Growth | J6: =IFERROR('Valor cuota (fin de mes)'!CV6/'Resumen'!$D$6-1,"") | K6: =IFERROR('Valor cuota (fin de mes)'!DH6/'Valor cuota (fin de mes)'!CV6-1,"") | L6: =IFERROR('Valor cuota (fin de mes)'!DR6/'Valor cuota (fin de mes)'!DH6-1,"")
A7: Hencorp · FIC Desarrollo Inmob. Hencorp Vivienda 01 | K7: =IFERROR('Valor cuota (fin de mes)'!DH7/'Resumen'!$D$7-1,"") | L7: =IFERROR('Valor cuota (fin de mes)'!DR7/'Valor cuota (fin de mes)'!DH7-1,"")
A8: Hencorp · FIC Inmobiliario Hencorp Blue Whale | K8: =IFERROR('Valor cuota (fin de mes)'!DH8/'Resumen'!$D$8-1,"") | L8: =IFERROR('Valor cuota (fin de mes)'!DR8/'Valor cuota (fin de mes)'!DH8-1,"")
A9: Hencorp · FIC Inmobiliario Hencorp Commercial Properties | L9: =IFERROR('Valor cuota (fin de mes)'!DR9/'Resumen'!$D$9-1,"")
A10: SGB · FI Abierto Rentable Corto Plazo | B10: =IFERROR('Valor cuota (fin de mes)'!D10/'Resumen'!$D$10-1,"") | C10: =IFERROR('Valor cuota (fin de mes)'!P10/'Valor cuota (fin de mes)'!D10-1,"") | D10: =IFERROR('Valor cuota (fin de mes)'!AB10/'Valor cuota (fin de mes)'!P10-1,"") | E10: =IFERROR('Valor cuota (fin de mes)'!AN10/'Valor cuota (fin de mes)'!AB10-1,"") | F10: =IFERROR('Valor cuota (fin de mes)'!AZ10/'Valor cuota (fin de mes)'!AN10-1,"") | G10: =IFERROR('Valor cuota (fin de mes)'!BL10/'Valor cuota (fin de mes)'!AZ10-1,"") | H10: =IFERROR('Valor cuota (fin de mes)'!BX10/'Valor cuota (fin de mes)'!BL10-1,"") | I10: =IFERROR('Valor cuota (fin de mes)'!CJ10/'Valor cuota (fin de mes)'!BX10-1,"") | J10: =IFERROR('Valor cuota (fin de mes)'!CV10/'Valor cuota (fin de mes)'!CJ10-1,"") | K10: =IFERROR('Valor cuota (fin de mes)'!DH10/'Valor cuota (fin de mes)'!CV10-1,"") | L10: =IFERROR('Valor cuota (fin de mes)'!DR10/'Valor cuota (fin de mes)'!DH10-1,"")
A11: SGB · FI Abierto Plazo 180 | D11: =IFERROR('Valor cuota (fin de mes)'!AB11/'Resumen'!$D$11-1,"") | E11: =IFERROR('Valor cuota (fin de mes)'!AN11/'Valor cuota (fin de mes)'!AB11-1,"") | F11: =IFERROR('Valor cuota (fin de mes)'!AZ11/'Valor cuota (fin de mes)'!AN11-1,"") | G11: =IFERROR('Valor cuota (fin de mes)'!BL11/'Valor cuota (fin de mes)'!AZ11-1,"") | H11: =IFERROR('Valor cuota (fin de mes)'!BX11/'Valor cuota (fin de mes)'!BL11-1,"") | I11: =IFERROR('Valor cuota (fin de mes)'!CJ11/'Valor cuota (fin de mes)'!BX11-1,"") | J11: =IFERROR('Valor cuota (fin de mes)'!CV11/'Valor cuota (fin de mes)'!CJ11-1,"") | K11: =IFERROR('Valor cuota (fin de mes)'!DH11/'Valor cuota (fin de mes)'!CV11-1,"") | L11: =IFERROR('Valor cuota (fin de mes)'!DR11/'Valor cuota (fin de mes)'!DH11-1,"")
A12: Atlántida · Fondo Abierto de Liquidez | D12: =IFERROR('Valor cuota (fin de mes)'!AB12/'Resumen'!$D$12-1,"") | E12: =IFERROR('Valor cuota (fin de mes)'!AN12/'Valor cuota (fin de mes)'!AB12-1,"") | F12: =IFERROR('Valor cuota (fin de mes)'!AZ12/'Valor cuota (fin de mes)'!AN12-1,"") | G12: =IFERROR('Valor cuota (fin de mes)'!BL12/'Valor cuota (fin de mes)'!AZ12-1,"") | H12: =IFERROR('Valor cuota (fin de mes)'!BX12/'Valor cuota (fin de mes)'!BL12-1,"") | I12: =IFERROR('Valor cuota (fin de mes)'!CJ12/'Valor cuota (fin de mes)'!BX12-1,"") | J12: =IFERROR('Valor cuota (fin de mes)'!CV12/'Valor cuota (fin de mes)'!CJ12-1,"") | K12: =IFERROR('Valor cuota (fin de mes)'!DH12/'Valor cuota (fin de mes)'!CV12-1,"")
A13: Atlántida · Fondo de Inversion Abierto Atlantida de Renta Mixta | K13: =IFERROR('Valor cuota (fin de mes)'!DH13/'Resumen'!$D$13-1,"")
A14: Atlántida · Fondo de Inversión Abierto de Crecimiento | D14: =IFERROR('Valor cuota (fin de mes)'!AB14/'Resumen'!$D$14-1,"") | E14: =IFERROR('Valor cuota (fin de mes)'!AN14/'Valor cuota (fin de mes)'!AB14-1,"") | F14: =IFERROR('Valor cuota (fin de mes)'!AZ14/'Valor cuota (fin de mes)'!AN14-1,"") | G14: =IFERROR('Valor cuota (fin de mes)'!BL14/'Valor cuota (fin de mes)'!AZ14-1,"") | H14: =IFERROR('Valor cuota (fin de mes)'!BX14/'Valor cuota (fin de mes)'!BL14-1,"") | I14: =IFERROR('Valor cuota (fin de mes)'!CJ14/'Valor cuota (fin de mes)'!BX14-1,"") | J14: =IFERROR('Valor cuota (fin de mes)'!CV14/'Valor cuota (fin de mes)'!CJ14-1,"") | K14: =IFERROR('Valor cuota (fin de mes)'!DH14/'Valor cuota (fin de mes)'!CV14-1,"")
A15: Atlántida · Fondo de Inversión Cerrado Inmobiliario Atlántida Progresa + | E15: =IFERROR('Valor cuota (fin de mes)'!AN15/'Resumen'!$D$15-1,"") | F15: =IFERROR('Valor cuota (fin de mes)'!AZ15/'Valor cuota (fin de mes)'!AN15-1,"") | G15: =IFERROR('Valor cuota (fin de mes)'!BL15/'Valor cuota (fin de mes)'!AZ15-1,"") | H15: =IFERROR('Valor cuota (fin de mes)'!BX15/'Valor cuota (fin de mes)'!BL15-1,"") | I15: =IFERROR('Valor cuota (fin de mes)'!CJ15/'Valor cuota (fin de mes)'!BX15-1,"") | J15: =IFERROR('Valor cuota (fin de mes)'!CV15/'Valor cuota (fin de mes)'!CJ15-1,"") | K15: =IFERROR('Valor cuota (fin de mes)'!DH15/'Valor cuota (fin de mes)'!CV15-1,"")

Sheet Diario
A1: Detalle diario — 12 fondos de inversión
A2: Fondos de Inversión El Salvador — Todas las gestoras | Fuente: sitios oficiales de cada gestora | datos al 2026-10-11 (actualización 2026-10-11) | una fila por día · lo más reciente arriba · se actualiza a diario
A3: Fecha | B3: Hencorp · Abierto Hencorp Opportunity | E3: Hencorp · Renta Fija I | H3: Hencorp · Inmobiliario Hencorp Growth | K3: Hencorp · Desarrollo Inmob. Hencorp Vivienda 01 | N3: Hencorp · Inmobiliario Hencorp Blue Whale | Q3: Hencorp · Inmobiliario Hencorp Commercial Properties | T3: SGB · Abierto Rentable Corto Plazo | W3: SGB · Abierto Plazo 180 | Z3: Atlántida · Fondo Abierto de Liquidez | AC3: Atlántida · Fondo de Inversion Abierto Atlantida de Renta Mixta | AF3: Atlántida · Fondo de Inversión Abierto de Crecimiento | AI3: Atlántida · Fondo de Inversión Cerrado Inmobiliario Atlántida Progresa +
B4: Valor cuota | C4: Rend. diario | D4: Patrimonio | E4: Valor cuota | F4: Rend. diario | G4: Patrimonio | H4: Valor cuota | I4: Rend. diario | J4: Patrimonio | K4: Valor cuota | L4: Rend. diario | M4: Patrimonio | N4: Valor cuota | O4: Rend. diario | P4: Patrimonio | Q4: Valor cuota | R4: Rend. diario | S4: Patrimonio | T4: Valor cuota | U4: Rend. diario | V4: Patrimonio | W4: Valor cuota | X4: Rend. diario | Y4: Patrimonio | Z4: Valor cuota | AA4: Rend. diario | AB4: Patrimonio | AC4: Valor cuota | AD4: Rend. diario | AE4: Patrimonio | AF4: Valor cuota | AG4: Rend. diario | AH4: Patrimonio | AI4: Valor cuota | AJ4: Rend. diario | AK4: Patrimonio
A5: 46306 | H5: 1245.9946 | I5: 0.000112 | J5: 30636516 | K5: 1171.9346 | L5: -4.4e-05 | M5: 18624385 | N5: 1012.9144 | O5: 0.000101 | P5: 9976194.1 | Q5: 1053.7491 | R5: 0.000304 | S5: 13646050 | T5: 1.4209956 | U5: 0.000112 | V5: 89242967 | W5: 1.5810436 | X5: 0.000147 | Y5: 39306328
A6: 46305 | B6: 1.1915885 | C6: 0.000129 | D6: 2.5994886e+08 | E6: 1052.6451 | F6: 0.000234 | G6: 6.8920467e+08 | H6: 1245.8547 | I6: 0.000112 | J6: 30633075 | K6: 1171.9856 | L6: -4.4e-05 | M6: 18625195 | N6: 1012.8125 | O6: 0.000101 | P6: 9975190.7 | Q6: 1053.4289 | R6: 0.000304 | S6: 13641904 | T6: 1.420837 | U6: 0.000112 | V6: 89233007 | W6: 1.5808106 | X6: 0.000147 | Y6: 39470504
A7: 46304 | B7: 1.1914348 | C7: 0.000141 | D7: 2.58886e+08 | E7: 1052.3986 | F7: 0.000234 | G7: 6.8904328e+08 | H7: 1245.7147 | I7: 0.000112 | J7: 30629633 | K7: 1172.0366 | L7: -4.4e-05 | M7: 18626006 | N7: 1012.7107 | O7: 0.000101 | P7: 9974187.3 | Q7: 1053.1087 | R7: 0.000304 | S7: 13637758 | T7: 1.4206784 | U7: 0.000112 | V7: 89223050 | W7: 1.5805781 | X7: 0.000147 | Y7: 39544098
A8: 46303 | B8: 1.1912664 | C8: 0.000125 | D8: 2.4113183e+08 | E8: 1052.1525 | F8: 0.000234 | G8: 6.8888215e+08 | H8: 1245.5748 | I8: 0.000112 | J8: 30626192 | K8: 1172.0876 | L8: -7.5e-05 | M8: 18626816 | N8: 1012.6088 | O8: 0.000101 | P8: 9973183.8 | Q8: 1052.7886 | R8: 0.000304 | S8: 13633612 | T8: 1.4205198 | U8: 0.000111 | V8: 89157035 | W8: 1.5803452 | X8: 0.000148 | Y8: 39469167
A9: 46302 | B9: 1.1911176 | C9: 0.000131 | D9: 2.4060634e+08 | E9: 1051.9063 | F9: 0.000234 | G9: 6.8872089e+08 | H9: 1245.4348 | I9: 0.000112 | J9: 30622751 | K9: 1172.1749 | L9: -4.1e-05 | M9: 18628204 | N9: 1012.5069 | O9: 0.000101 | P9: 9972180.3 | Q9: 1052.4684 | R9: 0.000304 | S9: 13629466 | T9: 1.4203615 | U9: 0.000111 | V9: 89320795 | W9: 1.5801121 | X9: 0.000157 | Y9: 39459929
A10: 46301 | B10: 1.1909616 | C10: 0.000129 | D10: 2.3955414e+08 | E10: 1051.6597 | F10: 0.000234 | G10: 688559476 | H10: 1245.2948 | I10: 0.000117 | J10: 30619310 | K10: 1172.2227 | L10: -4.1e-05 | M10: 18628963 | N10: 1012.405 | O10: 0.000101 | P10: 9971176.7 | Q10: 1052.1482 | R10: 0.000304 | S10: 13625320 | T10: 1.4202043 | U10: 0.000111 | V10: 91855587 | W10: 1.5798642 | X10: 0.000148 | Y10: 39464496
A11: 46300 | B11: 1.1908078 | C11: 0.000129 | D11: 2.3889229e+08 | E11: 1051.4134 | F11: 0.000233 | G11: 6.8839818e+08 | H11: 1245.1493 | I11: 0.000117 | J11: 30615731 | K11: 1172.2705 | L11: -0.000203 | M11: 18629722 | N11: 1012.3031 | O11: 0.000101 | P11: 9970173.1 | Q11: 1051.8281 | R11: 0.000304 | S11: 13621173 | T11: 1.4200464 | U11: 0.000111 | V11: 91707160 | W11: 1.5796309 | X11: 0.000148 | Y11: 39465497
A12: 46299 | B12: 1.1906543 | C12: 0.000131 | D12: 2.4112086e+08 | E12: 1051.168 | F12: 0.000234 | G12: 6.8823755e+08 | H12: 1245.0037 | I12: 0.000117 | J12: 30612152 | K12: 1172.5081 | L12: -4.1e-05 | M12: 18633499 | N12: 1012.2012 | O12: 0.000101 | P12: 9969169.4 | Q12: 1051.5079 | R12: 0.000305 | S12: 13617027 | T12: 1.4198885 | U12: 0.000111 | V12: 91561655 | W12: 1.5793964 | X12: 0.000148 | Y12: 39368819
A13: 46298 | B13: 1.1904988 | C13: 0.000131 | D13: 2.4110996e+08 | E13: 1050.9216 | F13: 0.000235 | G13: 6.8807621e+08 | H13: 1244.8582 | I13: 0.000117 | J13: 30608572 | K13: 1172.5559 | L13: -4.1e-05 | M13: 18634258 | N13: 1012.0993 | O13: 0.000101 | P13: 9968165.6 | Q13: 1051.1877 | R13: 0.000305 | S13: 13612881 | T13: 1.4197306 | U13: 0.000111 | V13: 91551472 | W13: 1.5791621 | X13: 0.000148 | Y13: 39388512
A14: 46297 | B14: 1.1903431 | C14: 0.000134 | D14: 2.4098208e+08 | E14: 1050.6752 | F14: 0.000233 | G14: 6.8791487e+08 | H14: 1244.7126 | I14: 0.000117 | J14: 30604993 | K14: 1172.6037 | L14: -4.1e-05 | M14: 18635017 | N14: 1011.9973 | O14: 0.000101 | P14: 9967161.8 | Q14: 1050.8675 | R14: 0.000305 | S14: 13608734 | T14: 1.4195727 | U14: 0.00014 | V14: 91541293 | W14: 1.5789287 | X14: 0.000156 | Y14: 39517373
A15: 46296 | B15: 1.1901837 | C15: 0.000138 | D15: 2.3522435e+08 | E15: 1050.4304 | F15: 0.000235 | G15: 6.8775463e+08 | H15: 1244.567 | I15: 0.000116 | J15: 30601414 | K15: 1172.6514 | L15: -4.1e-05 | M15: 18635777 | N15: 1011.8954 | O15: 0.000101 | P15: 9966158 | Q15: 1050.5473 | R15: 0.000305 | S15: 13604588 | T15: 1.4193746 | U15: 0.000113 | V15: 91275102 | W15: 1.5786821 | X15: 0.000148 | Y15: 39500977
A16: 46295 | B16: 1.19002 | C16: 0.000118 | D16: 2.3037484e+08 | E16: 1050.184 | F16: 0.000234 | G16: 6.875933e+08 | H16: 1244.4226 | I16: 0.000177 | J16: 30597864 | K16: 1172.6999 | L16: -4.1e-05 | M16: 18636547 | N16: 1011.7935 | O16: 0.000396 | P16: 9965154.1 | Q16: 1050.2271 | R16: 0.000317 | S16: 13600441 | T16: 1.4192145 | U16: 0.000113 | V16: 91115242 | W16: 1.578449 | X16: 0.000148 | Y16: 39536722
A17: 46294 | B17: 1.1898794 | C17: 0.000129 | D17: 2.2698861e+08 | E17: 1049.938 | F17: 0.000217 | G17: 6.874322e+08 | H17: 1244.2025 | I17: 0.000177 | J17: 30592452 | K17: 1172.7484 | L17: -4.1e-05 | M17: 18637318 | N17: 1011.3929 | O17: 0.000314 | P17: 9961208.6 | Q17: 1049.8942 | R17: 0.000317 | S17: 13596129 | T17: 1.419054 | U17: 0.000113 | V17: 89650008 | W17: 1.5782162 | X17: 0.000149 | Y17: 39522151
... A93: 46218 | B93: 1.1783813 | C93: 0.000127 | D93: 2.372933e+08 | E93: 1044.46 | F93: 0.000236 | G93: 6.8384554e+08 | H93: 1222.7709 | I93: 0.000137 | J93: 27374171 | K93: 1175.0751 | L93: -1.3e-05 | M93: 18674293 | N93: 1013.2342 | O93: 4.4e-05 | P93: 6949773.4 | Q93: 1022.0311 | R93: 0.000388 | S93: 13235303 | T93: 1.4070943 | U93: 0.000102 | V93: 93659949 | W93: 1.5609661 | X93: 0.000145 | Y93: 45550173
A94: 46217 | B94: 1.1782314 | C94: 0.000136 | D94: 2.38325e+08 | E94: 1044.2136 | F94: 0.000235 | G94: 6.8368425e+08 | H94: 1222.6034 | I94: 0.000137 | J94: 27370423 | K94: 1175.0904 | L94: -1.3e-05 | M94: 18674537 | N94: 1013.1896 | O94: 4.4e-05 | P94: 6949467.6 | Q94: 1021.6348 | R94: 0.000388 | S94: 13230171 | T94: 1.4069506 | U94: 0.000103 | V94: 93922582 | W94: 1.5607399 | X94: 0.000145 | Y94: 45581319 | Z94: 1.3490205 | AA94: 0.000106 | AB94: 32192093 | AC94: 1.0542528 | AD94: 0.000717 | AE94: 13305390 | AF94: 1.5269554 | AG94: 0.000228 | AH94: 26949440 | AI94: 5965.8165 | AJ94: 0.00013 | AK94: 71876157
A95: 46216 | B95: 1.1780717 | C95: 0.000132 | D95: 2.2794225e+08 | E95: 1043.9686 | F95: 0.000235 | G95: 6.8352382e+08 | H95: 1222.436 | I95: 0.000137 | J95: 27366674 | K95: 1175.1057 | L95: -1.3e-05 | M95: 18674780 | N95: 1013.145 | O95: 4.4e-05 | P95: 6949161.7 | Q95: 1021.2385 | R95: 0.000388 | S95: 13225039 | T95: 1.4068055 | U95: 0.000103 | V95: 92019558 | W95: 1.5605132 | X95: 0.000146 | Y95: 45487357 | Z95: 1.3488782 | AA95: 0.000106 | AB95: 32210245 | AC95: 1.0534972 | AD95: -0.000582 | AE95: 13251236 | AF95: 1.5266078 | AG95: 0.000157 | AH95: 26899436 | AI95: 5965.0419 | AJ95: 0.000211 | AK95: 71866825
A96: 46215 | B96: 1.1779159 | C96: 0.000133 | D96: 2.2841595e+08 | E96: 1043.723 | F96: 0.000235 | G96: 6.8336303e+08 | H96: 1222.2685 | I96: 0.000132 | J96: 27362926 | K96: 1175.121 | L96: -1.3e-05 | M96: 18675023 | N96: 1013.1004 | O96: 4.4e-05 | P96: 6948855.9 | Q96: 1020.8422 | R96: 0.000388 | S96: 13219907 | T96: 1.4066612 | U96: 0.000103 | V96: 92030061 | W96: 1.5602859 | X96: 0.000146 | Y96: 45370290 | Z96: 1.3487359 | AA96: 0.000106 | AB96: 32210146 | AC96: 1.0541104 | AD96: 0.00012 | AE96: 13255646 | AF96: 1.5263683 | AG96: 0.000157 | AH96: 26895816 | AI96: 5963.7857 | AJ96: 0.00013 | AK96: 71851690
A97: 46214 | B97: 1.1777598 | C97: 0.000133 | D97: 2.28379e+08 | E97: 1043.4779 | F97: 0.000234 | G97: 6.8320257e+08 | H97: 1222.1069 | I97: 0.000132 | J97: 27359308 | K97: 1175.1363 | L97: -1.3e-05 | M97: 18675266 | N97: 1013.0558 | O97: 4.4e-05 | P97: 6948550 | Q97: 1020.4459 | R97: 0.000389 | S97: 13214775 | T97: 1.4065168 | U97: 0.000103 | V97: 92020616 | W97: 1.5600588 | X97: 0.000146 | Y97: 45385243 | Z97: 1.3485936 | AA97: 0.000106 | AB97: 32206748 | AC97: 1.053984 | AD97: 0.00012 | AE97: 13254057 | AF97: 1.5261289 | AG97: 0.000157 | AH97: 26891596 | AI97: 5963.0092 | AJ97: 0.00013 | AK97: 71842335
A98: 46213 | B98: 1.1776036 | C98: 0.000131 | D98: 2.2834655e+08 | E98: 1043.2339 | F98: 0.000235 | G98: 6.830428e+08 | H98: 1221.9453 | I98: 0.000132 | J98: 27355690 | K98: 1175.1516 | L98: -1.3e-05 | M98: 18675509 | N98: 1013.0112 | O98: 9e-06 | P98: 6948244.1 | Q98: 1020.0496 | R98: 0.000389 | S98: 13209643 | T98: 1.4063713 | U98: 0.000102 | V98: 92011097 | W98: 1.5598304 | X98: 0.000144 | Y98: 45471888 | Z98: 1.3484513 | AA98: 0.000107 | AB98: 32203350 | AC98: 1.0538576 | AD98: 0.00018 | AE98: 13252468 | AF98: 1.5258894 | AG98: 0.000157 | AH98: 26887377 | AI98: 5962.2325 | AJ98: 9.7e-05 | AK98: 71832977
A99: 46212 | B99: 1.1774498 | C99: 0.000133 | D99: 2.2504366e+08 | E99: 1042.9888 | F99: 0.000236 | G99: 6.8288233e+08 | H99: 1221.7837 | I99: 0.000132 | J99: 27352071 | K99: 1175.1669 | L99: -1.3e-05 | M99: 18675752 | N99: 1013.0025 | O99: 4.4e-05 | P99: 6948183.9 | Q99: 1019.6533 | R99: 0.000389 | S99: 13204511 | T99: 1.4062278 | U99: 0.000103 | V99: 92466526 | W99: 1.5596051 | X99: 0.000144 | Y99: 45425691 | Z99: 1.3483077 | AA99: 0.000106 | AB99: 30108943 | AC99: 1.0536681 | AD99: 0.000578 | AE99: 13206443 | AF99: 1.5256498 | AG99: 0.000157 | AH99: 26877879 | AI99: 5961.6519 | AJ99: 0.000122 | AK99: 71825982
A100: 46211 | B100: 1.177293 | C100: 0.000132 | D100: 2.2525806e+08 | E100: 1042.7431 | F100: 0.000235 | G100: 6.8272148e+08 | H100: 1221.6221 | I100: 0.000132 | J100: 27348453 | K100: 1175.1822 | L100: -1.3e-05 | M100: 18675996 | N100: 1012.9579 | O100: 4.4e-05 | P100: 6947878 | Q100: 1019.2571 | R100: 0.000389 | S100: 13199379 | T100: 1.4060836 | U100: 0.000107 | V100: 91382859 | W100: 1.5593802 | X100: 0.000152 | Y100: 45372043 | Z100: 1.348165 | AA100: 0.000106 | AB100: 29755814 | AC100: 1.0530596 | AD100: -0.001544 | AE100: 13140409 | AF100: 1.5254102 | AG100: 0.000134 | AH100: 26871658 | AI100: 5960.9262 | AJ100: 0.000291 | AK100: 71817238
A101: 46210 | B101: 1.1771378 | C101: 0.000124 | D101: 2.2623547e+08 | E101: 1042.4977 | F101: 0.000235 | G101: 6.825608e+08 | H101: 1221.4604 | I101: 0.000132 | J101: 27344835 | K101: 1175.1975 | L101: -1.3e-05 | M101: 18676239 | N101: 1012.9133 | O101: 4.4e-05 | P101: 6947572.1 | Q101: 1018.8608 | R101: 0.000389 | S101: 13194247 | T101: 1.4059335 | U101: 0.000107 | V101: 91657221 | W101: 1.5591433 | X101: 0.000155 | Y101: 45236933 | Z101: 1.3480224 | AA101: 0.000106 | AB101: 29752416 | AC101: 1.0546883 | AD101: -0.000579 | AE101: 5673620.6 | AF101: 1.5252053 | AG101: -0.001413 | AH101: 26667576 | AI101: 5959.1925 | AJ101: 0.000116 | AK101: 71796352
A102: 46209 | B102: 1.1769916 | C102: 0.000127 | D102: 2.2606804e+08 | E102: 1042.2524 | F102: 0.000234 | G102: 6.8240016e+08 | H102: 1221.2989 | I102: 0.000132 | J102: 27341218 | K102: 1175.2128 | L102: -1.3e-05 | M102: 18676482 | N102: 1012.8687 | O102: 4.4e-05 | P102: 6947266.2 | Q102: 1018.4645 | R102: 0.000389 | S102: 13189115 | T102: 1.405783 | U102: 0.000107 | V102: 91662690 | W102: 1.5589024 | X102: 0.000152 | Y102: 45149366 | Z102: 1.3478795 | AA102: 0.000106 | AB102: 29735340 | AC102: 1.0552995 | AD102: 0.001071 | AE102: 7754711.9 | AF102: 1.5273629 | AG102: 0.000159 | AH102: 26700550 | AI102: 5958.5023 | AJ102: 6.5e-05 | AK102: 71788036
A103: 46208 | B103: 1.1768418 | C103: 0.000132 | D103: 2.2946368e+08 | E103: 1042.0086 | F103: 0.000235 | G103: 6.8224057e+08 | H103: 1221.1373 | I103: 0.000132 | J103: 27337602 | K103: 1175.2281 | L103: -1.3e-05 | M103: 18676725 | N103: 1012.8241 | O103: 4.4e-05 | P103: 6946960.2 | Q103: 1018.0682 | R103: 0.000389 | S103: 13183983 | T103: 1.4056325 | U103: 0.000107 | V103: 91468490 | W103: 1.5586652 | X103: 0.000152 | Y103: 45106042 | Z103: 1.3477367 | AA103: 0.000106 | AB103: 29688768 | AC103: 1.0541708 | AD103: 0.000157 | AE103: 7727566.6 | AF103: 1.5271207 | AG103: 0.000159 | AH103: 26695317 | AI103: 5958.1169 | AJ103: 0.000128 | AK103: 71783393
A104: 46207 | B104: 1.1766865 | C104: 0.000132 | D104: 2.2943526e+08 | E104: 1041.7634 | F104: 0.000235 | G104: 6.8207998e+08 | H104: 1220.9758 | I104: 0.000132 | J104: 27333985 | K104: 1175.2434 | L104: -1.3e-05 | M104: 18676968 | N104: 1012.7794 | O104: 4.4e-05 | P104: 6946654.2 | Q104: 1017.6719 | R104: 0.00039 | S104: 13178851 | T104: 1.4054819 | U104: 0.000107 | V104: 91458687 | W104: 1.5584281 | X104: 0.000152 | Y104: 45126349 | Z104: 1.3475938 | AA104: 0.000106 | AB104: 29689421 | AC104: 1.0540055 | AD104: 0.000156 | AE104: 7726705.1 | AF104: 1.5268786 | AG104: 0.000159 | AH104: 26691085 | AI104: 5957.3531 | AJ104: 9.5e-05 | AK104: 71774190
A105: 46206 | B105: 1.1765306 | C105: 0.000136 | D105: 2.2940016e+08 | E105: 1041.5188 | F105: 0.000236 | G105: 6.8191983e+08 | H105: 1220.8142 | I105: 0.000132 | J105: 27330368 | K105: 1175.2587 | L105: -1.3e-05 | M105: 18677211 | N105: 1012.7348 | O105: -0.000668 | P105: 6946348.2 | Q105: 1017.2756 | R105: 0.00039 | S105: 13173719 | T105: 1.4053312 | U105: 0.000106 | V105: 91448885 | W105: 1.5581915 | X105: 0.000152 | Y105: 45182086 | Z105: 1.3474509 | AA105: 0.000107 | AB105: 29686273 | AC105: 1.0538407 | AD105: 0.000158 | AE105: 7725497 | AF105: 1.5266365 | AG105: 0.000159 | AH105: 26686852 | AI105: 5956.7895 | AJ105: 1.5e-05 | AK105: 71767400
... A154: 46157 | B154: 1.1691829 | C154: 0.000131 | D154: 1.9086775e+08 | E154: 1037.1383 | F154: 0.000235 | G154: 6.7905178e+08 | H154: 1212.2054 | I154: 0.000139 | J154: 27137642 | K154: 1185.1899 | L154: -0.000136 | M154: 18835038 | N154: 1008.0383 | O154: 0.000171 | P154: 4898058 | Q154: 1000 | R154: 0 | S154: 12950000 | T154: 1.3978803 | U154: 0.000106 | V154: 98219846 | W154: 1.5466758 | X154: 0.000152 | Y154: 43608216 | Z154: 1.3404804 | AA154: 0.000108 | AB154: 31402899 | AC154: 1.0419826 | AD154: -0.001305 | AE154: 6240302.9 | AF154: 1.514707 | AG154: 0.000165 | AH154: 25817381 | AI154: 5973.7986 | AJ154: 0.000163 | AK154: 71972325
A155: 46156 | B155: 1.1690301 | C155: 0.000132 | D155: 1.8833728e+08 | E155: 1036.8949 | F155: 0.000235 | G155: 6.7889239e+08 | H155: 1212.0367 | I155: 0.000139 | J155: 27133865 | K155: 1185.3517 | L155: -0.000136 | M155: 18837608 | N155: 1007.8658 | O155: 0.000171 | P155: 4897219.8 | T155: 1.3977325 | U155: 0.000109 | V155: 98753906 | W155: 1.5464413 | X155: 0.000152 | Y155: 43107707 | Z155: 1.340335 | AA155: 0.000113 | AB155: 31394662 | AC155: 1.043344 | AD155: 0.000293 | AE155: 6243016.5 | AF155: 1.5144571 | AG155: 0.000171 | AH155: 25811746 | AI155: 5972.8256 | AJ155: 0.00015 | AK155: 71960603
A156: 46155 | B156: 1.1688755 | C156: 0.000105 | D156: 1.8710223e+08 | E156: 1036.6518 | F156: -0.018602 | G156: 6.7873323e+08 | H156: 1211.868 | I156: 0.000139 | J156: 27130088 | K156: 1185.5134 | L156: -0.000126 | M156: 18840178 | N156: 1007.6933 | O156: 0.000171 | P156: 4896381.6 | T156: 1.3975808 | U156: 0.00011 | V156: 90510803 | W156: 1.5462058 | X156: 0.000152 | Y156: 42800183 | Z156: 1.3401833 | AA156: 0.000128 | AB156: 23397714 | AC156: 1.0430384 | AD156: 0.001097 | AE156: 6237808.9 | AF156: 1.5141983 | AG156: 0.000165 | AH156: 25803196 | AI156: 5971.9324 | AJ156: 0.000111 | AK156: 71949842
A157: 46154 | B157: 1.1687526 | C157: 0.000123 | D157: 1.9749236e+08 | E157: 1056.3013 | F157: 0.000231 | G157: 6.9159847e+08 | H157: 1211.6992 | I157: 0.000138 | J157: 27126311 | K157: 1185.6628 | L157: -0.000126 | M157: 18842553 | N157: 1007.5207 | O157: 0.000171 | P157: 4895543.3 | T157: 1.3974272 | U157: 0.00011 | V157: 87384300 | W157: 1.5459702 | X157: 0.000154 | Y157: 42781924 | Z157: 1.3400123 | AA157: 0.000111 | AB157: 23336841 | AC157: 1.0418954 | AD157: -0.001087 | AE157: 6230174.5 | AF157: 1.5139483 | AG157: 0.000178 | AH157: 25797363 | AI157: 5971.268 | AJ157: 0.000156 | AK157: 71941837
A158: 46153 | B158: 1.1686087 | C158: 0.000133 | D158: 1.9624785e+08 | E158: 1056.0578 | F158: 0.000233 | G158: 6.9143904e+08 | H158: 1211.5325 | I158: 0.000138 | J158: 27122578 | K158: 1185.8122 | L158: -0.000126 | M158: 18844927 | N158: 1007.3482 | O158: 0.000171 | P158: 4894705 | T158: 1.3972737 | U158: 0.00011 | V158: 87376640 | W158: 1.5457326 | X158: 0.000153 | Y158: 42679122 | Z158: 1.3398634 | AA158: 0.000112 | AB158: 26342650 | AC158: 1.0430297 | AD158: 0.000365 | AE158: 6225589.7 | AF158: 1.5136793 | AG158: 0.000151 | AH158: 25792280 | AI158: 5970.3369 | AJ158: 0.000162 | AK158: 71930619
A159: 46152 | B159: 1.1684538 | C159: 0.00013 | D159: 1.9371083e+08 | E159: 1055.8121 | F159: 0.000232 | G159: 6.9127817e+08 | H159: 1211.3657 | I159: 0.000138 | J159: 27118844 | K159: 1185.9616 | L159: -0.000126 | M159: 18847302 | N159: 1007.1757 | O159: 0.000171 | P159: 4893866.6 | T159: 1.3971196 | U159: 0.00011 | V159: 86860203 | W159: 1.5454963 | X159: 0.000153 | Y159: 42719946 | Z159: 1.3397128 | AA159: 0.000111 | AB159: 26337164 | AC159: 1.0426492 | AD159: 0.000176 | AE159: 6206124.8 | AF159: 1.5134505 | AG159: 0.000165 | AH159: 25766384 | AI159: 5969.3689 | AJ159: 0.000162 | AK159: 71918957
A160: 46151 | B160: 1.1683014 | C160: 0.00013 | D160: 1.9365605e+08 | E160: 1055.5669 | F160: 0.000232 | G160: 6.9111763e+08 | H160: 1211.1989 | I160: 0.000138 | J160: 27115110 | K160: 1186.111 | L160: -0.000126 | M160: 18849676 | N160: 1007.0031 | O160: 0.000171 | P160: 4893028.2 | T160: 1.3969657 | U160: 0.00011 | V160: 86850629 | W160: 1.5452602 | X160: 0.000152 | Y160: 42744716 | Z160: 1.3395641 | AA160: 0.000111 | AB160: 26638476 | AC160: 1.0424654 | AD160: 0.000176 | AE160: 6208530.1 | AF160: 1.5132011 | AG160: 0.000165 | AH160: 25762138 | AI160: 5968.4009 | AJ160: 0.000162 | AK160: 71907294
A161: 46150 | B161: 1.1681491 | C161: 0.000128 | D161: 1.9361984e+08 | E161: 1055.3217 | F161: 0.000234 | G161: 6.9095708e+08 | H161: 1211.0321 | I161: 0.000138 | J161: 27111375 | K161: 1186.2604 | L161: -0.000126 | M161: 18852051 | N161: 1006.8306 | O161: 0.000171 | P161: 4892189.7 | T161: 1.3968115 | U161: 0.000133 | V161: 86841046 | W161: 1.5450247 | X161: 0.000156 | Y161: 42816364 | Z161: 1.3394155 | AA161: 0.000113 | AB161: 26635520 | AC161: 1.0422815 | AD161: 0.00037 | AE161: 6207435.2 | AF161: 1.5129513 | AG161: 0.000165 | AH161: 25757886 | AI161: 5967.4329 | AJ161: 4.7e-05 | AK161: 71895631
A162: 46149 | B162: 1.1679995 | C162: 0.000126 | D162: 1.9180323e+08 | E162: 1055.0748 | F162: 0.000233 | G162: 6.9079543e+08 | H162: 1210.8653 | I162: 0.000138 | J162: 27107641 | K162: 1186.4099 | L162: -0.000126 | M162: 18854426 | N162: 1006.658 | O162: 0.000121 | P162: 4891351.2 | T162: 1.3966256 | U162: 0.00011 | V162: 87015034 | W162: 1.5447844 | X162: 0.000162 | Y162: 42762629 | Z162: 1.3392638 | AA162: 0.000112 | AB162: 26631141 | AC162: 1.0418962 | AD162: 3.1e-05 | AE162: 6192431.3 | AF162: 1.5127019 | AG162: 0.000165 | AH162: 25752495 | AI162: 5967.1544 | AJ162: 0.000149 | AK162: 71892277
A163: 46148 | B163: 1.1678522 | C163: 0.000132 | D163: 1.8922016e+08 | E163: 1054.829 | F163: 0.000234 | G163: 6.9063452e+08 | H163: 1210.6985 | I163: 0.000138 | J163: 27103907 | K163: 1186.5593 | L163: -0.000126 | M163: 18856800 | N163: 1006.536 | O163: 0.000171 | P163: 4890758.4 | T163: 1.3964717 | U163: 0.000109 | V163: 87182098 | W163: 1.5445345 | X163: 0.000153 | Y163: 42805546 | Z163: 1.3391139 | AA163: 0.000112 | AB163: 26902838 | AC163: 1.0418641 | AD163: 0.001836 | AE163: 6184990.8 | AF163: 1.5124525 | AG163: 0.000165 | AH163: 25747650 | AI163: 5966.2641 | AJ163: 0.000146 | AK163: 71881550
...

Sheet Valor cuota (fin de mes)
A1: Valor cuota (fin de mes)
A2: Fondos de Inversión El Salvador — Todas las gestoras | Fuente: sitios oficiales de cada gestora | datos al 2026-10-11 (actualización 2026-10-11)
A3: Fondo | B3: oct-2016 | C3: nov-2016 | D3: dic-2016 | E3: ene-2017 | F3: feb-2017 | G3: mar-2017 | H3: abr-2017 | I3: may-2017 | J3: jun-2017 | K3: jul-2017 | L3: ago-2017 | M3: sep-2017 | N3: oct-2017 | O3: nov-2017 | P3: dic-2017 | Q3: ene-2018 | R3: feb-2018 | S3: mar-2018 | T3: abr-2018 | U3: may-2018 | V3: jun-2018 | W3: jul-2018 | X3: ago-2018 | Y3: sep-2018 | Z3: oct-2018 | AA3: nov-2018 | AB3: dic-2018 | AC3: ene-2019 | AD3: feb-2019 | AE3: mar-2019 | AF3: abr-2019 | AG3: may-2019 | AH3: jun-2019 | AI3: jul-2019 | AJ3: ago-2019 | AK3: sep-2019 | AL3: oct-2019 | AM3: nov-2019 | AN3: dic-2019 | AO3: ene-2020 | AP3: feb-2020 | AQ3: mar-2020 | AR3: abr-2020 | AS3: may-2020 | AT3: jun-2020 | AU3: jul-2020 | AV3: ago-2020 | AW3: sep-2020 | AX3: oct-2020 | AY3: nov-2020 | AZ3: dic-2020 | BA3: ene-2021 | BB3: feb-2021 | BC3: mar-2021 | BD3: abr-2021 | BE3: may-2021 | BF3: jun-2021 | BG3: jul-2021 | BH3: ago-2021 | BI3: sep-2021 | BJ3: oct-2021 | BK3: nov-2021 | BL3: dic-2021 | BM3: ene-2022 | BN3: feb-2022 | BO3: mar-2022 | BP3: abr-2022 | BQ3: may-2022 | BR3: jun-2022 | BS3: jul-2022 | BT3: ago-2022 | BU3: sep-2022 | BV3: oct-2022 | BW3: nov-2022 | BX3: dic-2022 | BY3: ene-2023 | BZ3: feb-2023 | CA3: mar-2023 | CB3: abr-2023 | CC3: may-2023 | CD3: jun-2023 | CE3: jul-2023 | CF3: ago-2023 | CG3: sep-2023 | CH3: oct-2023 | CI3: nov-2023 | CJ3: dic-2023 | CK3: ene-2024 | CL3: feb-2024 | CM3: mar-2024 | CN3: abr-2024 | CO3: may-2024 | CP3: jun-2024 | CQ3: jul-2024 | CR3: ago-2024 | CS3: sep-2024 | CT3: oct-2024 | CU3: nov-2024 | CV3: dic-2024 | CW3: ene-2025 | CX3: feb-2025 | CY3: mar-2025 | CZ3: abr-2025 | DA3: may-2025 | DB3: jun-2025 | DC3: jul-2025 | DD3: ago-2025 | DE3: sep-2025 | DF3: oct-2025 | DG3: nov-2025 | DH3: dic-2025 | DI3: ene-2026 | DJ3: feb-2026 | DK3: mar-2026 | DL3: abr-2026 | DM3: may-2026 | DN3: jun-2026 | DO3: jul-2026 | DP3: ago-2026 | DQ3: sep-2026 | DR3: oct-2026*
A4: Hencorp · FI Abierto Hencorp Opportunity | CC4: 1.0042318 | CD4: 1.0085181 | CE4: 1.0128668 | CF4: 1.0173763 | CG4: 1.0218089 | CH4: 1.0263879 | CI4: 1.0306844 | CJ4: 1.0359479 | CK4: 1.0406063 | CL4: 1.0448963 | CM4: 1.0494155 | CN4: 1.0539331 | CO4: 1.0592179 | CP4: 1.0640595 | CQ4: 1.0688075 | CR4: 1.0735092 | CS4: 1.0780725 | CT4: 1.0831082 | CU4: 1.0876538 | CV4: 1.0924678 | CW4: 1.0972577 | CX4: 1.1015601 | CY4: 1.1064724 | CZ4: 1.1113874 | DA4: 1.1162905 | DB4: 1.1209893 | DC4: 1.1259162 | DD4: 1.1307494 | DE4: 1.1354138 | DF4: 1.1399574 | DG4: 1.1441651 | DH4: 1.1488066 | DI4: 1.1533475 | DJ4: 1.1576537 | DK4: 1.1623831 | DL4: 1.1669559 | DM4: 1.1715671 | DN4: 1.1760487 | DO4: 1.1807452 | DP4: 1.18553 | DQ4: 1.19002 | DR4: 1.1915885
A5: Hencorp · FIC Renta Fija I | CH5: 1004.0914 | CI5: 1011.0099 | CJ5: 1017.9666 | CK5: 1025.1435 | CL5: 1032.2025 | CM5: 1039.5472 | CN5: 1046.9496 | CO5: 1038.798 | CP5: 1038.7396 | CQ5: 1046.1199 | CR5: 1048.7838 | CS5: 1048.8806 | CT5: 1056.2348 | CU5: 1039.2837 | CV5: 1039.3914 | CW5: 1046.7844 | CX5: 1048.5916 | CY5: 1048.6276 | CZ5: 1052.6819 | DA5: 1039.6517 | DB5: 1039.6638 | DC5: 1047.0897 | DD5: 1049.3232 | DE5: 1049.3728 | DF5: 1053.041 | DG5: 1040.2677 | DH5: 1040.2445 | DI5: 1047.591 | DJ5: 1049.709 | DK5: 1049.7459 | DL5: 1053.3552 | DM5: 1040.7866 | DN5: 1040.7832 | DO5: 1048.1392 | DP5: 1049.9987 | DQ5: 1050.184 | DR5: 1052.6451
A6: Hencorp · FIC Inmobiliario Hencorp Growth | CM6: 1001.831 | CN6: 1007.3205 | CO6: 1012.6369 | CP6: 1018.1412 | CQ6: 1023.6918 | CR6: 1006.1542 | CS6: 1011.7666 | CT6: 1017.3695 | CU6: 1023.0159 | CV6: 1028.5985 | CW6: 1034.1805 | CX6: 1039.5841 | CY6: 1184.043 | CZ6: 1188.8576 | DA6: 1194.2859 | DB6: 1199.7938 | DC6: 1204.5773 | DD6: 1210.2279 | DE6: 1215.8874 | DF6: 1221.4967 | DG6: 1236.1463 | DH6: 1173.4788 | DI6: 1179.4258 | DJ6: 1185.1761 | DK6: 1198.3295 | DL6: 1209.6864 | DM6: 1214.9764 | DN6: 1220.3307 | DO6: 1225.8443 | DP6: 1239.0646 | DQ6: 1244.4226 | DR6: 1245.9946
A7: Hencorp · FIC Desarrollo Inmob. Hencorp Vivienda 01 | DB7: 996.69381 | DC7: 993.41423 | DD7: 991.64457 | DE7: 991.08259 | DF7: 984.15311 | DG7: 977.39018 | DH7: 971.77694 | DI7: 956.22123 | DJ7: 1105.7385 | DK7: 1101.9769 | DL7: 1187.4564 | DM7: 1182.5741 | DN7: 1176.4937 | DO7: 1174.8788 | DP7: 1174.2168 | DQ7: 1172.6999 | DR7: 1171.9346
A8: Hencorp · FIC Inmobiliario Hencorp Blue Whale | DE8: 1000.023 | DF8: 1000.555 | DG8: 1007.7225 | DH8: 1013.0095 | DI8: 1013.1757 | DJ8: 1018.6383 | DK8: 1023.8524 | DL8: 1005.5003 | DM8: 1010.8201 | DN8: 1013.2382 | DO8: 1004.4542 | DP8: 1003.3424 | DQ8: 1011.7935 | DR8: 1012.9144
A9: Hencorp · FIC Inmobiliario Hencorp Commercial Properties | DM9: 1003.878 | DN9: 1016.0867 | DO9: 1028.3717 | DP9: 1040.2363 | DQ9: 1050.2271 | DR9: 1053.7491
