Workbook

Sheet Resumen
A1: Resumen — Fondos de Inversión Hencorp
A2: Grupo Hencorp — Gestora de Fondos | Fuente: hencorpgestora.com (Comportamiento Histórico) | datos al 2026-10-12 (actualización 2026-10-13)
A3: Fondo | B3: Tipo | C3: Inicio | D3: VC inicial (base) | E3: VC actual | F3: Fecha dato | G3: Patrimonio actual (US$) | H3: Meses | I3: Rend. acum. desde inicio | J3: Rend. anualizado (CAGR)
A4: FI Abierto Hencorp Opportunity | B4: Abierto | C4: 45048 | D4: 1 | E4: ='Valor cuota (fin de mes)'!AQ4 | F4: 46307 | G4: ='Patrimonio (fin de mes)'!AQ4 | H4: 42 | I4: =E4/D4-1 | J4: =IFERROR((E4/D4)^(365/(F4-C4))-1,"")
A5: FIC Renta Fija I | B5: Cerrado | C5: 45212 | D5: 1000 | E5: ='Valor cuota (fin de mes)'!AQ5 | F5: 46307 | G5: ='Patrimonio (fin de mes)'!AQ5 | H5: 37 | I5: =E5/D5-1 | J5: =IFERROR((E5/D5)^(365/(F5-C5))-1,"")
A6: FIC Inmobiliario Hencorp Growth | B6: Cerrado | C6: 45372 | D6: 1000 | E6: ='Valor cuota (fin de mes)'!AQ6 | F6: 46307 | G6: ='Patrimonio (fin de mes)'!AQ6 | H6: 32 | I6: =E6/D6-1 | J6: =IFERROR((E6/D6)^(365/(F6-C6))-1,"")
A7: FIC Desarrollo Inmob. Hencorp Vivienda 01 | B7: Cerrado | C7: 45819 | D7: 1000 | E7: ='Valor cuota (fin de mes)'!AQ7 | F7: 46307 | G7: ='Patrimonio (fin de mes)'!AQ7 | H7: 17 | I7: =E7/D7-1 | J7: =IFERROR((E7/D7)^(365/(F7-C7))-1,"")
A8: FIC Inmobiliario Hencorp Blue Whale | B8: Cerrado | C8: 45919 | D8: 1000 | E8: ='Valor cuota (fin de mes)'!AQ8 | F8: 46307 | G8: ='Patrimonio (fin de mes)'!AQ8 | H8: 14 | I8: =E8/D8-1 | J8: =IFERROR((E8/D8)^(365/(F8-C8))-1,"")
A9: FIC Inmobiliario Hencorp Commercial Properties | B9: Cerrado | C9: 46157 | D9: 1000 | E9: ='Valor cuota (fin de mes)'!AQ9 | F9: 46307 | G9: ='Patrimonio (fin de mes)'!AQ9 | H9: 6 | I9: =E9/D9-1 | J9: =IFERROR((E9/D9)^(365/(F9-C9))-1,"")

Sheet Gráficas
A1: Gráficas por fondo — patrimonio y rendimiento
A2: Grupo Hencorp — Gestora de Fondos | Fuente: hencorpgestora.com (Comportamiento Histórico) | datos al 2026-10-12 (actualización 2026-10-13) | una gráfica por fondo · cada una con su propio eje · se actualizan solas al crecer meses/días
A3: FI Abierto Hencorp Opportunity
A20: FIC Renta Fija I
A37: FIC Inmobiliario Hencorp Growth
A54: FIC Desarrollo Inmob. Hencorp Vivienda 01
A71: FIC Inmobiliario Hencorp Blue Whale
A88: FIC Inmobiliario Hencorp Commercial Properties

Sheet Rendimiento mensual
A1: Rendimiento mensual
A2: Grupo Hencorp — Gestora de Fondos | Fuente: hencorpgestora.com (Comportamiento Histórico) | datos al 2026-10-12 (actualización 2026-10-13)
A3: Fondo | B3: may-2023 | C3: jun-2023 | D3: jul-2023 | E3: ago-2023 | F3: sep-2023 | G3: oct-2023 | H3: nov-2023 | I3: dic-2023 | J3: ene-2024 | K3: feb-2024 | L3: mar-2024 | M3: abr-2024 | N3: may-2024 | O3: jun-2024 | P3: jul-2024 | Q3: ago-2024 | R3: sep-2024 | S3: oct-2024 | T3: nov-2024 | U3: dic-2024 | V3: ene-2025 | W3: feb-2025 | X3: mar-2025 | Y3: abr-2025 | Z3: may-2025 | AA3: jun-2025 | AB3: jul-2025 | AC3: ago-2025 | AD3: sep-2025 | AE3: oct-2025 | AF3: nov-2025 | AG3: dic-2025 | AH3: ene-2026 | AI3: feb-2026 | AJ3: mar-2026 | AK3: abr-2026 | AL3: may-2026 | AM3: jun-2026 | AN3: jul-2026 | AO3: ago-2026 | AP3: sep-2026 | AQ3: oct-2026*
A4: FI Abierto Hencorp Opportunity | B4: =IF('Valor cuota (fin de mes)'!B4="","",'Valor cuota (fin de mes)'!B4/'Resumen'!$D$4-1) | C4: =IFERROR(IF(OR('Valor cuota (fin de mes)'!C4="",'Valor cuota (fin de mes)'!B4=""),"",'Valor cuota (fin de mes)'!C4/'Valor cuota (fin de mes)'!B4-1),"") | D4: =IFERROR(IF(OR('Valor cuota (fin de mes)'!D4="",'Valor cuota (fin de mes)'!C4=""),"",'Valor cuota (fin de mes)'!D4/'Valor cuota (fin de mes)'!C4-1),"") | E4: =IFERROR(IF(OR('Valor cuota (fin de mes)'!E4="",'Valor cuota (fin de mes)'!D4=""),"",'Valor cuota (fin de mes)'!E4/'Valor cuota (fin de mes)'!D4-1),"") | F4: =IFERROR(IF(OR('Valor cuota (fin de mes)'!F4="",'Valor cuota (fin de mes)'!E4=""),"",'Valor cuota (fin de mes)'!F4/'Valor cuota (fin de mes)'!E4-1),"") | G4: =IFERROR(IF(OR('Valor cuota (fin de mes)'!G4="",'Valor cuota (fin de mes)'!F4=""),"",'Valor cuota (fin de mes)'!G4/'Valor cuota (fin de mes)'!F4-1),"") | H4: =IFERROR(IF(OR('Valor cuota (fin de mes)'!H4="",'Valor cuota (fin de mes)'!G4=""),"",'Valor cuota (fin de mes)'!H4/'Valor cuota (fin de mes)'!G4-1),"") | I4: =IFERROR(IF(OR('Valor cuota (fin de mes)'!I4="",'Valor cuota (fin de mes)'!H4=""),"",'Valor cuota (fin de mes)'!I4/'Valor cuota (fin de mes)'!H4-1),"") | J4: =IFERROR(IF(OR('Valor cuota (fin de mes)'!J4="",'Valor cuota (fin de mes)'!I4=""),"",'Valor cuota (fin de mes)'!J4/'Valor cuota (fin de mes)'!I4-1),"") | ... AQ4: =IFERROR(IF(OR('Valor cuota (fin de mes)'!AQ4="",'Valor cuota (fin de mes)'!AP4=""),"",'Valor cuota (fin de mes)'!AQ4/'Valor cuota (fin de mes)'!AP4-1),"")
A5: FIC Renta Fija I | G5: =IF('Valor cuota (fin de mes)'!G5="","",'Valor cuota (fin de mes)'!G5/'Resumen'!$D$5-1) | H5: =IFERROR(IF(OR('Valor cuota (fin de mes)'!H5="",'Valor cuota (fin de mes)'!G5=""),"",'Valor cuota (fin de mes)'!H5/'Valor cuota (fin de mes)'!G5-1),"") | I5: =IFERROR(IF(OR('Valor cuota (fin de mes)'!I5="",'Valor cuota (fin de mes)'!H5=""),"",'Valor cuota (fin de mes)'!I5/'Valor cuota (fin de mes)'!H5-1),"") | J5: =IFERROR(IF(OR('Valor cuota (fin de mes)'!J5="",'Valor cuota (fin de mes)'!I5=""),"",'Valor cuota (fin de mes)'!J5/'Valor cuota (fin de mes)'!I5-1),"") | K5: =IFERROR(IF(OR('Valor cuota (fin de mes)'!K5="",'Valor cuota (fin de mes)'!J5=""),"",'Valor cuota (fin de mes)'!K5/'Valor cuota (fin de mes)'!J5-1),"") | L5: =IFERROR(IF(OR('Valor cuota (fin de mes)'!L5="",'Valor cuota (fin de mes)'!K5=""),"",'Valor cuota (fin de mes)'!L5/'Valor cuota (fin de mes)'!K5-1),"") | M5: =IFERROR(IF(OR('Valor cuota (fin de mes)'!M5="",'Valor cuota (fin de mes)'!L5=""),"",'Valor cuota (fin de mes)'!M5/'Valor cuota (fin de mes)'!L5-1),"") | N5: =IFERROR(IF(OR('Valor cuota (fin de mes)'!N5="",'Valor cuota (fin de mes)'!M5=""),"",'Valor cuota (fin de mes)'!N5/'Valor cuota (fin de mes)'!M5-1),"") | O5: =IFERROR(IF(OR('Valor cuota (fin de mes)'!O5="",'Valor cuota (fin de mes)'!N5=""),"",'Valor cuota (fin de mes)'!O5/'Valor cuota (fin de mes)'!N5-1),"") | ... AQ5: =IFERROR(IF(OR('Valor cuota (fin de mes)'!AQ5="",'Valor cuota (fin de mes)'!AP5=""),"",'Valor cuota (fin de mes)'!AQ5/'Valor cuota (fin de mes)'!AP5-1),"")
A6: FIC Inmobiliario Hencorp Growth | L6: =IF('Valor cuota (fin de mes)'!L6="","",'Valor cuota (fin de mes)'!L6/'Resumen'!$D$6-1) | M6: =IFERROR(IF(OR('Valor cuota (fin de mes)'!M6="",'Valor cuota (fin de mes)'!L6=""),"",'Valor cuota (fin de mes)'!M6/'Valor cuota (fin de mes)'!L6-1),"") | N6: =IFERROR(IF(OR('Valor cuota (fin de mes)'!N6="",'Valor cuota (fin de mes)'!M6=""),"",'Valor cuota (fin de mes)'!N6/'Valor cuota (fin de mes)'!M6-1),"") | O6: =IFERROR(IF(OR('Valor cuota (fin de mes)'!O6="",'Valor cuota (fin de mes)'!N6=""),"",'Valor cuota (fin de mes)'!O6/'Valor cuota (fin de mes)'!N6-1),"") | P6: =IFERROR(IF(OR('Valor cuota (fin de mes)'!P6="",'Valor cuota (fin de mes)'!O6=""),"",'Valor cuota (fin de mes)'!P6/'Valor cuota (fin de mes)'!O6-1),"") | Q6: =IFERROR(IF(OR('Valor cuota (fin de mes)'!Q6="",'Valor cuota (fin de mes)'!P6=""),"",'Valor cuota (fin de mes)'!Q6/'Valor cuota (fin de mes)'!P6-1),"") | R6: =IFERROR(IF(OR('Valor cuota (fin de mes)'!R6="",'Valor cuota (fin de mes)'!Q6=""),"",'Valor cuota (fin de mes)'!R6/'Valor cuota (fin de mes)'!Q6-1),"") | S6: =IFERROR(IF(OR('Valor cuota (fin de mes)'!S6="",'Valor cuota (fin de mes)'!R6=""),"",'Valor cuota (fin de mes)'!S6/'Valor cuota (fin de mes)'!R6-1),"") | T6: =IFERROR(IF(OR('Valor cuota (fin de mes)'!T6="",'Valor cuota (fin de mes)'!S6=""),"",'Valor cuota (fin de mes)'!T6/'Valor cuota (fin de mes)'!S6-1),"") | ... AQ6: =IFERROR(IF(OR('Valor cuota (fin de mes)'!AQ6="",'Valor cuota (fin de mes)'!AP6=""),"",'Valor cuota (fin de mes)'!AQ6/'Valor cuota (fin de mes)'!AP6-1),"")
A7: FIC Desarrollo Inmob. Hencorp Vivienda 01 | AA7: =IF('Valor cuota (fin de mes)'!AA7="","",'Valor cuota (fin de mes)'!AA7/'Resumen'!$D$7-1) | AB7: =IFERROR(IF(OR('Valor cuota (fin de mes)'!AB7="",'Valor cuota (fin de mes)'!AA7=""),"",'Valor cuota (fin de mes)'!AB7/'Valor cuota (fin de mes)'!AA7-1),"") | AC7: =IFERROR(IF(OR('Valor cuota (fin de mes)'!AC7="",'Valor cuota (fin de mes)'!AB7=""),"",'Valor cuota (fin de mes)'!AC7/'Valor cuota (fin de mes)'!AB7-1),"") | AD7: =IFERROR(IF(OR('Valor cuota (fin de mes)'!AD7="",'Valor cuota (fin de mes)'!AC7=""),"",'Valor cuota (fin de mes)'!AD7/'Valor cuota (fin de mes)'!AC7-1),"") | AE7: =IFERROR(IF(OR('Valor cuota (fin de mes)'!AE7="",'Valor cuota (fin de mes)'!AD7=""),"",'Valor cuota (fin de mes)'!AE7/'Valor cuota (fin de mes)'!AD7-1),"") | AF7: =IFERROR(IF(OR('Valor cuota (fin de mes)'!AF7="",'Valor cuota (fin de mes)'!AE7=""),"",'Valor cuota (fin de mes)'!AF7/'Valor cuota (fin de mes)'!AE7-1),"") | AG7: =IFERROR(IF(OR('Valor cuota (fin de mes)'!AG7="",'Valor cuota (fin de mes)'!AF7=""),"",'Valor cuota (fin de mes)'!AG7/'Valor cuota (fin de mes)'!AF7-1),"") | AH7: =IFERROR(IF(OR('Valor cuota (fin de mes)'!AH7="",'Valor cuota (fin de mes)'!AG7=""),"",'Valor cuota (fin de mes)'!AH7/'Valor cuota (fin de mes)'!AG7-1),"") | AI7: =IFERROR(IF(OR('Valor cuota (fin de mes)'!AI7="",'Valor cuota (fin de mes)'!AH7=""),"",'Valor cuota (fin de mes)'!AI7/'Valor cuota (fin de mes)'!AH7-1),"") | ... AQ7: =IFERROR(IF(OR('Valor cuota (fin de mes)'!AQ7="",'Valor cuota (fin de mes)'!AP7=""),"",'Valor cuota (fin de mes)'!AQ7/'Valor cuota (fin de mes)'!AP7-1),"")
A8: FIC Inmobiliario Hencorp Blue Whale | AD8: =IF('Valor cuota (fin de mes)'!AD8="","",'Valor cuota (fin de mes)'!AD8/'Resumen'!$D$8-1) | AE8: =IFERROR(IF(OR('Valor cuota (fin de mes)'!AE8="",'Valor cuota (fin de mes)'!AD8=""),"",'Valor cuota (fin de mes)'!AE8/'Valor cuota (fin de mes)'!AD8-1),"") | AF8: =IFERROR(IF(OR('Valor cuota (fin de mes)'!AF8="",'Valor cuota (fin de mes)'!AE8=""),"",'Valor cuota (fin de mes)'!AF8/'Valor cuota (fin de mes)'!AE8-1),"") | AG8: =IFERROR(IF(OR('Valor cuota (fin de mes)'!AG8="",'Valor cuota (fin de mes)'!AF8=""),"",'Valor cuota (fin de mes)'!AG8/'Valor cuota (fin de mes)'!AF8-1),"") | AH8: =IFERROR(IF(OR('Valor cuota (fin de mes)'!AH8="",'Valor cuota (fin de mes)'!AG8=""),"",'Valor cuota (fin de mes)'!AH8/'Valor cuota (fin de mes)'!AG8-1),"") | AI8: =IFERROR(IF(OR('Valor cuota (fin de mes)'!AI8="",'Valor cuota (fin de mes)'!AH8=""),"",'Valor cuota (fin de mes)'!AI8/'Valor cuota (fin de mes)'!AH8-1),"") | AJ8: =IFERROR(IF(OR('Valor cuota (fin de mes)'!AJ8="",'Valor cuota (fin de mes)'!AI8=""),"",'Valor cuota (fin de mes)'!AJ8/'Valor cuota (fin de mes)'!AI8-1),"") | AK8: =IFERROR(IF(OR('Valor cuota (fin de mes)'!AK8="",'Valor cuota (fin de mes)'!AJ8=""),"",'Valor cuota (fin de mes)'!AK8/'Valor cuota (fin de mes)'!AJ8-1),"") | AL8: =IFERROR(IF(OR('Valor cuota (fin de mes)'!AL8="",'Valor cuota (fin de mes)'!AK8=""),"",'Valor cuota (fin de mes)'!AL8/'Valor cuota (fin de mes)'!AK8-1),"") | ... AQ8: =IFERROR(IF(OR('Valor cuota (fin de mes)'!AQ8="",'Valor cuota (fin de mes)'!AP8=""),"",'Valor cuota (fin de mes)'!AQ8/'Valor cuota (fin de mes)'!AP8-1),"")
A9: FIC Inmobiliario Hencorp Commercial Properties | AL9: =IF('Valor cuota (fin de mes)'!AL9="","",'Valor cuota (fin de mes)'!AL9/'Resumen'!$D$9-1) | AM9: =IFERROR(IF(OR('Valor cuota (fin de mes)'!AM9="",'Valor cuota (fin de mes)'!AL9=""),"",'Valor cuota (fin de mes)'!AM9/'Valor cuota (fin de mes)'!AL9-1),"") | AN9: =IFERROR(IF(OR('Valor cuota (fin de mes)'!AN9="",'Valor cuota (fin de mes)'!AM9=""),"",'Valor cuota (fin de mes)'!AN9/'Valor cuota (fin de mes)'!AM9-1),"") | AO9: =IFERROR(IF(OR('Valor cuota (fin de mes)'!AO9="",'Valor cuota (fin de mes)'!AN9=""),"",'Valor cuota (fin de mes)'!AO9/'Valor cuota (fin de mes)'!AN9-1),"") | AP9: =IFERROR(IF(OR('Valor cuota (fin de mes)'!AP9="",'Valor cuota (fin de mes)'!AO9=""),"",'Valor cuota (fin de mes)'!AP9/'Valor cuota (fin de mes)'!AO9-1),"") | AQ9: =IFERROR(IF(OR('Valor cuota (fin de mes)'!AQ9="",'Valor cuota (fin de mes)'!AP9=""),"",'Valor cuota (fin de mes)'!AQ9/'Valor cuota (fin de mes)'!AP9-1),"")

Sheet Cierre 31-dic (mensual)
A1: Cierre 31-dic (mensual)
A2: Rendimiento del mes de diciembre de cada año (mismo indicador que la hoja mensual). El año en curso = ultimo mes disponible (parcial)
A3: Fondo | B3: 2023 | C3: 2024 | D3: 2025 | E3: 2026 (YTD)
A4: FI Abierto Hencorp Opportunity | B4: ='Rendimiento mensual'!I4 | C4: ='Rendimiento mensual'!U4 | D4: ='Rendimiento mensual'!AG4 | E4: ='Rendimiento mensual'!AQ4
A5: FIC Renta Fija I | B5: ='Rendimiento mensual'!I5 | C5: ='Rendimiento mensual'!U5 | D5: ='Rendimiento mensual'!AG5 | E5: ='Rendimiento mensual'!AQ5
A6: FIC Inmobiliario Hencorp Growth | C6: ='Rendimiento mensual'!U6 | D6: ='Rendimiento mensual'!AG6 | E6: ='Rendimiento mensual'!AQ6
A7: FIC Desarrollo Inmob. Hencorp Vivienda 01 | D7: ='Rendimiento mensual'!AG7 | E7: ='Rendimiento mensual'!AQ7
A8: FIC Inmobiliario Hencorp Blue Whale | D8: ='Rendimiento mensual'!AG8 | E8: ='Rendimiento mensual'!AQ8
A9: FIC Inmobiliario Hencorp Commercial Properties | E9: ='Rendimiento mensual'!AQ9

Sheet Rendimiento anual
A1: Rendimiento anual
A2: Rendimiento ANUAL (ene–dic) desde la cuota. Año de lanzamiento = desde la base; el año en curso = YTD (parcial)
A3: Fondo | B3: 2023 | C3: 2024 | D3: 2025 | E3: 2026 (YTD)
A4: FI Abierto Hencorp Opportunity | B4: =IFERROR('Valor cuota (fin de mes)'!I4/'Resumen'!$D$4-1,"") | C4: =IFERROR('Valor cuota (fin de mes)'!U4/'Valor cuota (fin de mes)'!I4-1,"") | D4: =IFERROR('Valor cuota (fin de mes)'!AG4/'Valor cuota (fin de mes)'!U4-1,"") | E4: =IFERROR('Valor cuota (fin de mes)'!AQ4/'Valor cuota (fin de mes)'!AG4-1,"")
A5: FIC Renta Fija I | B5: =IFERROR('Valor cuota (fin de mes)'!I5/'Resumen'!$D$5-1,"") | C5: =IFERROR('Valor cuota (fin de mes)'!U5/'Valor cuota (fin de mes)'!I5-1,"") | D5: =IFERROR('Valor cuota (fin de mes)'!AG5/'Valor cuota (fin de mes)'!U5-1,"") | E5: =IFERROR('Valor cuota (fin de mes)'!AQ5/'Valor cuota (fin de mes)'!AG5-1,"")
A6: FIC Inmobiliario Hencorp Growth | C6: =IFERROR('Valor cuota (fin de mes)'!U6/'Resumen'!$D$6-1,"") | D6: =IFERROR('Valor cuota (fin de mes)'!AG6/'Valor cuota (fin de mes)'!U6-1,"") | E6: =IFERROR('Valor cuota (fin de mes)'!AQ6/'Valor cuota (fin de mes)'!AG6-1,"")
A7: FIC Desarrollo Inmob. Hencorp Vivienda 01 | D7: =IFERROR('Valor cuota (fin de mes)'!AG7/'Resumen'!$D$7-1,"") | E7: =IFERROR('Valor cuota (fin de mes)'!AQ7/'Valor cuota (fin de mes)'!AG7-1,"")
A8: FIC Inmobiliario Hencorp Blue Whale | D8: =IFERROR('Valor cuota (fin de mes)'!AG8/'Resumen'!$D$8-1,"") | E8: =IFERROR('Valor cuota (fin de mes)'!AQ8/'Valor cuota (fin de mes)'!AG8-1,"")
A9: FIC Inmobiliario Hencorp Commercial Properties | E9: =IFERROR('Valor cuota (fin de mes)'!AQ9/'Resumen'!$D$9-1,"")

Sheet Diario
A1: Detalle diario — 6 fondos de inversión
A2: Grupo Hencorp — Gestora de Fondos | Fuente: hencorpgestora.com (Comportamiento Histórico) | datos al 2026-10-12 (actualización 2026-10-13) | una fila por día · lo más reciente arriba · se actualiza a diario
A3: Fecha | B3: Abierto Hencorp Opportunity | E3: Renta Fija I | H3: Inmobiliario Hencorp Growth | K3: Desarrollo Inmob. Hencorp Vivienda 01 | N3: Inmobiliario Hencorp Blue Whale | Q3: Inmobiliario Hencorp Commercial Properties
B4: Valor cuota | C4: Rend. diario | D4: Patrimonio | E4: Valor cuota | F4: Rend. diario | G4: Patrimonio | H4: Valor cuota | I4: Rend. diario | J4: Patrimonio | K4: Valor cuota | L4: Rend. diario | M4: Patrimonio | N4: Valor cuota | O4: Rend. diario | P4: Patrimonio | Q4: Valor cuota | R4: Rend. diario | S4: Patrimonio
A5: 46307 | B5: 1.1918761 | C5: 0.000111 | D5: 2.595947e+08 | E5: 1053.139 | F5: 0.000236 | G5: 6.8952799e+08 | H5: 1246.1298 | I5: 0.000108 | J5: 30639839 | K5: 1171.8836 | L5: -4.4e-05 | M5: 18623574 | N5: 1013.0163 | O5: 0.000101 | P5: 9977197.4 | Q5: 1054.0692 | R5: 0.000304 | S5: 13650196
A6: 46306 | B6: 1.1917438 | C6: 0.00013 | D6: 2.6013833e+08 | E6: 1052.8906 | F6: 0.000233 | G6: 6.893654e+08 | H6: 1245.9946 | I6: 0.000112 | J6: 30636516 | K6: 1171.9346 | L6: -4.4e-05 | M6: 18624385 | N6: 1012.9144 | O6: 0.000101 | P6: 9976194.1 | Q6: 1053.7491 | R6: 0.000304 | S6: 13646050
A7: 46305 | B7: 1.1915885 | C7: 0.000129 | D7: 2.5994886e+08 | E7: 1052.6451 | F7: 0.000234 | G7: 6.8920467e+08 | H7: 1245.8547 | I7: 0.000112 | J7: 30633075 | K7: 1171.9856 | L7: -4.4e-05 | M7: 18625195 | N7: 1012.8125 | O7: 0.000101 | P7: 9975190.7 | Q7: 1053.4289 | R7: 0.000304 | S7: 13641904
A8: 46304 | B8: 1.1914348 | C8: 0.000141 | D8: 2.58886e+08 | E8: 1052.3986 | F8: 0.000234 | G8: 6.8904328e+08 | H8: 1245.7147 | I8: 0.000112 | J8: 30629633 | K8: 1172.0366 | L8: -4.4e-05 | M8: 18626006 | N8: 1012.7107 | O8: 0.000101 | P8: 9974187.3 | Q8: 1053.1087 | R8: 0.000304 | S8: 13637758
A9: 46303 | B9: 1.1912664 | C9: 0.000125 | D9: 2.4113183e+08 | E9: 1052.1525 | F9: 0.000234 | G9: 6.8888215e+08 | H9: 1245.5748 | I9: 0.000112 | J9: 30626192 | K9: 1172.0876 | L9: -7.5e-05 | M9: 18626816 | N9: 1012.6088 | O9: 0.000101 | P9: 9973183.8 | Q9: 1052.7886 | R9: 0.000304 | S9: 13633612
A10: 46302 | B10: 1.1911176 | C10: 0.000131 | D10: 2.4060634e+08 | E10: 1051.9063 | F10: 0.000234 | G10: 6.8872089e+08 | H10: 1245.4348 | I10: 0.000112 | J10: 30622751 | K10: 1172.1749 | L10: -4.1e-05 | M10: 18628204 | N10: 1012.5069 | O10: 0.000101 | P10: 9972180.3 | Q10: 1052.4684 | R10: 0.000304 | S10: 13629466
A11: 46301 | B11: 1.1909616 | C11: 0.000129 | D11: 2.3955414e+08 | E11: 1051.6597 | F11: 0.000234 | G11: 688559476 | H11: 1245.2948 | I11: 0.000117 | J11: 30619310 | K11: 1172.2227 | L11: -4.1e-05 | M11: 18628963 | N11: 1012.405 | O11: 0.000101 | P11: 9971176.7 | Q11: 1052.1482 | R11: 0.000304 | S11: 13625320
A12: 46300 | B12: 1.1908078 | C12: 0.000129 | D12: 2.3889229e+08 | E12: 1051.4134 | F12: 0.000233 | G12: 6.8839818e+08 | H12: 1245.1493 | I12: 0.000117 | J12: 30615731 | K12: 1172.2705 | L12: -0.000203 | M12: 18629722 | N12: 1012.3031 | O12: 0.000101 | P12: 9970173.1 | Q12: 1051.8281 | R12: 0.000304 | S12: 13621173
A13: 46299 | B13: 1.1906543 | C13: 0.000131 | D13: 2.4112086e+08 | E13: 1051.168 | F13: 0.000234 | G13: 6.8823755e+08 | H13: 1245.0037 | I13: 0.000117 | J13: 30612152 | K13: 1172.5081 | L13: -4.1e-05 | M13: 18633499 | N13: 1012.2012 | O13: 0.000101 | P13: 9969169.4 | Q13: 1051.5079 | R13: 0.000305 | S13: 13617027
A14: 46298 | B14: 1.1904988 | C14: 0.000131 | D14: 2.4110996e+08 | E14: 1050.9216 | F14: 0.000235 | G14: 6.8807621e+08 | H14: 1244.8582 | I14: 0.000117 | J14: 30608572 | K14: 1172.5559 | L14: -4.1e-05 | M14: 18634258 | N14: 1012.0993 | O14: 0.000101 | P14: 9968165.6 | Q14: 1051.1877 | R14: 0.000305 | S14: 13612881
A15: 46297 | B15: 1.1903431 | C15: 0.000134 | D15: 2.4098208e+08 | E15: 1050.6752 | F15: 0.000233 | G15: 6.8791487e+08 | H15: 1244.7126 | I15: 0.000117 | J15: 30604993 | K15: 1172.6037 | L15: -4.1e-05 | M15: 18635017 | N15: 1011.9973 | O15: 0.000101 | P15: 9967161.8 | Q15: 1050.8675 | R15: 0.000305 | S15: 13608734
A16: 46296 | B16: 1.1901837 | C16: 0.000138 | D16: 2.3522435e+08 | E16: 1050.4304 | F16: 0.000235 | G16: 6.8775463e+08 | H16: 1244.567 | I16: 0.000116 | J16: 30601414 | K16: 1172.6514 | L16: -4.1e-05 | M16: 18635777 | N16: 1011.8954 | O16: 0.000101 | P16: 9966158 | Q16: 1050.5473 | R16: 0.000305 | S16: 13604588
... A155: 46157 | B155: 1.1691829 | C155: 0.000131 | D155: 1.9086775e+08 | E155: 1037.1383 | F155: 0.000235 | G155: 6.7905178e+08 | H155: 1212.2054 | I155: 0.000139 | J155: 27137642 | K155: 1185.1899 | L155: -0.000136 | M155: 18835038 | N155: 1008.0383 | O155: 0.000171 | P155: 4898058 | Q155: 1000 | R155: 0 | S155: 12950000
A156: 46156 | B156: 1.1690301 | C156: 0.000132 | D156: 1.8833728e+08 | E156: 1036.8949 | F156: 0.000235 | G156: 6.7889239e+08 | H156: 1212.0367 | I156: 0.000139 | J156: 27133865 | K156: 1185.3517 | L156: -0.000136 | M156: 18837608 | N156: 1007.8658 | O156: 0.000171 | P156: 4897219.8
A157: 46155 | B157: 1.1688755 | C157: 0.000105 | D157: 1.8710223e+08 | E157: 1036.6518 | F157: -0.018602 | G157: 6.7873323e+08 | H157: 1211.868 | I157: 0.000139 | J157: 27130088 | K157: 1185.5134 | L157: -0.000126 | M157: 18840178 | N157: 1007.6933 | O157: 0.000171 | P157: 4896381.6
A158: 46154 | B158: 1.1687526 | C158: 0.000123 | D158: 1.9749236e+08 | E158: 1056.3013 | F158: 0.000231 | G158: 6.9159847e+08 | H158: 1211.6992 | I158: 0.000138 | J158: 27126311 | K158: 1185.6628 | L158: -0.000126 | M158: 18842553 | N158: 1007.5207 | O158: 0.000171 | P158: 4895543.3
A159: 46153 | B159: 1.1686087 | C159: 0.000133 | D159: 1.9624785e+08 | E159: 1056.0578 | F159: 0.000233 | G159: 6.9143904e+08 | H159: 1211.5325 | I159: 0.000138 | J159: 27122578 | K159: 1185.8122 | L159: -0.000126 | M159: 18844927 | N159: 1007.3482 | O159: 0.000171 | P159: 4894705
A160: 46152 | B160: 1.1684538 | C160: 0.00013 | D160: 1.9371083e+08 | E160: 1055.8121 | F160: 0.000232 | G160: 6.9127817e+08 | H160: 1211.3657 | I160: 0.000138 | J160: 27118844 | K160: 1185.9616 | L160: -0.000126 | M160: 18847302 | N160: 1007.1757 | O160: 0.000171 | P160: 4893866.6
A161: 46151 | B161: 1.1683014 | C161: 0.00013 | D161: 1.9365605e+08 | E161: 1055.5669 | F161: 0.000232 | G161: 6.9111763e+08 | H161: 1211.1989 | I161: 0.000138 | J161: 27115110 | K161: 1186.111 | L161: -0.000126 | M161: 18849676 | N161: 1007.0031 | O161: 0.000171 | P161: 4893028.2
A162: 46150 | B162: 1.1681491 | C162: 0.000128 | D162: 1.9361984e+08 | E162: 1055.3217 | F162: 0.000234 | G162: 6.9095708e+08 | H162: 1211.0321 | I162: 0.000138 | J162: 27111375 | K162: 1186.2604 | L162: -0.000126 | M162: 18852051 | N162: 1006.8306 | O162: 0.000171 | P162: 4892189.7
A163: 46149 | B163: 1.1679995 | C163: 0.000126 | D163: 1.9180323e+08 | E163: 1055.0748 | F163: 0.000233 | G163: 6.9079543e+08 | H163: 1210.8653 | I163: 0.000138 | J163: 27107641 | K163: 1186.4099 | L163: -0.000126 | M163: 18854426 | N163: 1006.658 | O163: 0.000121 | P163: 4891351.2
A164: 46148 | B164: 1.1678522 | C164: 0.000132 | D164: 1.8922016e+08 | E164: 1054.829 | F164: 0.000234 | G164: 6.9063452e+08 | H164: 1210.6985 | I164: 0.000138 | J164: 27103907 | K164: 1186.5593 | L164: -0.000126 | M164: 18856800 | N164: 1006.536 | O164: 0.000171 | P164: 4890758.4
A165: 46147 | B165: 1.1676985 | C165: 0.000115 | D165: 1.855718e+08 | E165: 1054.5827 | F165: 0.000231 | G165: 6.9047327e+08 | H165: 1210.5314 | I165: 0.000138 | J165: 27100167 | K165: 1186.7087 | L165: -0.000126 | M165: 18859175 | N165: 1006.3634 | O165: 0.000172 | P165: 4889919.8
A166: 46146 | B166: 1.1675637 | C166: 0.000126 | D166: 1.9190367e+08 | E166: 1054.3393 | F166: 0.000233 | G166: 6.903139e+08 | H166: 1210.3639 | I166: 0.00014 | J166: 27096416 | K166: 1186.8581 | L166: -0.000126 | M166: 18861550 | N166: 1006.1908 | O166: 0.000172 | P166: 4889081.2
A167: 46145 | B167: 1.1674161 | C167: 0.00013 | D167: 1.8935419e+08 | E167: 1054.0935 | F167: 0.000234 | G167: 6.9015298e+08 | H167: 1210.1942 | I167: 0.00014 | J167: 27092618 | K167: 1187.0076 | L167: -0.000126 | M167: 18863924 | N167: 1006.0182 | O167: 0.000172 | P167: 4888242.5
... A393: 45919 | B393: 1.1337366 | C393: 0.000153 | D393: 1.1562394e+08 | E393: 1046.6654 | F393: 0.000236 | G393: 6.6766475e+08 | H393: 1213.33 | I393: 0.000143 | J393: 27162818 | K393: 991.31917 | L393: -1.7e-05 | M393: 14234352 | N393: 1000 | O393: 0 | P393: 3500000
A394: 45918 | B394: 1.133563 | C394: 0.000146 | D394: 1.135317e+08 | E394: 1046.4184 | F394: 0.000236 | G394: 6.6750718e+08 | H394: 1213.1569 | I394: 0.000147 | J394: 27158944 | K394: 991.3363 | L394: -1.7e-05 | M394: 14234598
A395: 45917 | B395: 1.1333979 | C395: 0.000154 | D395: 1.1140102e+08 | E395: 1046.1711 | F395: 0.000236 | G395: 6.6734937e+08 | H395: 1212.9788 | I395: 0.000133 | J395: 27154957 | K395: 991.35342 | L395: -1.7e-05 | M395: 14234844
A396: 45916 | B396: 1.1332239 | C396: 0.000172 | D396: 1.1257745e+08 | E396: 1045.9237 | F396: 0.000237 | G396: 6.6719161e+08 | H396: 1212.817 | I396: 0.000133 | J396: 27151335 | K396: 991.37055 | L396: -1.7e-05 | M396: 14235090
A397: 45915 | B397: 1.133029 | C397: 0.000145 | D397: 1.1138594e+08 | E397: 1045.6764 | F397: 0.000236 | G397: 6.6703382e+08 | H397: 1212.6552 | I397: 0.000133 | J397: 27147712 | K397: 991.38767 | L397: -1.7e-05 | M397: 14235336
A398: 45914 | B398: 1.1328643 | C398: 0.000127 | D398: 1.1136976e+08 | E398: 1045.4296 | F398: 0.000236 | G398: 6.668764e+08 | H398: 1212.4934 | I398: 0.000133 | J398: 27144089 | K398: 991.4048 | L398: -1.7e-05 | M398: 14235581
A399: 45913 | B399: 1.1327205 | C399: 0.000124 | D399: 1.1135562e+08 | E399: 1045.1831 | F399: 0.000237 | G399: 6.6671914e+08 | H399: 1212.3315 | I399: 0.000134 | J399: 27140466 | K399: 991.42192 | L399: -1.7e-05 | M399: 14235827
A400: 45912 | B400: 1.1325795 | C400: 0.000139 | D400: 1.1134176e+08 | E400: 1044.9355 | F400: 0.000237 | G400: 6.665612e+08 | H400: 1212.1697 | I400: 0.000134 | J400: 27136843 | K400: 991.43905 | L400: -1.7e-05 | M400: 14236073
A401: 45911 | B401: 1.1324224 | C401: 0.000133 | D401: 1.123591e+08 | E401: 1044.688 | F401: 0.000237 | G401: 6.6640336e+08 | H401: 1212.0078 | I401: 0.000134 | J401: 27133219 | K401: 991.45617 | L401: -1.7e-05 | M401: 14236319
A402: 45910 | B402: 1.1322716 | C402: 0.00013 | D402: 1.1334323e+08 | E402: 1044.4404 | F402: 0.000211 | G402: 6.662454e+08 | H402: 1211.846 | I402: 0.000134 | J402: 27129596 | K402: 991.4733 | L402: -1.7e-05 | M402: 14236565
A403: 45909 | B403: 1.132124 | C403: 0.000138 | D403: 1.1310846e+08 | E403: 1044.2199 | F403: 0.000237 | G403: 6.6268698e+08 | H403: 1211.6841 | I403: 0.000134 | J403: 27125973 | K403: 991.49042 | L403: -1.7e-05 | M403: 14236811
...

Sheet Valor cuota (fin de mes)
A1: Valor cuota (fin de mes)
A2: Grupo Hencorp — Gestora de Fondos | Fuente: hencorpgestora.com (Comportamiento Histórico) | datos al 2026-10-12 (actualización 2026-10-13)
A3: Fondo | B3: may-2023 | C3: jun-2023 | D3: jul-2023 | E3: ago-2023 | F3: sep-2023 | G3: oct-2023 | H3: nov-2023 | I3: dic-2023 | J3: ene-2024 | K3: feb-2024 | L3: mar-2024 | M3: abr-2024 | N3: may-2024 | O3: jun-2024 | P3: jul-2024 | Q3: ago-2024 | R3: sep-2024 | S3: oct-2024 | T3: nov-2024 | U3: dic-2024 | V3: ene-2025 | W3: feb-2025 | X3: mar-2025 | Y3: abr-2025 | Z3: may-2025 | AA3: jun-2025 | AB3: jul-2025 | AC3: ago-2025 | AD3: sep-2025 | AE3: oct-2025 | AF3: nov-2025 | AG3: dic-2025 | AH3: ene-2026 | AI3: feb-2026 | AJ3: mar-2026 | AK3: abr-2026 | AL3: may-2026 | AM3: jun-2026 | AN3: jul-2026 | AO3: ago-2026 | AP3: sep-2026 | AQ3: oct-2026*
A4: FI Abierto Hencorp Opportunity | B4: 1.0042318 | C4: 1.0085181 | D4: 1.0128668 | E4: 1.0173763 | F4: 1.0218089 | G4: 1.0263879 | H4: 1.0306844 | I4: 1.0359479 | J4: 1.0406063 | K4: 1.0448963 | L4: 1.0494155 | M4: 1.0539331 | N4: 1.0592179 | O4: 1.0640595 | P4: 1.0688075 | Q4: 1.0735092 | R4: 1.0780725 | S4: 1.0831082 | T4: 1.0876538 | U4: 1.0924678 | V4: 1.0972577 | W4: 1.1015601 | X4: 1.1064724 | Y4: 1.1113874 | Z4: 1.1162905 | AA4: 1.1209893 | AB4: 1.1259162 | AC4: 1.1307494 | AD4: 1.1354138 | AE4: 1.1399574 | AF4: 1.1441651 | AG4: 1.1488066 | AH4: 1.1533475 | AI4: 1.1576537 | AJ4: 1.1623831 | AK4: 1.1669559 | AL4: 1.1715671 | AM4: 1.1760487 | AN4: 1.1807452 | AO4: 1.18553 | AP4: 1.19002 | AQ4: 1.1918761
A5: FIC Renta Fija I | G5: 1004.0914 | H5: 1011.0099 | I5: 1017.9666 | J5: 1025.1435 | K5: 1032.2025 | L5: 1039.5472 | M5: 1046.9496 | N5: 1038.798 | O5: 1038.7396 | P5: 1046.1199 | Q5: 1048.7838 | R5: 1048.8806 | S5: 1056.2348 | T5: 1039.2837 | U5: 1039.3914 | V5: 1046.7844 | W5: 1048.5916 | X5: 1048.6276 | Y5: 1052.6819 | Z5: 1039.6517 | AA5: 1039.6638 | AB5: 1047.0897 | AC5: 1049.3232 | AD5: 1049.3728 | AE5: 1053.041 | AF5: 1040.2677 | AG5: 1040.2445 | AH5: 1047.591 | AI5: 1049.709 | AJ5: 1049.7459 | AK5: 1053.3552 | AL5: 1040.7866 | AM5: 1040.7832 | AN5: 1048.1392 | AO5: 1049.9987 | AP5: 1050.184 | AQ5: 1053.139
A6: FIC Inmobiliario Hencorp Growth | L6: 1001.831 | M6: 1007.3205 | N6: 1012.6369 | O6: 1018.1412 | P6: 1023.6918 | Q6: 1006.1542 | R6: 1011.7666 | S6: 1017.3695 | T6: 1023.0159 | U6: 1028.5985 | V6: 1034.1805 | W6: 1039.5841 | X6: 1184.043 | Y6: 1188.8576 | Z6: 1194.2859 | AA6: 1199.7938 | AB6: 1204.5773 | AC6: 1210.2279 | AD6: 1215.8874 | AE6: 1221.4967 | AF6: 1236.1463 | AG6: 1173.4788 | AH6: 1179.4258 | AI6: 1185.1761 | AJ6: 1198.3295 | AK6: 1209.6864 | AL6: 1214.9764 | AM6: 1220.3307 | AN6: 1225.8443 | AO6: 1239.0646 | AP6: 1244.4226 | AQ6: 1246.1298
A7: FIC Desarrollo Inmob. Hencorp Vivienda 01 | AA7: 996.69381 | AB7: 993.41423 | AC7: 991.64457 | AD7: 991.08259 | AE7: 984.15311 | AF7: 977.39018 | AG7: 971.77694 | AH7: 956.22123 | AI7: 1105.7385 | AJ7: 1101.9769 | AK7: 1187.4564 | AL7: 1182.5741 | AM7: 1176.4937 | AN7: 1174.8788 | AO7: 1174.2168 | AP7: 1172.6999 | AQ7: 1171.8836
A8: FIC Inmobiliario Hencorp Blue Whale | AD8: 1000.023 | AE8: 1000.555 | AF8: 1007.7225 | AG8: 1013.0095 | AH8: 1013.1757 | AI8: 1018.6383 | AJ8: 1023.8524 | AK8: 1005.5003 | AL8: 1010.8201 | AM8: 1013.2382 | AN8: 1004.4542 | AO8: 1003.3424 | AP8: 1011.7935 | AQ8: 1013.0163
A9: FIC Inmobiliario Hencorp Commercial Properties | AL9: 1003.878 | AM9: 1016.0867 | AN9: 1028.3717 | AO9: 1040.2363 | AP9: 1050.2271 | AQ9: 1054.0692

Sheet Patrimonio (fin de mes)
A1: Patrimonio (fin de mes)
A2: Grupo Hencorp — Gestora de Fondos | Fuente: hencorpgestora.com (Comportamiento Histórico) | datos al 2026-10-12 (actualización 2026-10-13)
A3: Fondo | B3: may-2023 | C3: jun-2023 | D3: jul-2023 | E3: ago-2023 | F3: sep-2023 | G3: oct-2023 | H3: nov-2023 | I3: dic-2023 | J3: ene-2024 | K3: feb-2024 | L3: mar-2024 | M3: abr-2024 | N3: may-2024 | O3: jun-2024 | P3: jul-2024 | Q3: ago-2024 | R3: sep-2024 | S3: oct-2024 | T3: nov-2024 | U3: dic-2024 | V3: ene-2025 | W3: feb-2025 | X3: mar-2025 | Y3: abr-2025 | Z3: may-2025 | AA3: jun-2025 | AB3: jul-2025 | AC3: ago-2025 | AD3: sep-2025 | AE3: oct-2025 | AF3: nov-2025 | AG3: dic-2025 | AH3: ene-2026 | AI3: feb-2026 | AJ3: mar-2026 | AK3: abr-2026 | AL3: may-2026 | AM3: jun-2026 | AN3: jul-2026 | AO3: ago-2026 | AP3: sep-2026 | AQ3: oct-2026*
A4: FI Abierto Hencorp Opportunity | B4: 1503994.7 | C4: 1928332.3 | D4: 3606769.4 | E4: 7098164.7 | F4: 10409972 | G4: 11885615 | H4: 13128322 | I4: 15296245 | J4: 13775708 | K4: 15487388 | L4: 18663588 | M4: 24448617 | N4: 29070852 | O4: 27254196 | P4: 33841877 | Q4: 33108264 | R4: 37009004 | S4: 41438096 | T4: 44883885 | U4: 58584153 | V4: 53955392 | W4: 68104178 | X4: 81791519 | Y4: 89671128 | Z4: 84856704 | AA4: 99314486 | AB4: 1.0049102e+08 | AC4: 1.1465442e+08 | AD4: 1.2153727e+08 | AE4: 1.3886524e+08 | AF4: 1.3891596e+08 | AG4: 1.5356222e+08 | AH4: 1.6046527e+08 | AI4: 1.6249484e+08 | AJ4: 179487689 | AK4: 1.8927627e+08 | AL4: 2.1768848e+08 | AM4: 2.1867738e+08 | AN4: 2.3212283e+08 | AO4: 2.4613725e+08 | AP4: 2.3037484e+08 | AQ4: 2.595947e+08
A5: FIC Renta Fija I | G5: 2.013364e+08 | H5: 3.0332927e+08 | I5: 3.0541645e+08 | J5: 4.0814037e+08 | K5: 5.1150794e+08 | L5: 5.6545027e+08 | M5: 6.1980255e+08 | N5: 6.2201563e+08 | O5: 6.2198067e+08 | P5: 6.2639986e+08 | Q5: 6.3502077e+08 | R5: 6.3507936e+08 | S5: 6.4406238e+08 | T5: 6.4377287e+08 | U5: 6.4383956e+08 | V5: 6.4841907e+08 | W5: 6.5255951e+08 | X5: 6.5609691e+08 | Y5: 6.6042312e+08 | Z5: 6.5527586e+08 | AA5: 6.5779426e+08 | AB5: 6.6249261e+08 | AC5: 6.6592567e+08 | AD5: 6.6939179e+08 | AE5: 6.7375036e+08 | AF5: 6.7010925e+08 | AG5: 6.7312765e+08 | AH5: 6.8589556e+08 | AI5: 6.8728229e+08 | AJ5: 6.8730641e+08 | AK5: 6.8966958e+08 | AL5: 6.8144048e+08 | AM5: 6.8143826e+08 | AN5: 6.8625448e+08 | AO5: 6.8747197e+08 | AP5: 6.875933e+08 | AQ5: 6.8952799e+08
A6: FIC Inmobiliario Hencorp Growth | L6: 14527551 | M6: 14607154 | N6: 14684248 | O6: 14764066 | P6: 14844554 | Q6: 14590241 | R6: 14671628 | S6: 14752875 | T6: 17400477 | U6: 17495433 | V6: 17590376 | W6: 17682286 | X6: 20139387 | Y6: 22664382 | Z6: 22767866 | AA6: 22872870 | AB6: 26966872 | AC6: 27093373 | AD6: 27220071 | AE6: 27345648 | AF6: 27673608 | AG6: 26270669 | AH6: 26403805 | AI6: 26532538 | AJ6: 26827002 | AK6: 27081248 | AL6: 27199676 | AM6: 27319544 | AN6: 27442976 | AO6: 27738940 | AP6: 30597864 | AQ6: 30639839
A7: FIC Desarrollo Inmob. Hencorp Vivienda 01 | AA7: 2421966 | AB7: 9963944.7 | AC7: 14239024 | AD7: 14230955 | AE7: 15640161 | AF7: 15532685 | AG7: 15443479 | AH7: 15196268 | AI7: 17572397 | AJ7: 17512616 | AK7: 18871058 | AL7: 18793467 | AM7: 18696838 | AN7: 18671173 | AO7: 18660653 | AP7: 18636547 | AQ7: 18623574
A8: FIC Inmobiliario Hencorp Blue Whale | AD8: 3500080.5 | AE8: 3501942.6 | AF8: 4896523.4 | AG8: 4922213.2 | AH8: 4923020.5 | AI8: 4949563.3 | AJ8: 4974899 | AK8: 4885726.1 | AL8: 4911574.7 | AM8: 4923324.5 | AN8: 7642892.1 | AO8: 7634432.5 | AP8: 9965154.1 | AQ8: 9977197.4
A9: FIC Inmobiliario Hencorp Commercial Properties | AL9: 13000220 | AM9: 13158322 | AN9: 13317413 | AO9: 13471060 | AP9: 13600441 | AQ9: 13650196

Sheet Notas y metodologia
A1: Notas y metodología
A3: Fuente: Hencorp Gestora de Fondos de Inversión, S.A. — sección 'Informe Valor Cuota' (PDF 'Comportamiento Histórico del Fondo') en hencorpgestora.com. Archivo regenerado automáticamente.
A4: datos al 2026-10-12 (actualización 2026-10-13).
A6: DEFINICIÓN DE 'RENDIMIENTO MENSUAL':
A7: Rendimiento del mes = (Valor cuota al cierre del mes ÷ Valor cuota al cierre del mes anterior) − 1. Es el rendimiento real de la cuota en el mes.
A8: El primer mes de cada fondo se mide desde el valor cuota inicial (base) hasta el cierre de ese mes (puede ser parcial). El año en curso es PARCIAL.
A10: ADVERTENCIA (fondos cerrados):
A11: • Renta Fija I DISTRIBUYE en mayo y noviembre: la cuota baja esos meses, por lo que su rendimiento medido SOLO desde la cuota SUBESTIMA el total del partícipe (lo distribuido se paga en efectivo).
A12: • Growth y Vivienda 01 registran REVALUACIONES inmobiliarias (saltos grandes) y bajas por distribución/markdown. Commercial Properties tiene historia mínima (inició may-2026).
A14: Códigos de color: azul = dato de origen extraído; verde = enlace a otra hoja; negro = fórmula.

Sheet Datos_graficas
A1: Fondo | B1: may-2023 | C1: jun-2023 | D1: jul-2023 | E1: ago-2023 | F1: sep-2023 | G1: oct-2023 | H1: nov-2023 | I1: dic-2023 | J1: ene-2024 | K1: feb-2024 | L1: mar-2024 | M1: abr-2024 | N1: may-2024 | O1: jun-2024 | P1: jul-2024 | Q1: ago-2024 | R1: sep-2024 | S1: oct-2024 | T1: nov-2024 | U1: dic-2024 | V1: ene-2025 | W1: feb-2025 | X1: mar-2025 | Y1: abr-2025 | Z1: may-2025 | AA1: jun-2025 | AB1: jul-2025 | AC1: ago-2025 | AD1: sep-2025 | AE1: oct-2025 | AF1: nov-2025 | AG1: dic-2025 | AH1: ene-2026 | AI1: feb-2026 | AJ1: mar-2026 | AK1: abr-2026 | AL1: may-2026 | AM1: jun-2026 | AN1: jul-2026 | AO1: ago-2026 | AP1: sep-2026 | AQ1: oct-2026*
A2: Abierto Hencorp Opportunity | B2: 1503994.7 | C2: 1928332.3 | D2: 3606769.4 | E2: 7098164.7 | F2: 10409972 | G2: 11885615 | H2: 13128322 | I2: 15296245 | J2: 13775708 | K2: 15487388 | L2: 18663588 | M2: 24448617 | N2: 29070852 | O2: 27254196 | P2: 33841877 | Q2: 33108264 | R2: 37009004 | S2: 41438096 | T2: 44883885 | U2: 58584153 | V2: 53955392 | W2: 68104178 | X2: 81791519 | Y2: 89671128 | Z2: 84856704 | AA2: 99314486 | AB2: 1.0049102e+08 | AC2: 1.1465442e+08 | AD2: 1.2153727e+08 | AE2: 1.3886524e+08 | AF2: 1.3891596e+08 | AG2: 1.5356222e+08 | AH2: 1.6046527e+08 | AI2: 1.6249484e+08 | AJ2: 179487689 | AK2: 1.8927627e+08 | AL2: 2.1768848e+08 | AM2: 2.1867738e+08 | AN2: 2.3212283e+08 | AO2: 2.4613725e+08 | AP2: 2.3037484e+08 | AQ2: 2.595947e+08
A3: Renta Fija I | G3: 2.013364e+08 | H3: 3.0332927e+08 | I3: 3.0541645e+08 | J3: 4.0814037e+08 | K3: 5.1150794e+08 | L3: 5.6545027e+08 | M3: 6.1980255e+08 | N3: 6.2201563e+08 | O3: 6.2198067e+08 | P3: 6.2639986e+08 | Q3: 6.3502077e+08 | R3: 6.3507936e+08 | S3: 6.4406238e+08 | T3: 6.4377287e+08 | U3: 6.4383956e+08 | V3: 6.4841907e+08 | W3: 6.5255951e+08 | X3: 6.5609691e+08 | Y3: 6.6042312e+08 | Z3: 6.5527586e+08 | AA3: 6.5779426e+08 | AB3: 6.6249261e+08 | AC3: 6.6592567e+08 | AD3: 6.6939179e+08 | AE3: 6.7375036e+08 | AF3: 6.7010925e+08 | AG3: 6.7312765e+08 | AH3: 6.8589556e+08 | AI3: 6.8728229e+08 | AJ3: 6.8730641e+08 | AK3: 6.8966958e+08 | AL3: 6.8144048e+08 | AM3: 6.8143826e+08 | AN3: 6.8625448e+08 | AO3: 6.8747197e+08 | AP3: 6.875933e+08 | AQ3: 6.8952799e+08
A4: Inmobiliario Hencorp Growth | L4: 14527551 | M4: 14607154 | N4: 14684248 | O4: 14764066 | P4: 14844554 | Q4: 14590241 | R4: 14671628 | S4: 14752875 | T4: 17400477 | U4: 17495433 | V4: 17590376 | W4: 17682286 | X4: 20139387 | Y4: 22664382 | Z4: 22767866 | AA4: 22872870 | AB4: 26966872 | AC4: 27093373 | AD4: 27220071 | AE4: 27345648 | AF4: 27673608 | AG4: 26270669 | AH4: 26403805 | AI4: 26532538 | AJ4: 26827002 | AK4: 27081248 | AL4: 27199676 | AM4: 27319544 | AN4: 27442976 | AO4: 27738940 | AP4: 30597864 | AQ4: 30639839
A5: Desarrollo Inmob. Hencorp Vivienda 01 | AA5: 2421966 | AB5: 9963944.7 | AC5: 14239024 | AD5: 14230955 | AE5: 15640161 | AF5: 15532685 | AG5: 15443479 | AH5: 15196268 | AI5: 17572397 | AJ5: 17512616 | AK5: 18871058 | AL5: 18793467 | AM5: 18696838 | AN5: 18671173 | AO5: 18660653 | AP5: 18636547 | AQ5: 18623574
A6: Inmobiliario Hencorp Blue Whale | AD6: 3500080.5 | AE6: 3501942.6 | AF6: 4896523.4 | AG6: 4922213.2 | AH6: 4923020.5 | AI6: 4949563.3 | AJ6: 4974899 | AK6: 4885726.1 | AL6: 4911574.7 | AM6: 4923324.5 | AN6: 7642892.1 | AO6: 7634432.5 | AP6: 9965154.1 | AQ6: 9977197.4
A7: Inmobiliario Hencorp Commercial Properties | AL7: 13000220 | AM7: 13158322 | AN7: 13317413 | AO7: 13471060 | AP7: 13600441 | AQ7: 13650196
A10: Fondo | B10: 2023 | C10: 2024 | D10: 2025 | E10: 2026
A11: Abierto Hencorp Opportunity | B11: 15296245 | C11: 58584153 | D11: 1.5356222e+08 | E11: 2.595947e+08
A12: Renta Fija I | B12: 3.0541645e+08 | C12: 6.4383956e+08 | D12: 6.7312765e+08 | E12: 6.8952799e+08
A13: Inmobiliario Hencorp Growth | C13: 17495433 | D13: 26270669 | E13: 30639839
A14: Desarrollo Inmob. Hencorp Vivienda 01 | D14: 15443479 | E14: 18623574
A15: Inmobiliario Hencorp Blue Whale | D15: 4922213.2 | E15: 9977197.4
A16: Inmobiliario Hencorp Commercial Properties | E16: 13650196
A19: Fondo | B19: may-2023 | C19: jun-2023 | D19: jul-2023 | E19: ago-2023 | F19: sep-2023 | G19: oct-2023 | H19: nov-2023 | I19: dic-2023 | J19: ene-2024 | K19: feb-2024 | L19: mar-2024 | M19: abr-2024 | N19: may-2024 | O19: jun-2024 | P19: jul-2024 | Q19: ago-2024 | R19: sep-2024 | S19: oct-2024 | T19: nov-2024 | U19: dic-2024 | V19: ene-2025 | W19: feb-2025 | X19: mar-2025 | Y19: abr-2025 | Z19: may-2025 | AA19: jun-2025 | AB19: jul-2025 | AC19: ago-2025 | AD19: sep-2025 | AE19: oct-2025 | AF19: nov-2025 | AG19: dic-2025 | AH19: ene-2026 | AI19: feb-2026 | AJ19: mar-2026 | AK19: abr-2026 | AL19: may-2026 | AM19: jun-2026 | AN19: jul-2026 | AO19: ago-2026 | AP19: sep-2026 | AQ19: oct-2026*
A20: Abierto Hencorp Opportunity | B20: 0.004232 | C20: 0.004268 | D20: 0.004312 | E20: 0.004452 | F20: 0.004357 | G20: 0.004481 | H20: 0.004186 | I20: 0.005107 | J20: 0.004497 | K20: 0.004123 | L20: 0.004325 | M20: 0.004305 | N20: 0.005014 | O20: 0.004571 | P20: 0.004462 | Q20: 0.004399 | R20: 0.004251 | S20: 0.004671 | T20: 0.004197 | U20: 0.004426 | V20: 0.004384 | W20: 0.003921 | X20: 0.004459 | Y20: 0.004442 | Z20: 0.004412 | AA20: 0.004209 | AB20: 0.004395 | AC20: 0.004293 | AD20: 0.004125 | AE20: 0.004002 | AF20: 0.003691 | AG20: 0.004057 | AH20: 0.003953 | AI20: 0.003734 | AJ20: 0.004085 | AK20: 0.003934 | AL20: 0.003951 | AM20: 0.003825 | AN20: 0.003993 | AO20: 0.004052 | AP20: 0.003787 | AQ20: 0.00156
A21: Renta Fija I | G21: 0.004091 | H21: 0.00689 | I21: 0.006881 | J21: 0.00705 | K21: 0.006886 | L21: 0.007116 | M21: 0.007121 | N21: -0.007786 | O21: -5.6e-05 | P21: 0.007105 | Q21: 0.002546 | R21: 9.2e-05 | S21: 0.007011 | T21: -0.016049 | U21: 0.000104 | V21: 0.007113 | W21: 0.001726 | X21: 3.4e-05 | Y21: 0.003866 | Z21: -0.012378 | AA21: 1.2e-05 | AB21: 0.007143 | AC21: 0.002133 | AD21: 4.7e-05 | AE21: 0.003496 | AF21: -0.01213 | AG21: -2.2e-05 | AH21: 0.007062 | AI21: 0.002022 | AJ21: 3.5e-05 | AK21: 0.003438 | AL21: -0.011932 | AM21: -3e-06 | AN21: 0.007068 | AO21: 0.001774 | AP21: 0.000176 | AQ21: 0.002814
A22: Inmobiliario Hencorp Growth | L22: 0.001831 | M22: 0.005479 | N22: 0.005278 | O22: 0.005436 | P22: 0.005452 | Q22: -0.017132 | R22: 0.005578 | S22: 0.005538 | T22: 0.00555 | U22: 0.005457 | V22: 0.005427 | W22: 0.005225 | X22: 0.138958 | Y22: 0.004066 | Z22: 0.004566 | AA22: 0.004612 | AB22: 0.003987 | AC22: 0.004691 | AD22: 0.004676 | AE22: 0.004613 | AF22: 0.011993 | AG22: -0.050696 | AH22: 0.005068 | AI22: 0.004876 | AJ22: 0.011098 | AK22: 0.009477 | AL22: 0.004373 | AM22: 0.004407 | AN22: 0.004518 | AO22: 0.010785 | AP22: 0.004324 | AQ22: 0.001372
A23: Desarrollo Inmob. Hencorp Vivienda 01 | AA23: -0.003306 | AB23: -0.00329 | AC23: -0.001781 | AD23: -0.000567 | AE23: -0.006992 | AF23: -0.006872 | AG23: -0.005743 | AH23: -0.016007 | AI23: 0.156363 | AJ23: -0.003402 | AK23: 0.077569 | AL23: -0.004112 | AM23: -0.005142 | AN23: -0.001373 | AO23: -0.000563 | AP23: -0.001292 | AQ23: -0.000696
A24: Inmobiliario Hencorp Blue Whale | AD24: 2.3e-05 | AE24: 0.000532 | AF24: 0.007163 | AG24: 0.005247 | AH24: 0.000164 | AI24: 0.005392 | AJ24: 0.005119 | AK24: -0.017925 | AL24: 0.005291 | AM24: 0.002392 | AN24: -0.008669 | AO24: -0.001107 | AP24: 0.008423 | AQ24: 0.001209
A25: Inmobiliario Hencorp Commercial Properties | AL25: 0.003878 | AM25: 0.012162 | AN25: 0.01209 | AO25: 0.011537 | AP25: 0.009604 | AQ25: 0.003658
